Workbook
Name DATE1: OFFSET([1]日前信息!$B$89,,,COUNTA([1]日前信息!$B$89:$B$123))
Name NAME: OFFSET([1]日前信息!$A$89,,,COUNTA([1]日前信息!$A$89:$A$123))
Name REAL_1: _xlfn._xlws.FILTER('[1]收益测算-累计创值'!$AE$242:$AE$276,'[1]收益测算-累计创值'!$A$242:$A$276<=[1]测算看板2.0!$C$2)
Name DATE7: OFFSET([1]日前信息!$P$89,,,COUNTA([1]日前信息!$P$89:$P$123))

Sheet 负荷
A1: 日期 | B1: 0.010416667 | C1: 0.020833333 | D1: 0.03125 | E1: 0.041666667 | F1: 0.052083333 | G1: 0.0625 | H1: 0.072916667 | I1: 0.083333333 | J1: 0.09375 | K1: 0.10416667 | L1: 0.11458333 | M1: 0.125 | N1: 0.13541667 | O1: 0.14583333 | P1: 0.15625 | Q1: 0.16666667 | R1: 0.17708333 | S1: 0.1875 | T1: 0.19791667 | U1: 0.20833333 | V1: 0.21875 | W1: 0.22916667 | X1: 0.23958333 | Y1: 0.25 | Z1: 0.26041667 | AA1: 0.27083333 | AB1: 0.28125 | AC1: 0.29166667 | AD1: 0.30208333 | AE1: 0.3125 | AF1: 0.32291667 | AG1: 0.33333333 | AH1: 0.34375 | AI1: 0.35416667 | AJ1: 0.36458333 | AK1: 0.375 | AL1: 0.38541667 | AM1: 0.39583333 | AN1: 0.40625 | AO1: 0.41666667 | AP1: 0.42708333 | AQ1: 0.4375 | AR1: 0.44791667 | AS1: 0.45833333 | AT1: 0.46875 | AU1: 0.47916667 | AV1: 0.48958333 | AW1: 0.5 | AX1: 0.51041667 | AY1: 0.52083333 | AZ1: 0.53125 | BA1: 0.54166667 | BB1: 0.55208333 | BC1: 0.5625 | BD1: 0.57291667 | BE1: 0.58333333 | BF1: 0.59375 | BG1: 0.60416667 | BH1: 0.61458333 | BI1: 0.625 | BJ1: 0.63541667 | BK1: 0.64583333 | BL1: 0.65625 | BM1: 0.66666667 | BN1: 0.67708333 | BO1: 0.6875 | BP1: 0.69791667 | BQ1: 0.70833333 | BR1: 0.71875 | BS1: 0.72916667 | BT1: 0.73958333 | BU1: 0.75 | BV1: 0.76041667 | BW1: 0.77083333 | BX1: 0.78125 | BY1: 0.79166667 | BZ1: 0.80208333 | CA1: 0.8125 | CB1: 0.82291667 | CC1: 0.83333333 | CD1: 0.84375 | CE1: 0.85416667 | CF1: 0.86458333 | CG1: 0.875 | CH1: 0.88541667 | CI1: 0.89583333 | CJ1: 0.90625 | CK1: 0.91666667 | CL1: 0.92708333 | CM1: 0.9375 | CN1: 0.94791667 | CO1: 0.95833333 | CP1: 0.96875 | CQ1: 0.97916667 | CR1: 0.98958333 | CS1: 1
A2: 46235 | B2: 33749.1 | C2: 33229.73 | D2: 32912.51 | E2: 32638.83 | F2: 32276.52 | G2: 31931.31 | H2: 31638.97 | I2: 31438.37 | J2: 31327.97 | K2: 30976.54 | L2: 30858.36 | M2: 30534.92 | N2: 30334.32 | O2: 30307.89 | P2: 30301.67 | Q2: 30091.74 | R2: 30149.28 | S2: 30069.97 | T2: 30000 | U2: 30500.71 | V2: 30925.22 | W2: 31264.21 | X2: 31712.05 | Y2: 32002.84 | Z2: 32581.3 | AA2: 32937.39 | AB2: 33439.66 | AC2: 33949.7 | AD2: 34853.15 | AE2: 35590.22 | AF2: 36457.91 | AG2: 37336.49 | AH2: 38491.85 | AI2: 39465.28 | AJ2: 40280.1 | AK2: 40993.85 | AL2: 41693.6 | AM2: 42471.1 | AN2: 42796.09 | AO2: 43236.16 | AP2: 43808.4 | AQ2: 44494.15 | AR2: 44578.12 | AS2: 44766.28 | AT2: 44812.93 | AU2: 44347.98 | AV2: 44430.4 | AW2: 44542.36 | AX2: 44803.6 | AY2: 44837.81 | AZ2: 44872.02 | BA2: 45207.9 | BB2: 45430.26 | BC2: 45195.46 | BD2: 45315.19 | BE2: 45170.58 | BF2: 45284.09 | BG2: 45169.02 | BH2: 45150.36 | BI2: 45225 | BJ2: 45550 | BK2: 45438.04 | BL2: 45200.12 | BM2: 45364.95 | BN2: 45495.57 | BO2: 45459.81 | BP2: 45235.89 | BQ2: 44458.39 | BR2: 44068.08 | BS2: 43971.67 | BT2: 43786.63 | BU2: 43648.23 | BV2: 43329.46 | BW2: 43349.67 | BX2: 42978.03 | BY2: 42831.86 | BZ2: 42973.36 | CA2: 43124.2 | CB2: 43425.87 | CC2: 43303.02 | CD2: 43077.55 | CE2: 42813.2 | CF2: 42399.57 | CG2: 41776.01 | CH2: 41505.44 | CI2: 40746.6 | CJ2: 40188.36 | CK2: 39326.89 | CL2: 39155.84 | CM2: 38306.81 | CN2: 37532.42 | CO2: 36663.17 | CP2: 36151.58 | CQ2: 35593.33 | CR2: 34798.73 | CS2: 34136.3
A3: 46236 | B3: 33523.48 | C3: 33056.3 | D3: 32590.54 | E3: 32474.1 | F3: 32241.22 | G3: 32123.36 | H3: 31890.48 | I3: 31657.6 | J3: 31541.16 | K3: 31308.28 | L3: 31191.84 | M3: 30841.1 | N3: 30724.66 | O3: 30724.66 | P3: 30724.66 | Q3: 30608.22 | R3: 30608.22 | S3: 30608.22 | T3: 30550 | U3: 30899.32 | V3: 31191.84 | W3: 31482.94 | X3: 32183 | Y3: 32735.38 | Z3: 33228.12 | AA3: 33539.1 | AB3: 33993.5 | AC3: 34442.22 | AD3: 35238.84 | AE3: 35879.26 | AF3: 36673.04 | AG3: 37446.94 | AH3: 38494.9 | AI3: 39345.48 | AJ3: 40086.72 | AK3: 40741.34 | AL3: 41391.7 | AM3: 42087.5 | AN3: 42401.32 | AO3: 42808.86 | AP3: 43317.22 | AQ3: 43923.56 | AR3: 44020.12 | AS3: 44191.94 | AT3: 44233.12 | AU3: 43804.28 | AV3: 43861.08 | AW3: 43940.6 | AX3: 44157.86 | AY3: 44216.08 | AZ3: 44244.48 | BA3: 44519.96 | BB3: 44713.08 | BC3: 44494.4 | BD3: 44619.36 | BE3: 44463.16 | BF3: 44552.62 | BG3: 44461.74 | BH3: 44414.88 | BI3: 44478.78 | BJ3: 44750 | BK3: 44676.16 | BL3: 44453.22 | BM3: 44583.86 | BN3: 44688.94 | BO3: 44652.02 | BP3: 44447.54 | BQ3: 43744.64 | BR3: 43408.1 | BS3: 43298.76 | BT3: 43122.68 | BU3: 42967.9 | BV3: 42693.84 | BW3: 42675.38 | BX3: 42358.72 | BY3: 42219.56 | BZ3: 42372.92 | CA3: 42527.7 | CB3: 42813.12 | CC3: 42735.02 | CD3: 42533.38 | CE3: 42306.18 | CF3: 41934.14 | CG3: 41359.04 | CH3: 41138.94 | CI3: 40461.6 | CJ3: 39964.6 | CK3: 39183.6 | CL3: 39075.68 | CM3: 38317.4 | CN3: 37590.36 | CO3: 36803.68 | CP3: 36316.62 | CQ3: 35788.38 | CR3: 35064.18 | CS3: 34460.68
A4: 46237 | B4: 33620 | C4: 33270.5 | D4: 32954 | E4: 32615 | F4: 32307.5 | G4: 32013.5 | H4: 31811 | I4: 31635.5 | J4: 31565 | K4: 31286 | L4: 31154 | M4: 31008.5 | N4: 30839 | O4: 30822.5 | P4: 30815 | Q4: 30650 | R4: 30768.5 | S4: 30690.5 | T4: 30723.5 | U4: 31041.5 | V4: 31559 | W4: 31901 | X4: 32322.5 | Y4: 32792 | Z4: 33311 | AA4: 33903.5 | AB4: 34416.5 | AC4: 34851.5 | AD4: 35685.5 | AE4: 36431 | AF4: 37286 | AG4: 38216 | AH4: 39578 | AI4: 40434.5 | AJ4: 41250.5 | AK4: 41856.5 | AL4: 42534.5 | AM4: 43334 | AN4: 43623.5 | AO4: 43907 | AP4: 44462 | AQ4: 44960 | AR4: 45144.5 | AS4: 45116 | AT4: 45068 | AU4: 45027.5 | AV4: 44795.24 | AW4: 45147.5 | AX4: 45159.5 | AY4: 45291.5 | AZ4: 45479 | BA4: 45446 | BB4: 45650 | BC4: 45581 | BD4: 45591.5 | BE4: 45417.5 | BF4: 45495.5 | BG4: 45455 | BH4: 45449 | BI4: 45353 | BJ4: 45515 | BK4: 45491 | BL4: 45416 | BM4: 45344 | BN4: 45441.5 | BO4: 45201.5 | BP4: 44870 | BQ4: 44123 | BR4: 43724 | BS4: 43650.5 | BT4: 43337 | BU4: 43259 | BV4: 42915.5 | BW4: 42833 | BX4: 42758 | BY4: 42563 | BZ4: 42765.5 | CA4: 42849.5 | CB4: 43172 | CC4: 42999.5 | CD4: 42729.5 | CE4: 42588.5 | CF4: 42147.5 | CG4: 41699 | CH4: 41414 | CI4: 40692.5 | CJ4: 40160 | CK4: 39503 | CL4: 39407 | CM4: 38687 | CN4: 37980.5 | CO4: 37244 | CP4: 36654.5 | CQ4: 36068 | CR4: 35466.5 | CS4: 34788.5
A5: 46238 | B5: 34222.79 | C5: 33893.84 | D5: 33587.84 | E5: 33179.33 | F5: 32966.66 | G5: 32570.39 | H5: 32538.26 | I5: 32360.78 | J5: 32175.65 | K5: 31857.41 | L5: 31568.24 | M5: 31588.13 | N5: 31410.65 | O5: 31448.9 | P5: 31412.18 | Q5: 31250 | R5: 31416.77 | S5: 31387.7 | T5: 31474.91 | U5: 31738.07 | V5: 32388.32 | W5: 32671.37 | X5: 33142.61 | Y5: 33877.01 | Z5: 34489.01 | AA5: 35110.19 | AB5: 35612.03 | AC5: 36015.95 | AD5: 36675.38 | AE5: 37513.82 | AF5: 38408.87 | AG5: 39433.97 | AH5: 40976.21 | AI5: 41794.76 | AJ5: 42784.67 | AK5: 43326.29 | AL5: 43575.68 | AM5: 44455.43 | AN5: 44732.36 | AO5: 45038.36 | AP5: 45635.06 | AQ5: 45849.26 | AR5: 46066.52 | AS5: 45942.59 | AT5: 46040.51 | AU5: 46011.44 | AV5: 45590.69 | AW5: 45957.89 | AX5: 45986.96 | AY5: 46344.98 | AZ5: 46550 | BA5: 46358.75 | BB5: 46040.51 | BC5: 46386.29 | BD5: 46305.2 | BE5: 46141.49 | BF5: 46404.65 | BG5: 46332.74 | BH5: 46449.02 | BI5: 46074.17 | BJ5: 46332.74 | BK5: 46398.53 | BL5: 46256.24 | BM5: 46228.7 | BN5: 46248.59 | BO5: 45934.94 | BP5: 45462.17 | BQ5: 44795.09 | BR5: 44432.48 | BS5: 44342.21 | BT5: 43964.3 | BU5: 43872.5 | BV5: 43566.5 | BW5: 43456.34 | BX5: 43411.97 | BY5: 43083.02 | BZ5: 43327.82 | CA5: 43407.38 | CB5: 43860.26 | CC5: 43659.83 | CD5: 43404.32 | CE5: 43335.47 | CF5: 42896.36 | CG5: 42648.5 | CH5: 42134.42 | CI5: 41234.78 | CJ5: 40687.04 | CK5: 40102.58 | CL5: 39914.39 | CM5: 39299.33 | CN5: 38727.11 | CO5: 38056.97 | CP5: 37298.09 | CQ5: 36661.61 | CR5: 36146 | CS5: 35433.02
A6: 46239 | B6: 34820.96 | C6: 34458.08 | D6: 34122.08 | E6: 33671.84 | F6: 33440 | G6: 33003.2 | H6: 32966.24 | I6: 32771.36 | J6: 32568.08 | K6: 32216.96 | L6: 31899.44 | M6: 31921.28 | N6: 31726.4 | O6: 31768.4 | P6: 31728.08 | Q6: 31550 | R6: 31733.12 | S6: 31701.2 | T6: 31798.64 | U6: 32087.6 | V6: 32801.6 | W6: 33112.4 | X6: 33631.52 | Y6: 34439.6 | Z6: 35113.28 | AA6: 35797.04 | AB6: 36348.08 | AC6: 36793.28 | AD6: 37519.04 | AE6: 38441.36 | AF6: 39425.84 | AG6: 40553.12 | AH6: 42249.92 | AI6: 43150.4 | AJ6: 44240.72 | AK6: 44837.12 | AL6: 45109.28 | AM6: 46078.64 | AN6: 46382.72 | AO6: 46718.72 | AP6: 47375.6 | AQ6: 47610.8 | AR6: 47851.04 | AS6: 47714.96 | AT6: 47820.8 | AU6: 47788.88 | AV6: 47326.88 | AW6: 47731.76 | AX6: 47762 | AY6: 48195.44 | AZ6: 48350 | BA6: 47871.2 | BB6: 47520.08 | BC6: 47901.44 | BD6: 47810.72 | BE6: 47630.96 | BF6: 47919.92 | BG6: 47565.44 | BH6: 47767.04 | BI6: 47347.04 | BJ6: 47511.68 | BK6: 47439.44 | BL6: 47232.8 | BM6: 47026.16 | BN6: 46947.36 | BO6: 46535.76 | BP6: 45764.64 | BQ6: 45096 | BR6: 44733.12 | BS6: 44642.4 | BT6: 44262.72 | BU6: 44168.64 | BV6: 43862.88 | BW6: 43750.32 | BX6: 43704.96 | BY6: 43372.32 | BZ6: 43614.24 | CA6: 43691.52 | CB6: 44138.4 | CC6: 43936.8 | CD6: 43679.76 | CE6: 43609.2 | CF6: 43170.72 | CG6: 42920.4 | CH6: 42406.32 | CI6: 41510.88 | CJ6: 40961.52 | CK6: 40378.56 | CL6: 40187.04 | CM6: 39572.16 | CN6: 39000.96 | CO6: 38332.32 | CP6: 37572.96 | CQ6: 36939.6 | CR6: 36422.16 | CS6: 35713.2
A7: 46240 | B7: 34857.27 | C7: 34506.82 | D7: 34065.09 | E7: 33755.39 | F7: 33489.7 | G7: 33147.4 | H7: 32925.72 | I7: 32756.2 | J7: 32550.82 | K7: 32338.92 | L7: 32169.4 | M7: 31985.21 | N7: 31830.36 | O7: 31753.75 | P7: 31690.18 | Q7: 31550 | R7: 31708.11 | S7: 31701.59 | T7: 31773.31 | U7: 32141.69 | V7: 32653.51 | W7: 33033.3 | X7: 33445.69 | Y7: 34083.02 | Z7: 34761.1 | AA7: 35393.54 | AB7: 36006.42 | AC7: 36547.58 | AD7: 37391.92 | AE7: 38317.76 | AF7: 39178.4 | AG7: 40265.61 | AH7: 41615.25 | AI7: 42550.87 | AJ7: 43398.47 | AK7: 44246.07 | AL7: 45017.06 | AM7: 45783.16 | AN7: 46234.67 | AO7: 46611.2 | AP7: 47101.83 | AQ7: 47543.56 | AR7: 47616.91 | AS7: 47568.01 | AT7: 47563.12 | AU7: 47479.99 | AV7: 47343.07 | AW7: 47405.01 | AX7: 47447.39 | AY7: 47726.12 | AZ7: 47781.54 | BA7: 47721.23 | BB7: 47850 | BC7: 47685.37 | BD7: 47745.68 | BE7: 47558.23 | BF7: 47744.05 | BG7: 47636.47 | BH7: 47524 | BI7: 47300.69 | BJ7: 47486.51 | BK7: 47458.8 | BL7: 47470.21 | BM7: 47194.74 | BN7: 47581.05 | BO7: 47052.93 | BP7: 46832.88 | BQ7: 46045.59 | BR7: 45660.91 | BS7: 45633.2 | BT7: 45274.6 | BU7: 45360.99 | BV7: 44964.9 | BW7: 44855.69 | BX7: 44777.45 | BY7: 44524.8 | BZ7: 44790.49 | CA7: 44938.82 | CB7: 44935.48 | CC7: 44756.18 | CD7: 44524.72 | CE7: 44332.38 | CF7: 43745.58 | CG7: 43372.31 | CH7: 42940.36 | CI7: 42099.28 | CJ7: 41448.91 | CK7: 40548.58 | CL7: 40279.63 | CM7: 39392.91 | CN7: 38670.82 | CO7: 37934.06 | CP7: 37203.82 | CQ7: 36599.09 | CR7: 35929.16 | CS7: 35151.65
A8: 46241 | B8: 34633.81 | C8: 34204.64 | D8: 33762.11 | E8: 33475.51 | F8: 33205.24 | G8: 32838.44 | H8: 32535.5 | I8: 32366.21 | J8: 32254.84 | K8: 31953.38 | L8: 31816.76 | M8: 31536.1 | N8: 31455.91 | O8: 31409.87 | P8: 31320.77 | Q8: 31150 | R8: 31292.56 | S8: 31201.97 | T8: 31210.88 | U8: 31516.79 | V8: 32008.33 | W8: 32453.83 | X8: 32853.29 | Y8: 33346.31 | Z8: 33999.71 | AA8: 34760.03 | AB8: 35383.73 | AC8: 35916.85 | AD8: 36712.81 | AE8: 37701.82 | AF8: 38573.51 | AG8: 39552.13 | AH8: 40759.43 | AI8: 41656.37 | AJ8: 42373.63 | AK8: 43185.92 | AL8: 43796.26 | AM8: 44415.5 | AN8: 44786.75 | AO8: 44924.86 | AP8: 45336.2 | AQ8: 45830.71 | AR8: 45959.9 | AS8: 46000 | AT8: 45818.83 | AU8: 45659.93 | AV8: 45532.22 | AW8: 45523.31 | AX8: 45517.37 | AY8: 45585.68 | AZ8: 45811.4 | BA8: 45673.3 | BB8: 45835.16 | BC8: 45642.11 | BD8: 45806.95 | BE8: 45422.33 | BF8: 45459.46 | BG8: 45665.87 | BH8: 45509.95 | BI8: 45584.2 | BJ8: 45634.69 | BK8: 45478.76 | BL8: 45469.85 | BM8: 45328.78 | BN8: 45566.38 | BO8: 45302.05 | BP8: 45153.55 | BQ8: 44443.72 | BR8: 44252.15 | BS8: 43907.63 | BT8: 43686.37 | BU8: 43454.71 | BV8: 43027.03 | BW8: 43093.85 | BX8: 43073.06 | BY8: 42986.93 | BZ8: 43315.12 | CA8: 43315.12 | CB8: 43413.13 | CC8: 43145.83 | CD8: 42936.44 | CE8: 42658.75 | CF8: 42040.99 | CG8: 41395.01 | CH8: 41010.4 | CI8: 40432.73 | CJ8: 39546.19 | CK8: 38647.76 | CL8: 38334.43 | CM8: 37621.63 | CN8: 36891.01 | CO8: 36112.87 | CP8: 35408.98 | CQ8: 34760.03 | CR8: 34183.85 | CS8: 33441.35
A9: 46242 | B9: 32574.37 | C9: 32236.94 | D9: 31760.5 | E9: 31624.54 | F9: 31215.6 | G9: 30672.7 | H9: 30401.25 | I9: 30196.9 | J9: 29992.55 | K9: 29721.58 | L9: 29585.62 | M9: 29314.65 | N9: 29043.68 | O9: 28905.22 | P9: 28905.22 | Q9: 28905.22 | R9: 28905.22 | S9: 28812.2 | T9: 28800 | U9: 28912.85 | V9: 29388.65 | W9: 29869.02 | X9: 30314.32 | Y9: 31035.65 | Z9: 31435.2 | AA9: 32174.82 | AB9: 32793.97 | AC9: 33253 | AD9: 34088.7 | AE9: 34861.87 | AF9: 35796.7 | AG9: 36742.2 | AH9: 38183.32 | AI9: 38982.42 | AJ9: 39816.6 | AK9: 40537.92 | AL9: 41486.47 | AM9: 42294.72 | AN9: 42740.02 | AO9: 43074 | AP9: 43459.82 | AQ9: 43828.87 | AR9: 44050 | AS9: 43998.15 | AT9: 43687.05 | AU9: 43616.9 | AV9: 43279.87 | AW9: 43159.4 | AX9: 43058.75 | AY9: 43130.42 | AZ9: 43374.42 | BA9: 43031.3 | BB9: 43468.97 | BC9: 43095.35 | BD9: 43176.17 | BE9: 42828.47 | BF9: 42796.45 | BG9: 42823.9 | BH9: 42611.92 | BI9: 42506.7 | BJ9: 42441.12 | BK9: 42608.87 | BL9: 42773.57 | BM9: 42355.72 | BN9: 42721.72 | BO9: 42497.55 | BP9: 42198.65 | BQ9: 41321.77 | BR9: 41137.25 | BS9: 41012.2 | BT9: 40662.97 | BU9: 40591.3 | BV9: 40306.12 | BW9: 40303.07 | BX9: 40624.85 | BY9: 40501.32 | BZ9: 40940.52 | CA9: 40984.75 | CB9: 41009.15 | CC9: 40664.5 | CD9: 40071.27 | CE9: 39850.15 | CF9: 39101.37 | CG9: 38450.2 | CH9: 38064.37 | CI9: 37358.3 | CJ9: 36682.72 | CK9: 35894.3 | CL9: 36182.52 | CM9: 35323.95 | CN9: 34459.27 | CO9: 33675.42 | CP9: 32963.25 | CQ9: 32304.45 | CR9: 31648.7 | CS9: 30893.82
A10: 46243 | B10: 29525 | C10: 29087.5 | D10: 28878.75 | E10: 28747.5 | F10: 28415 | G10: 28112.5 | H10: 27858.75 | I10: 27720 | J10: 27516.25 | K10: 27360 | L10: 27046.25 | M10: 26860 | N10: 26971.25 | O10: 26661.25 | P10: 26635 | Q10: 26550 | R10: 26678.75 | S10: 26667.5 | T10: 26878.75 | U10: 27385 | V10: 27742.5 | W10: 28007.5 | X10: 28492.5 | Y10: 28747.5 | Z10: 29118.75 | AA10: 29683.75 | AB10: 29873.75 | AC10: 30151.25 | AD10: 30892.5 | AE10: 31425 | AF10: 32078.75 | AG10: 32671.25 | AH10: 33732.5 | AI10: 34276.25 | AJ10: 35123.75 | AK10: 35625 | AL10: 36268.75 | AM10: 36640 | AN10: 36896.25 | AO10: 37295 | AP10: 37436.25 | AQ10: 38183.75 | AR10: 38511.25 | AS10: 38368.75 | AT10: 38645 | AU10: 38127.5 | AV10: 38127.5 | AW10: 38127.5 | AX10: 38127.5 | AY10: 38257.5 | AZ10: 38257.5 | BA10: 38387.5 | BB10: 38387.5 | BC10: 38770 | BD10: 38751.25 | BE10: 38890 | BF10: 38753.75 | BG10: 38590 | BH10: 38690 | BI10: 38568.75 | BJ10: 39050 | BK10: 38933.75 | BL10: 38817.5 | BM10: 38546.25 | BN10: 38432.5 | BO10: 38380 | BP10: 38560 | BQ10: 37793.75 | BR10: 37616.25 | BS10: 37341.25 | BT10: 37013.75 | BU10: 36905 | BV10: 36698.75 | BW10: 36645 | BX10: 36575 | BY10: 36185 | BZ10: 36695 | CA10: 36777.5 | CB10: 37026.25 | CC10: 37166.25 | CD10: 37161.25 | CE10: 36936.25 | CF10: 36535 | CG10: 35930 | CH10: 35457.5 | CI10: 34727.5 | CJ10: 34196.25 | CK10: 33586.25 | CL10: 33611.25 | CM10: 32942.5 | CN10: 32112.5 | CO10: 31475 | CP10: 30677.5 | CQ10: 30111.25 | CR10: 29478.75 | CS10: 29030
A11: 46244 | B11: 28665.25 | C11: 28325.35 | D11: 28087.75 | E11: 27724.75 | F11: 27586.15 | G11: 27277.6 | H11: 27153.85 | I11: 26866.75 | J11: 26785.9 | K11: 26592.85 | L11: 26465.8 | M11: 26213.35 | N11: 26256.25 | O11: 26051.65 | P11: 26050 | Q11: 26097.85 | R11: 26287.6 | S11: 26368.45 | T11: 26533.45 | U11: 26914.6 | V11: 27487.15 | W11: 27935.95 | X11: 28727.95 | Y11: 29048.05 | Z11: 30019.9 | AA11: 30452.2 | AB11: 31132 | AC11: 31526.35 | AD11: 32445.4 | AE11: 33158.2 | AF11: 33979.9 | AG11: 34837.9 | AH11: 36228.85 | AI11: 37243.6 | AJ11: 37931.65 | AK11: 38646.1 | AL11: 39472.75 | AM11: 39990.85 | AN11: 40495.75 | AO11: 40934.65 | AP11: 41236.6 | AQ11: 41795.95 | AR11: 42114.4 | AS11: 42046.75 | AT11: 42172.15 | AU11: 41706.85 | AV11: 41487.4 | AW11: 41446.15 | AX11: 41645.8 | AY11: 41540.2 | AZ11: 41832.25 | BA11: 41774.5 | BB11: 42224.95 | BC11: 42213.4 | BD11: 42488.95 | BE11: 42464.2 | BF11: 42172.15 | BG11: 42378.4 | BH11: 42550 | BI11: 42269.5 | BJ11: 42500.5 | BK11: 42355.3 | BL11: 42312.4 | BM11: 42122.65 | BN11: 41952.7 | BO11: 41692 | BP11: 41484.1 | BQ11: 40480.9 | BR11: 40238.35 | BS11: 39949.6 | BT11: 39839.05 | BU11: 39674.05 | BV11: 39438.1 | BW11: 39294.55 | BX11: 39258.25 | BY11: 39035.5 | BZ11: 39474.4 | CA11: 39596.5 | CB11: 39782.95 | CC11: 39599.8 | CD11: 39405.1 | CE11: 39094.9 | CF11: 38599.9 | CG11: 38052.1 | CH11: 37575.25 | CI11: 36829.45 | CJ11: 36172.75 | CK11: 35294.95 | CL11: 35435.2 | CM11: 34494.7 | CN11: 33752.2 | CO11: 32897.5 | CP11: 32313.4 | CQ11: 31618.75 | CR11: 31127.05 | CS11: 30467.05
A12: 46245 | B12: 30787.98 | C12: 30328.47 | D12: 30085.2 | E12: 29678.16 | F12: 29568.45 | G12: 29172.54 | H12: 29002.41 | I12: 28776.63 | J12: 28542.9 | K12: 28544.49 | L12: 28331.43 | M12: 28129.5 | N12: 28380.72 | O12: 28050 | P12: 28107.24 | Q12: 28072.26 | R12: 28304.4 | S12: 28422.06 | T12: 28560.39 | U12: 29019.9 | V12: 29547.78 | W12: 29792.64 | X12: 30640.11 | Y12: 30656.01 | Z12: 31694.28 | AA12: 31937.55 | AB12: 32716.65 | AC12: 33077.58 | AD12: 33929.82 | AE12: 34832.94 | AF12: 35575.47 | AG12: 36448.38 | AH12: 37742.64 | AI12: 38710.95 | AJ12: 39267.45 | AK12: 39825.54 | AL12: 40582.38 | AM12: 41350.35 | AN12: 41916.39 | AO12: 42167.61 | AP12: 42425.19 | AQ12: 43132.74 | AR12: 43337.85 | AS12: 43347.39 | AT12: 43639.95 | AU12: 43054.83 | AV12: 42776.58 | AW12: 42914.91 | AX12: 43191.57 | AY12: 42865.62 | AZ12: 43077.09 | BA12: 43024.62 | BB12: 43487.31 | BC12: 43360.11 | BD12: 43913.43 | BE12: 43908.66 | BF12: 43277.43 | BG12: 43674.93 | BH12: 43950 | BI12: 43426.89 | BJ12: 43883.22 | BK12: 43927.74 | BL12: 43841.88 | BM12: 43818.03 | BN12: 43555.68 | BO12: 43487.31 | BP12: 43116.84 | BQ12: 42259.83 | BR12: 42104.01 | BS12: 41905.26 | BT12: 41897.31 | BU12: 41658.81 | BV12: 41515.71 | BW12: 41385.33 | BX12: 41119.8 | BY12: 40839.96 | BZ12: 41100.72 | CA12: 41324.91 | CB12: 41642.91 | CC12: 41636.55 | CD12: 41188.17 | CE12: 41043.48 | CF12: 40539.45 | CG12: 40134 | CH12: 39741.27 | CI12: 38947.86 | CJ12: 38356.38 | CK12: 37411.92 | CL12: 37680.63 | CM12: 36756.84 | CN12: 35984.1 | CO12: 35152.53 | CP12: 34308.24 | CQ12: 33692.91 | CR12: 33239.76 | CS12: 32646.69
A13: 46246 | B13: 31878.2 | C13: 31597.43 | D13: 31315.19 | E13: 30893.3 | F13: 30649.28 | G13: 30364.1 | H13: 30149.48 | I13: 29820.2 | J13: 29687.9 | K13: 29540.9 | L13: 29407.13 | M13: 29158.7 | N13: 29074.91 | O13: 28958.78 | P13: 28891.16 | Q13: 28850 | R13: 28939.67 | S13: 28941.14 | T13: 29014.64 | U13: 29301.29 | V13: 29707.01 | W13: 30146.54 | X13: 30771.29 | Y13: 31263.74 | Z13: 31941.41 | AA13: 32514.71 | AB13: 33077.72 | AC13: 33593.69 | AD13: 34443.35 | AE13: 35056.34 | AF13: 35857.49 | AG13: 36835.04 | AH13: 38084.54 | AI13: 38856.29 | AJ13: 39636.86 | AK13: 40157.24 | AL13: 40842.26 | AM13: 41374.4 | AN13: 41809.52 | AO13: 42210.83 | AP13: 42541.58 | AQ13: 42914.96 | AR13: 43175.15 | AS13: 43216.31 | AT13: 43229.54 | AU13: 42695.93 | AV13: 42647.42 | AW13: 42570.98 | AX13: 42738.56 | AY13: 42797.36 | AZ13: 43067.84 | BA13: 43157.51 | BB13: 43347.14 | BC13: 43380.95 | BD13: 43550 | BE13: 43403 | BF13: 43441.22 | BG13: 43445.63 | BH13: 43463.27 | BI13: 43403 | BJ13: 43525.01 | BK13: 43541.18 | BL13: 43385.36 | BM13: 43323.62 | BN13: 43419.17 | BO13: 43233.95 | BP13: 43084.01 | BQ13: 42338.72 | BR13: 42106.46 | BS13: 41993.27 | BT13: 41799.23 | BU13: 41666.93 | BV13: 41475.83 | BW13: 41458.19 | BX13: 41444.96 | BY13: 41322.95 | BZ13: 41652.23 | CA13: 41663.99 | CB13: 41825.69 | CC13: 41650.76 | CD13: 41367.05 | CE13: 41175.95 | CF13: 40664.39 | CG13: 40026.41 | CH13: 39566.3 | CI13: 38835.71 | CJ13: 38183.03 | CK13: 37403.93 | CL13: 37271.63 | CM13: 36492.53 | CN13: 35717.84 | CO13: 35012.24 | CP13: 34397.78 | CQ13: 33762.74 | CR13: 33174.74 | CS13: 32497.07
... A32: 46265 | B32: 27407.6 | C32: 27232.88 | D32: 26952.08 | E32: 26833.52 | F32: 26683.76 | G32: 26466.4 | H32: 26379.04 | I32: 26183.52 | J32: 26017.12 | K32: 25842.4 | L32: 25827.84 | M32: 25752.96 | N32: 25715.52 | O32: 25699.92 | P32: 25692.64 | Q32: 25650 | R32: 25846.56 | S32: 25921.44 | T32: 26100.32 | U32: 26323.92 | V32: 26889.68 | W32: 27334.8 | X32: 27961.92 | Y32: 28526.64 | Z32: 29165.2 | AA32: 29616.56 | AB32: 30108.48 | AC32: 30449.6 | AD32: 31084 | AE32: 31552 | AF32: 32066.8 | AG32: 32542.08 | AH32: 33379.28 | AI32: 33960.64 | AJ32: 34346.48 | AK32: 34844.64 | AL32: 35135.84 | AM32: 35416.64 | AN32: 35636.08 | AO32: 35748.4 | AP32: 35870.08 | AQ32: 36050 | AR32: 36029.2 | AS32: 35950.16 | AT32: 35767.12 | AU32: 35159.76 | AV32: 34799.92 | AW32: 34543.04 | AX32: 34571.12 | AY32: 34638.72 | AZ32: 34959.04 | BA32: 35003.76 | BB32: 35204.48 | BC32: 35225.28 | BD32: 35320.96 | BE32: 35335.52 | BF32: 35389.6 | BG32: 35338.64 | BH32: 35282.48 | BI32: 35206.56 | BJ32: 35364.64 | BK32: 35302.24 | BL32: 35283.52 | BM32: 35333.44 | BN32: 35160.8 | BO32: 35103.6 | BP32: 34685.52 | BQ32: 34113.52 | BR32: 33985.6 | BS32: 33790.08 | BT32: 33697.52 | BU32: 33682.96 | BV32: 33614.32 | BW32: 33651.76 | BX32: 33923.2 | BY32: 33928.4 | BZ32: 34085.44 | CA32: 34013.68 | CB32: 33814 | CC32: 33396.96 | CD32: 33199.36 | CE32: 32973.68 | CF32: 32542.08 | CG32: 32020 | CH32: 31713.2 | CI32: 31139.12 | CJ32: 30666.96 | CK32: 30233.28 | CL32: 30247.84 | CM32: 29778.8 | CN32: 29314.96 | CO32: 28842.8 | CP32: 28560.96 | CQ32: 28169.92 | CR32: 27789.28 | CS32: 27385.76

Sheet 水电
A1: 日期 | B1: 0.010416667 | C1: 0.020833333 | D1: 0.03125 | E1: 0.041666667 | F1: 0.052083333 | G1: 0.0625 | H1: 0.072916667 | I1: 0.083333333 | J1: 0.09375 | K1: 0.10416667 | L1: 0.11458333 | M1: 0.125 | N1: 0.13541667 | O1: 0.14583333 | P1: 0.15625 | Q1: 0.16666667 | R1: 0.17708333 | S1: 0.1875 | T1: 0.19791667 | U1: 0.20833333 | V1: 0.21875 | W1: 0.22916667 | X1: 0.23958333 | Y1: 0.25 | Z1: 0.26041667 | AA1: 0.27083333 | AB1: 0.28125 | AC1: 0.29166667 | AD1: 0.30208333 | AE1: 0.3125 | AF1: 0.32291667 | AG1: 0.33333333 | AH1: 0.34375 | AI1: 0.35416667 | AJ1: 0.36458333 | AK1: 0.375 | AL1: 0.38541667 | AM1: 0.39583333 | AN1: 0.40625 | AO1: 0.41666667 | AP1: 0.42708333 | AQ1: 0.4375 | AR1: 0.44791667 | AS1: 0.45833333 | AT1: 0.46875 | AU1: 0.47916667 | AV1: 0.48958333 | AW1: 0.5 | AX1: 0.51041667 | AY1: 0.52083333 | AZ1: 0.53125 | BA1: 0.54166667 | BB1: 0.55208333 | BC1: 0.5625 | BD1: 0.57291667 | BE1: 0.58333333 | BF1: 0.59375 | BG1: 0.60416667 | BH1: 0.61458333 | BI1: 0.625 | BJ1: 0.63541667 | BK1: 0.64583333 | BL1: 0.65625 | BM1: 0.66666667 | BN1: 0.67708333 | BO1: 0.6875 | BP1: 0.69791667 | BQ1: 0.70833333 | BR1: 0.71875 | BS1: 0.72916667 | BT1: 0.73958333 | BU1: 0.75 | BV1: 0.76041667 | BW1: 0.77083333 | BX1: 0.78125 | BY1: 0.79166667 | BZ1: 0.80208333 | CA1: 0.8125 | CB1: 0.82291667 | CC1: 0.83333333 | CD1: 0.84375 | CE1: 0.85416667 | CF1: 0.86458333 | CG1: 0.875 | CH1: 0.88541667 | CI1: 0.89583333 | CJ1: 0.90625 | CK1: 0.91666667 | CL1: 0.92708333 | CM1: 0.9375 | CN1: 0.94791667 | CO1: 0.95833333 | CP1: 0.96875 | CQ1: 0.97916667 | CR1: 0.98958333 | CS1: 1
A2: 46235 | B2: =抽蓄水电!B2+地方水电!B2 -> 568.31 | C2: =抽蓄水电!C2+地方水电!C2 -> 567.78 | D2: =抽蓄水电!D2+地方水电!D2 -> 567.74 | E2: =抽蓄水电!E2+地方水电!E2 -> 567.86 | F2: =抽蓄水电!F2+地方水电!F2 -> 568.19 | G2: =抽蓄水电!G2+地方水电!G2 -> 568.18 | H2: =抽蓄水电!H2+地方水电!H2 -> 568.07 | I2: =抽蓄水电!I2+地方水电!I2 -> 568.19 | ... CS2: =抽蓄水电!CS2+地方水电!CS2 -> 459.95
A3: 46236 | B3: =抽蓄水电!B3+地方水电!B3 -> 626.09 | C3: =抽蓄水电!C3+地方水电!C3 -> 625.58 | D3: =抽蓄水电!D3+地方水电!D3 -> 624.89 | E3: =抽蓄水电!E3+地方水电!E3 -> 624.89 | F3: =抽蓄水电!F3+地方水电!F3 -> 625.2 | G3: =抽蓄水电!G3+地方水电!G3 -> 625.36 | H3: =抽蓄水电!H3+地方水电!H3 -> 625.2 | I3: =抽蓄水电!I3+地方水电!I3 -> 625.29 | ... CS3: =抽蓄水电!CS3+地方水电!CS3 -> 460.17
A4: 46237 | B4: =抽蓄水电!B4+地方水电!B4 -> 587.41 | C4: =抽蓄水电!C4+地方水电!C4 -> 586.29 | D4: =抽蓄水电!D4+地方水电!D4 -> 583.97 | E4: =抽蓄水电!E4+地方水电!E4 -> 583.9 | F4: =抽蓄水电!F4+地方水电!F4 -> 584.43 | G4: =抽蓄水电!G4+地方水电!G4 -> 625.41 | H4: =抽蓄水电!H4+地方水电!H4 -> 625.32 | I4: =抽蓄水电!I4+地方水电!I4 -> 625.39 | ... CS4: =抽蓄水电!CS4+地方水电!CS4 -> 454.27
A5: 46238 | B5: =抽蓄水电!B5+地方水电!B5 -> 559.74 | C5: =抽蓄水电!C5+地方水电!C5 -> 560.05 | D5: =抽蓄水电!D5+地方水电!D5 -> 557.71 | E5: =抽蓄水电!E5+地方水电!E5 -> 557.85 | F5: =抽蓄水电!F5+地方水电!F5 -> 558.03 | G5: =抽蓄水电!G5+地方水电!G5 -> 557.97 | H5: =抽蓄水电!H5+地方水电!H5 -> 557.98 | I5: =抽蓄水电!I5+地方水电!I5 -> 558.01 | ... CS5: =抽蓄水电!CS5+地方水电!CS5 -> 446.31
A6: 46239 | B6: =抽蓄水电!B6+地方水电!B6 -> 606.59 | C6: =抽蓄水电!C6+地方水电!C6 -> 606.73 | D6: =抽蓄水电!D6+地方水电!D6 -> 605.23 | E6: =抽蓄水电!E6+地方水电!E6 -> 605.31 | F6: =抽蓄水电!F6+地方水电!F6 -> 605.58 | G6: =抽蓄水电!G6+地方水电!G6 -> 605.41 | H6: =抽蓄水电!H6+地方水电!H6 -> 605.43 | I6: =抽蓄水电!I6+地方水电!I6 -> 605.46 | ... CS6: =抽蓄水电!CS6+地方水电!CS6 -> 493.3
A7: 46240 | B7: =抽蓄水电!B7+地方水电!B7 -> 535.25 | C7: =抽蓄水电!C7+地方水电!C7 -> 535.51 | D7: =抽蓄水电!D7+地方水电!D7 -> 535.9 | E7: =抽蓄水电!E7+地方水电!E7 -> 536.23 | F7: =抽蓄水电!F7+地方水电!F7 -> 536.49 | G7: =抽蓄水电!G7+地方水电!G7 -> 536.45 | H7: =抽蓄水电!H7+地方水电!H7 -> 536.54 | I7: =抽蓄水电!I7+地方水电!I7 -> 536.56 | ... CS7: =抽蓄水电!CS7+地方水电!CS7 -> 501.95
A8: 46241 | B8: =抽蓄水电!B8+地方水电!B8 -> 474.04 | C8: =抽蓄水电!C8+地方水电!C8 -> 475.51 | D8: =抽蓄水电!D8+地方水电!D8 -> 475.99 | E8: =抽蓄水电!E8+地方水电!E8 -> 476.05 | F8: =抽蓄水电!F8+地方水电!F8 -> 476.14 | G8: =抽蓄水电!G8+地方水电!G8 -> 476.13 | H8: =抽蓄水电!H8+地方水电!H8 -> 476.22 | I8: =抽蓄水电!I8+地方水电!I8 -> 476.12 | ... CS8: =抽蓄水电!CS8+地方水电!CS8 -> 496.93
A9: 46242 | B9: =抽蓄水电!B9+地方水电!B9 -> 140.81 | C9: =抽蓄水电!C9+地方水电!C9 -> 142.44 | D9: =抽蓄水电!D9+地方水电!D9 -> 142.85 | E9: =抽蓄水电!E9+地方水电!E9 -> 141.57 | F9: =抽蓄水电!F9+地方水电!F9 -> 141.73 | G9: =抽蓄水电!G9+地方水电!G9 -> 141.79 | H9: =抽蓄水电!H9+地方水电!H9 -> 141.86 | I9: =抽蓄水电!I9+地方水电!I9 -> 141.8 | ... CS9: =抽蓄水电!CS9+地方水电!CS9 -> 498.66
A10: 46243 | B10: =抽蓄水电!B10+地方水电!B10 -> 386.82 | C10: =抽蓄水电!C10+地方水电!C10 -> 387.32 | D10: =抽蓄水电!D10+地方水电!D10 -> 387.45 | E10: =抽蓄水电!E10+地方水电!E10 -> 385.97 | F10: =抽蓄水电!F10+地方水电!F10 -> 386.14 | G10: =抽蓄水电!G10+地方水电!G10 -> 386.07 | H10: =抽蓄水电!H10+地方水电!H10 -> 386.14 | I10: =抽蓄水电!I10+地方水电!I10 -> 385.98 | ... CS10: =抽蓄水电!CS10+地方水电!CS10 -> 492.17
A11: 46244 | B11: =抽蓄水电!B11+地方水电!B11 -> 483.09 | C11: =抽蓄水电!C11+地方水电!C11 -> 482.09 | D11: =抽蓄水电!D11+地方水电!D11 -> 482.14 | E11: =抽蓄水电!E11+地方水电!E11 -> 480.75 | F11: =抽蓄水电!F11+地方水电!F11 -> 480.83 | G11: =抽蓄水电!G11+地方水电!G11 -> 480.79 | H11: =抽蓄水电!H11+地方水电!H11 -> 480.85 | I11: =抽蓄水电!I11+地方水电!I11 -> 480.83 | ... CS11: =抽蓄水电!CS11+地方水电!CS11 -> 494.36
A12: 46245 | B12: =抽蓄水电!B12+地方水电!B12 -> 484.6 | C12: =抽蓄水电!C12+地方水电!C12 -> 483.7 | D12: =抽蓄水电!D12+地方水电!D12 -> 483.62 | E12: =抽蓄水电!E12+地方水电!E12 -> 483.47 | F12: =抽蓄水电!F12+地方水电!F12 -> 442.42 | G12: =抽蓄水电!G12+地方水电!G12 -> 442.19 | H12: =抽蓄水电!H12+地方水电!H12 -> 442.11 | I12: =抽蓄水电!I12+地方水电!I12 -> 442.02 | ... CS12: =抽蓄水电!CS12+地方水电!CS12 -> 492.35
A13: 46246 | B13: =抽蓄水电!B13+地方水电!B13 -> 485.71 | C13: =抽蓄水电!C13+地方水电!C13 -> 485.84 | D13: =抽蓄水电!D13+地方水电!D13 -> 484.43 | E13: =抽蓄水电!E13+地方水电!E13 -> 484.28 | F13: =抽蓄水电!F13+地方水电!F13 -> 484.25 | G13: =抽蓄水电!G13+地方水电!G13 -> 484.05 | H13: =抽蓄水电!H13+地方水电!H13 -> 483.97 | I13: =抽蓄水电!I13+地方水电!I13 -> 483.82 | ... CS13: =抽蓄水电!CS13+地方水电!CS13 -> 421.76
... A23: 46256 | B23: =抽蓄水电!B23+地方水电!B23 -> 340.28 | C23: =抽蓄水电!C23+地方水电!C23 -> 337.24 | D23: =抽蓄水电!D23+地方水电!D23 -> 334.35 | E23: =抽蓄水电!E23+地方水电!E23 -> 332.55 | F23: =抽蓄水电!F23+地方水电!F23 -> 332.38 | G23: =抽蓄水电!G23+地方水电!G23 -> 331.73 | H23: =抽蓄水电!H23+地方水电!H23 -> 331.99 | I23: =抽蓄水电!I23+地方水电!I23 -> 331.98 | ... CS23: =抽蓄水电!CS23+地方水电!CS23 -> 222.78
A24: 46257 | B24: =抽蓄水电!B24+地方水电!B25 -> 464.91 | C24: =抽蓄水电!C24+地方水电!C25 -> 471.09 | D24: =抽蓄水电!D24+地方水电!D25 -> 471.1 | E24: =抽蓄水电!E24+地方水电!E25 -> 471.25 | F24: =抽蓄水电!F24+地方水电!F25 -> 471.23 | G24: =抽蓄水电!G24+地方水电!G25 -> 471.38 | H24: =抽蓄水电!H24+地方水电!H25 -> 471.11 | I24: =抽蓄水电!I24+地方水电!I25 -> 472.9 | ... CS24: =抽蓄水电!CS24+地方水电!CS25 -> 400.58
A25: 46258 | B25: =抽蓄水电!B25+地方水电!B26 -> 442.68 | C25: =抽蓄水电!C25+地方水电!C26 -> 449.99 | D25: =抽蓄水电!D25+地方水电!D26 -> 449.99 | E25: =抽蓄水电!E25+地方水电!E26 -> 450.17 | F25: =抽蓄水电!F25+地方水电!F26 -> 450.57 | G25: =抽蓄水电!G25+地方水电!G26 -> 450.63 | H25: =抽蓄水电!H25+地方水电!H26 -> 450.46 | I25: =抽蓄水电!I25+地方水电!I26 -> 452.21 | ... CS25: =抽蓄水电!CS25+地方水电!CS26 -> 450.94
A26: 46259 | B26: =抽蓄水电!B26+地方水电!B27 -> 513.86 | C26: =抽蓄水电!C26+地方水电!C27 -> 516.65 | D26: =抽蓄水电!D26+地方水电!D27 -> 519.01 | E26: =抽蓄水电!E26+地方水电!E27 -> 519.22 | F26: =抽蓄水电!F26+地方水电!F27 -> 519.65 | G26: =抽蓄水电!G26+地方水电!G27 -> 519.67 | H26: =抽蓄水电!H26+地方水电!H27 -> 517.35 | I26: =抽蓄水电!I26+地方水电!I27 -> 517.91 | ... CS26: =抽蓄水电!CS26+地方水电!CS27 -> 514.45
A27: 46260 | B27: =抽蓄水电!B27+地方水电!B28 -> 534.71 | C27: =抽蓄水电!C27+地方水电!C28 -> 541.14 | D27: =抽蓄水电!D27+地方水电!D28 -> 544.86 | E27: =抽蓄水电!E27+地方水电!E28 -> 544.89 | F27: =抽蓄水电!F27+地方水电!F28 -> 546.14 | G27: =抽蓄水电!G27+地方水电!G28 -> 546.95 | H27: =抽蓄水电!H27+地方水电!H28 -> 544.74 | I27: =抽蓄水电!I27+地方水电!I28 -> 545.41 | ... CS27: =抽蓄水电!CS27+地方水电!CS28 -> 478.32
A28: 46261 | B28: =抽蓄水电!B28+地方水电!B29 -> 301.45 | C28: =抽蓄水电!C28+地方水电!C29 -> 307.86 | D28: =抽蓄水电!D28+地方水电!D29 -> 311.67 | E28: =抽蓄水电!E28+地方水电!E29 -> 311.63 | F28: =抽蓄水电!F28+地方水电!F29 -> 312.41 | G28: =抽蓄水电!G28+地方水电!G29 -> 313.22 | H28: =抽蓄水电!H28+地方水电!H29 -> 311 | I28: =抽蓄水电!I28+地方水电!I29 -> 311.7 | ... CS28: =抽蓄水电!CS28+地方水电!CS29 -> 298.86
A29: 46262 | B29: =抽蓄水电!B29+地方水电!B30 -> 338.2 | C29: =抽蓄水电!C29+地方水电!C30 -> 345.62 | D29: =抽蓄水电!D29+地方水电!D30 -> 348.26 | E29: =抽蓄水电!E29+地方水电!E30 -> 348.39 | F29: =抽蓄水电!F29+地方水电!F30 -> 349.13 | G29: =抽蓄水电!G29+地方水电!G30 -> 349.99 | H29: =抽蓄水电!H29+地方水电!H30 -> 350 | I29: =抽蓄水电!I29+地方水电!I30 -> 350.19 | ... CS29: =抽蓄水电!CS29+地方水电!CS30 -> 240.37
A30: 46263 | B30: =抽蓄水电!B30+地方水电!B31 -> 240.15 | C30: =抽蓄水电!C30+地方水电!C31 -> 242.81 | D30: =抽蓄水电!D30+地方水电!D31 -> 244.09 | E30: =抽蓄水电!E30+地方水电!E31 -> 244.29 | F30: =抽蓄水电!F30+地方水电!F31 -> 244.02 | G30: =抽蓄水电!G30+地方水电!G31 -> 244.22 | H30: =抽蓄水电!H30+地方水电!H31 -> 244.22 | I30: =抽蓄水电!I30+地方水电!I31 -> 244.26 | ... CS30: =抽蓄水电!CS30+地方水电!CS31 -> 301.63
A31: 46264 | B31: =抽蓄水电!B31+地方水电!B32 -> 236.48 | C31: =抽蓄水电!C31+地方水电!C32 -> 239.14 | D31: =抽蓄水电!D31+地方水电!D32 -> 240.39 | E31: =抽蓄水电!E31+地方水电!E32 -> 240.61 | F31: =抽蓄水电!F31+地方水电!F32 -> 240.56 | G31: =抽蓄水电!G31+地方水电!G32 -> 240.76 | H31: =抽蓄水电!H31+地方水电!H32 -> 240.76 | I31: =抽蓄水电!I31+地方水电!I32 -> 240.75 | ... CS31: =抽蓄水电!CS31+地方水电!CS32 -> 343.91
A32: 46265 | B32: =抽蓄水电!B32+地方水电!B33 -> 126 | C32: =抽蓄水电!C32+地方水电!C33 -> 126 | D32: =抽蓄水电!D32+地方水电!D33 -> 126 | E32: =抽蓄水电!E32+地方水电!E33 -> 126 | F32: =抽蓄水电!F32+地方水电!F33 -> 126 | G32: =抽蓄水电!G32+地方水电!G33 -> 126 | H32: =抽蓄水电!H32+地方水电!H33 -> 126 | I32: =抽蓄水电!I32+地方水电!I33 -> 126 | ... CS32: =抽蓄水电!CS32+地方水电!CS33 -> 188

Sheet 核电
A1: 日期 | B1: 0.010416667 | C1: 0.020833333 | D1: 0.03125 | E1: 0.041666667 | F1: 0.052083333 | G1: 0.0625 | H1: 0.072916667 | I1: 0.083333333 | J1: 0.09375 | K1: 0.10416667 | L1: 0.11458333 | M1: 0.125 | N1: 0.13541667 | O1: 0.14583333 | P1: 0.15625 | Q1: 0.16666667 | R1: 0.17708333 | S1: 0.1875 | T1: 0.19791667 | U1: 0.20833333 | V1: 0.21875 | W1: 0.22916667 | X1: 0.23958333 | Y1: 0.25 | Z1: 0.26041667 | AA1: 0.27083333 | AB1: 0.28125 | AC1: 0.29166667 | AD1: 0.30208333 | AE1: 0.3125 | AF1: 0.32291667 | AG1: 0.33333333 | AH1: 0.34375 | AI1: 0.35416667 | AJ1: 0.36458333 | AK1: 0.375 | AL1: 0.38541667 | AM1: 0.39583333 | AN1: 0.40625 | AO1: 0.41666667 | AP1: 0.42708333 | AQ1: 0.4375 | AR1: 0.44791667 | AS1: 0.45833333 | AT1: 0.46875 | AU1: 0.47916667 | AV1: 0.48958333 | AW1: 0.5 | AX1: 0.51041667 | AY1: 0.52083333 | AZ1: 0.53125 | BA1: 0.54166667 | BB1: 0.55208333 | BC1: 0.5625 | BD1: 0.57291667 | BE1: 0.58333333 | BF1: 0.59375 | BG1: 0.60416667 | BH1: 0.61458333 | BI1: 0.625 | BJ1: 0.63541667 | BK1: 0.64583333 | BL1: 0.65625 | BM1: 0.66666667 | BN1: 0.67708333 | BO1: 0.6875 | BP1: 0.69791667 | BQ1: 0.70833333 | BR1: 0.71875 | BS1: 0.72916667 | BT1: 0.73958333 | BU1: 0.75 | BV1: 0.76041667 | BW1: 0.77083333 | BX1: 0.78125 | BY1: 0.79166667 | BZ1: 0.80208333 | CA1: 0.8125 | CB1: 0.82291667 | CC1: 0.83333333 | CD1: 0.84375 | CE1: 0.85416667 | CF1: 0.86458333 | CG1: 0.875 | CH1: 0.88541667 | CI1: 0.89583333 | CJ1: 0.90625 | CK1: 0.91666667 | CL1: 0.92708333 | CM1: 0.9375 | CN1: 0.94791667 | CO1: 0.95833333 | CP1: 0.96875 | CQ1: 0.97916667 | CR1: 0.98958333 | CS1: 1
A2: 46235 | B2: 6345 | C2: 6345 | D2: 6345 | E2: 6345 | F2: 6345 | G2: 6345 | H2: 6345 | I2: 6345 | J2: 6345 | K2: 6345 | L2: 6345 | M2: 6345 | N2: 6345 | O2: 6345 | P2: 6345 | Q2: 6345 | R2: 6345 | S2: 6345 | T2: 6345 | U2: 6345 | V2: 6345 | W2: 6345 | X2: 6345 | Y2: 6345 | Z2: 6345 | AA2: 6345 | AB2: 6345 | AC2: 6345 | AD2: 6345 | AE2: 6345 | AF2: 6345 | AG2: 6345 | AH2: 6345 | AI2: 6345 | AJ2: 6345 | AK2: 6345 | AL2: 6345 | AM2: 6345 | AN2: 6345 | AO2: 6345 | AP2: 6345 | AQ2: 6345 | AR2: 6345 | AS2: 6345 | AT2: 6345 | AU2: 6345 | AV2: 6345 | AW2: 6345 | AX2: 6345 | AY2: 6345 | AZ2: 6345 | BA2: 6345 | BB2: 6345 | BC2: 6345 | BD2: 6345 | BE2: 6345 | BF2: 6345 | BG2: 6345 | BH2: 6345 | BI2: 6345 | BJ2: 6345 | BK2: 6345 | BL2: 6345 | BM2: 6345 | BN2: 6345 | BO2: 6345 | BP2: 6345 | BQ2: 6345 | BR2: 6345 | BS2: 6345 | BT2: 6345 | BU2: 6345 | BV2: 6345 | BW2: 6345 | BX2: 6345 | BY2: 6345 | BZ2: 6345 | CA2: 6345 | CB2: 6345 | CC2: 6345 | CD2: 6345 | CE2: 6345 | CF2: 6345 | CG2: 6345 | CH2: 6345 | CI2: 6345 | CJ2: 6345 | CK2: 6345 | CL2: 6345 | CM2: 6345 | CN2: 6345 | CO2: 6345 | CP2: 6345 | CQ2: 6345 | CR2: 6345 | CS2: 6345
A3: 46236 | B3: 6337 | C3: 6337 | D3: 6337 | E3: 6337 | F3: 6337 | G3: 6337 | H3: 6337 | I3: 6337 | J3: 6337 | K3: 6337 | L3: 6337 | M3: 6337 | N3: 6337 | O3: 6337 | P3: 6337 | Q3: 6337 | R3: 6337 | S3: 6337 | T3: 6337 | U3: 6337 | V3: 6337 | W3: 6337 | X3: 6337 | Y3: 6337 | Z3: 6337 | AA3: 6337 | AB3: 6337 | AC3: 6337 | AD3: 6337 | AE3: 6337 | AF3: 6337 | AG3: 6337 | AH3: 6337 | AI3: 6337 | AJ3: 6337 | AK3: 6337 | AL3: 6337 | AM3: 6337 | AN3: 6337 | AO3: 6337 | AP3: 6337 | AQ3: 6337 | AR3: 6337 | AS3: 6337 | AT3: 6337 | AU3: 6337 | AV3: 6337 | AW3: 6337 | AX3: 6337 | AY3: 6337 | AZ3: 6337 | BA3: 6337 | BB3: 6337 | BC3: 6337 | BD3: 6337 | BE3: 6337 | BF3: 6337 | BG3: 6337 | BH3: 6337 | BI3: 6337 | BJ3: 6337 | BK3: 6337 | BL3: 6337 | BM3: 6337 | BN3: 6337 | BO3: 6337 | BP3: 6337 | BQ3: 6337 | BR3: 6337 | BS3: 6337 | BT3: 6337 | BU3: 6337 | BV3: 6337 | BW3: 6337 | BX3: 6337 | BY3: 6337 | BZ3: 6337 | CA3: 6337 | CB3: 6337 | CC3: 6337 | CD3: 6337 | CE3: 6337 | CF3: 6337 | CG3: 6337 | CH3: 6337 | CI3: 6337 | CJ3: 6337 | CK3: 6337 | CL3: 6337 | CM3: 6337 | CN3: 6337 | CO3: 6337 | CP3: 6337 | CQ3: 6337 | CR3: 6337 | CS3: 6337
A4: 46237 | B4: 6326 | C4: 6326 | D4: 6326 | E4: 6326 | F4: 6326 | G4: 6326 | H4: 6326 | I4: 6326 | J4: 6326 | K4: 6326 | L4: 6326 | M4: 6326 | N4: 6326 | O4: 6326 | P4: 6326 | Q4: 6326 | R4: 6326 | S4: 6326 | T4: 6326 | U4: 6326 | V4: 6326 | W4: 6326 | X4: 6326 | Y4: 6326 | Z4: 6326 | AA4: 6326 | AB4: 6326 | AC4: 6326 | AD4: 6326 | AE4: 6326 | AF4: 6326 | AG4: 6326 | AH4: 6326 | AI4: 6326 | AJ4: 6326 | AK4: 6326 | AL4: 6326 | AM4: 6326 | AN4: 6326 | AO4: 6326 | AP4: 6326 | AQ4: 6326 | AR4: 6326 | AS4: 6326 | AT4: 6326 | AU4: 6326 | AV4: 6326 | AW4: 6326 | AX4: 6326 | AY4: 6326 | AZ4: 6326 | BA4: 6326 | BB4: 6326 | BC4: 6326 | BD4: 6326 | BE4: 6326 | BF4: 6326 | BG4: 6326 | BH4: 6326 | BI4: 6326 | BJ4: 6326 | BK4: 6326 | BL4: 6326 | BM4: 6326 | BN4: 6326 | BO4: 6326 | BP4: 6326 | BQ4: 6326 | BR4: 6326 | BS4: 6326 | BT4: 6326 | BU4: 6326 | BV4: 6326 | BW4: 6326 | BX4: 6326 | BY4: 6326 | BZ4: 6326 | CA4: 6326 | CB4: 6326 | CC4: 6326 | CD4: 6326 | CE4: 6326 | CF4: 6326 | CG4: 6326 | CH4: 6326 | CI4: 6326 | CJ4: 6326 | CK4: 6326 | CL4: 6326 | CM4: 6326 | CN4: 6326 | CO4: 6326 | CP4: 6326 | CQ4: 6326 | CR4: 6326 | CS4: 6326
A5: 46238 | B5: 6298 | C5: 6298 | D5: 6298 | E5: 6298 | F5: 6298 | G5: 6298 | H5: 6298 | I5: 6298 | J5: 6298 | K5: 6298 | L5: 6298 | M5: 6298 | N5: 6298 | O5: 6298 | P5: 6298 | Q5: 6298 | R5: 6298 | S5: 6298 | T5: 6298 | U5: 6298 | V5: 6298 | W5: 6298 | X5: 6298 | Y5: 6298 | Z5: 6298 | AA5: 6298 | AB5: 6298 | AC5: 6298 | AD5: 6298 | AE5: 6298 | AF5: 6298 | AG5: 6298 | AH5: 6298 | AI5: 6298 | AJ5: 6298 | AK5: 6298 | AL5: 6298 | AM5: 6298 | AN5: 6298 | AO5: 6298 | AP5: 6298 | AQ5: 6298 | AR5: 6298 | AS5: 6298 | AT5: 6298 | AU5: 6298 | AV5: 6298 | AW5: 6298 | AX5: 6298 | AY5: 6298 | AZ5: 6298 | BA5: 6298 | BB5: 6298 | BC5: 6298 | BD5: 6298 | BE5: 6298 | BF5: 6298 | BG5: 6298 | BH5: 6298 | BI5: 6298 | BJ5: 6298 | BK5: 6298 | BL5: 6298 | BM5: 6298 | BN5: 6298 | BO5: 6298 | BP5: 6298 | BQ5: 6298 | BR5: 6298 | BS5: 6298 | BT5: 6298 | BU5: 6298 | BV5: 6298 | BW5: 6298 | BX5: 6298 | BY5: 6298 | BZ5: 6298 | CA5: 6298 | CB5: 6298 | CC5: 6298 | CD5: 6298 | CE5: 6298 | CF5: 6298 | CG5: 6298 | CH5: 6298 | CI5: 6298 | CJ5: 6298 | CK5: 6298 | CL5: 6298 | CM5: 6298 | CN5: 6298 | CO5: 6298 | CP5: 6298 | CQ5: 6298 | CR5: 6298 | CS5: 6298
A6: 46239 | B6: 6289 | C6: 6289 | D6: 6289 | E6: 6289 | F6: 6289 | G6: 6289 | H6: 6289 | I6: 6289 | J6: 6289 | K6: 6289 | L6: 6289 | M6: 6289 | N6: 6289 | O6: 6289 | P6: 6289 | Q6: 6289 | R6: 6289 | S6: 6289 | T6: 6289 | U6: 6289 | V6: 6289 | W6: 6289 | X6: 6289 | Y6: 6289 | Z6: 6289 | AA6: 6289 | AB6: 6289 | AC6: 6289 | AD6: 6289 | AE6: 6289 | AF6: 6289 | AG6: 6289 | AH6: 6289 | AI6: 6289 | AJ6: 6289 | AK6: 6289 | AL6: 6289 | AM6: 6289 | AN6: 6289 | AO6: 6289 | AP6: 6289 | AQ6: 6289 | AR6: 6289 | AS6: 6289 | AT6: 6289 | AU6: 6289 | AV6: 6289 | AW6: 6289 | AX6: 6289 | AY6: 6289 | AZ6: 6289 | BA6: 6289 | BB6: 6289 | BC6: 6289 | BD6: 6289 | BE6: 6289 | BF6: 6289 | BG6: 6289 | BH6: 6289 | BI6: 6289 | BJ6: 6289 | BK6: 6289 | BL6: 6289 | BM6: 6289 | BN6: 6289 | BO6: 6289 | BP6: 6289 | BQ6: 6289 | BR6: 6289 | BS6: 6289 | BT6: 6289 | BU6: 6289 | BV6: 6289 | BW6: 6289 | BX6: 6289 | BY6: 6289 | BZ6: 6289 | CA6: 6289 | CB6: 6289 | CC6: 6289 | CD6: 6289 | CE6: 6289 | CF6: 6289 | CG6: 6289 | CH6: 6289 | CI6: 6289 | CJ6: 6289 | CK6: 6289 | CL6: 6289 | CM6: 6289 | CN6: 6289 | CO6: 6289 | CP6: 6289 | CQ6: 6289 | CR6: 6289 | CS6: 6289
A7: 46240 | B7: 6277 | C7: 6277 | D7: 6277 | E7: 6277 | F7: 6277 | G7: 6277 | H7: 6277 | I7: 6277 | J7: 6277 | K7: 6277 | L7: 6277 | M7: 6277 | N7: 6277 | O7: 6277 | P7: 6277 | Q7: 6277 | R7: 6277 | S7: 6277 | T7: 6277 | U7: 6277 | V7: 6277 | W7: 6277 | X7: 6277 | Y7: 6277 | Z7: 6277 | AA7: 6277 | AB7: 6277 | AC7: 6277 | AD7: 6277 | AE7: 6277 | AF7: 6277 | AG7: 6277 | AH7: 6277 | AI7: 6277 | AJ7: 6277 | AK7: 6277 | AL7: 6277 | AM7: 6277 | AN7: 6277 | AO7: 6277 | AP7: 6277 | AQ7: 6277 | AR7: 6277 | AS7: 6277 | AT7: 6277 | AU7: 6277 | AV7: 6277 | AW7: 6277 | AX7: 6277 | AY7: 6277 | AZ7: 6277 | BA7: 6277 | BB7: 6277 | BC7: 6277 | BD7: 6277 | BE7: 6277 | BF7: 6277 | BG7: 6277 | BH7: 6277 | BI7: 6277 | BJ7: 6267 | BK7: 6267 | BL7: 6257 | BM7: 6257 | BN7: 6257 | BO7: 6277 | BP7: 6277 | BQ7: 6277 | BR7: 6277 | BS7: 6277 | BT7: 6277 | BU7: 6277 | BV7: 6277 | BW7: 6277 | BX7: 6277 | BY7: 6277 | BZ7: 6277 | CA7: 6277 | CB7: 6277 | CC7: 6277 | CD7: 6277 | CE7: 6277 | CF7: 6277 | CG7: 6277 | CH7: 6277 | CI7: 6277 | CJ7: 6277 | CK7: 6277 | CL7: 6277 | CM7: 6277 | CN7: 6277 | CO7: 6277 | CP7: 6277 | CQ7: 6277 | CR7: 6277 | CS7: 6277
A8: 46241 | B8: 6277 | C8: 6277 | D8: 6277 | E8: 6277 | F8: 6277 | G8: 6277 | H8: 6277 | I8: 6277 | J8: 6277 | K8: 6277 | L8: 6277 | M8: 6277 | N8: 6277 | O8: 6277 | P8: 6277 | Q8: 6277 | R8: 6277 | S8: 6277 | T8: 6277 | U8: 6277 | V8: 6277 | W8: 6277 | X8: 6277 | Y8: 6277 | Z8: 6277 | AA8: 6277 | AB8: 6277 | AC8: 6277 | AD8: 6277 | AE8: 6277 | AF8: 6277 | AG8: 6277 | AH8: 6277 | AI8: 6277 | AJ8: 6277 | AK8: 6277 | AL8: 6277 | AM8: 6277 | AN8: 6277 | AO8: 6277 | AP8: 6277 | AQ8: 6277 | AR8: 6277 | AS8: 6277 | AT8: 6277 | AU8: 6277 | AV8: 6277 | AW8: 6277 | AX8: 6277 | AY8: 6277 | AZ8: 6277 | BA8: 6277 | BB8: 6277 | BC8: 6277 | BD8: 6277 | BE8: 6277 | BF8: 6277 | BG8: 6277 | BH8: 6277 | BI8: 6277 | BJ8: 6277 | BK8: 6277 | BL8: 6277 | BM8: 6277 | BN8: 6277 | BO8: 6277 | BP8: 6277 | BQ8: 6277 | BR8: 6277 | BS8: 6277 | BT8: 6277 | BU8: 6277 | BV8: 6277 | BW8: 6277 | BX8: 6277 | BY8: 6277 | BZ8: 6277 | CA8: 6277 | CB8: 6277 | CC8: 6277 | CD8: 6277 | CE8: 6277 | CF8: 6277 | CG8: 6277 | CH8: 6277 | CI8: 6277 | CJ8: 6277 | CK8: 6277 | CL8: 6277 | CM8: 6277 | CN8: 6277 | CO8: 6277 | CP8: 6277 | CQ8: 6277 | CR8: 6277 | CS8: 6277
A9: 46242 | B9: 6277 | C9: 6277 | D9: 6277 | E9: 6277 | F9: 6277 | G9: 6277 | H9: 6277 | I9: 6277 | J9: 6277 | K9: 6277 | L9: 6277 | M9: 6277 | N9: 6277 | O9: 6277 | P9: 6277 | Q9: 6277 | R9: 6277 | S9: 6277 | T9: 6277 | U9: 6277 | V9: 6277 | W9: 6277 | X9: 6277 | Y9: 6277 | Z9: 6277 | AA9: 6277 | AB9: 6277 | AC9: 6277 | AD9: 6277 | AE9: 6277 | AF9: 6277 | AG9: 6277 | AH9: 6277 | AI9: 6277 | AJ9: 6277 | AK9: 6277 | AL9: 6277 | AM9: 6277 | AN9: 6277 | AO9: 6277 | AP9: 6277 | AQ9: 6277 | AR9: 6277 | AS9: 6277 | AT9: 6277 | AU9: 6277 | AV9: 6277 | AW9: 6277 | AX9: 6277 | AY9: 6277 | AZ9: 6277 | BA9: 6277 | BB9: 6277 | BC9: 6277 | BD9: 6277 | BE9: 6277 | BF9: 6277 | BG9: 6277 | BH9: 6277 | BI9: 6277 | BJ9: 6277 | BK9: 6277 | BL9: 6277 | BM9: 6277 | BN9: 6277 | BO9: 6277 | BP9: 6277 | BQ9: 6277 | BR9: 6277 | BS9: 6277 | BT9: 6277 | BU9: 6277 | BV9: 6277 | BW9: 6277 | BX9: 6277 | BY9: 6277 | BZ9: 6277 | CA9: 6277 | CB9: 6277 | CC9: 6277 | CD9: 6277 | CE9: 6277 | CF9: 6277 | CG9: 6277 | CH9: 6277 | CI9: 6277 | CJ9: 6277 | CK9: 6277 | CL9: 6277 | CM9: 6277 | CN9: 6277 | CO9: 6277 | CP9: 6277 | CQ9: 6277 | CR9: 6277 | CS9: 6277
A10: 46243 | B10: 6271 | C10: 6271 | D10: 6271 | E10: 6271 | F10: 6271 | G10: 6271 | H10: 6271 | I10: 6271 | J10: 6271 | K10: 6271 | L10: 6271 | M10: 6271 | N10: 6271 | O10: 6271 | P10: 6271 | Q10: 6271 | R10: 6271 | S10: 6271 | T10: 6271 | U10: 6271 | V10: 6271 | W10: 6271 | X10: 6271 | Y10: 6271 | Z10: 6271 | AA10: 6271 | AB10: 6271 | AC10: 6271 | AD10: 6271 | AE10: 6271 | AF10: 6271 | AG10: 6271 | AH10: 6271 | AI10: 6271 | AJ10: 6271 | AK10: 6271 | AL10: 6271 | AM10: 6271 | AN10: 6271 | AO10: 6271 | AP10: 6271 | AQ10: 6271 | AR10: 6271 | AS10: 6271 | AT10: 6271 | AU10: 6271 | AV10: 6271 | AW10: 6271 | AX10: 6271 | AY10: 6271 | AZ10: 6271 | BA10: 6271 | BB10: 6271 | BC10: 6271 | BD10: 6271 | BE10: 6271 | BF10: 6271 | BG10: 6271 | BH10: 6271 | BI10: 6271 | BJ10: 6271 | BK10: 6271 | BL10: 6271 | BM10: 6271 | BN10: 6271 | BO10: 6271 | BP10: 6271 | BQ10: 6271 | BR10: 6271 | BS10: 6271 | BT10: 6271 | BU10: 6271 | BV10: 6271 | BW10: 6271 | BX10: 6271 | BY10: 6271 | BZ10: 6271 | CA10: 6271 | CB10: 6271 | CC10: 6271 | CD10: 6271 | CE10: 6271 | CF10: 6271 | CG10: 6271 | CH10: 6271 | CI10: 6271 | CJ10: 6271 | CK10: 6271 | CL10: 6271 | CM10: 6271 | CN10: 6271 | CO10: 6271 | CP10: 6271 | CQ10: 6271 | CR10: 6271 | CS10: 6271
A11: 46244 | B11: 6285 | C11: 6285 | D11: 6285 | E11: 6285 | F11: 6285 | G11: 6285 | H11: 6285 | I11: 6285 | J11: 6285 | K11: 6285 | L11: 6285 | M11: 6285 | N11: 6285 | O11: 6285 | P11: 6285 | Q11: 6285 | R11: 6285 | S11: 6285 | T11: 6285 | U11: 6285 | V11: 6285 | W11: 6285 | X11: 6285 | Y11: 6285 | Z11: 6285 | AA11: 6285 | AB11: 6285 | AC11: 6285 | AD11: 6285 | AE11: 6285 | AF11: 6285 | AG11: 6285 | AH11: 6285 | AI11: 6285 | AJ11: 6285 | AK11: 6285 | AL11: 6285 | AM11: 6285 | AN11: 6285 | AO11: 6285 | AP11: 6285 | AQ11: 6285 | AR11: 6285 | AS11: 6285 | AT11: 6285 | AU11: 6285 | AV11: 6285 | AW11: 6285 | AX11: 6285 | AY11: 6285 | AZ11: 6285 | BA11: 6285 | BB11: 6285 | BC11: 6285 | BD11: 6285 | BE11: 6285 | BF11: 6285 | BG11: 6285 | BH11: 6285 | BI11: 6285 | BJ11: 6285 | BK11: 6285 | BL11: 6285 | BM11: 6285 | BN11: 6285 | BO11: 6285 | BP11: 6285 | BQ11: 6285 | BR11: 6285 | BS11: 6285 | BT11: 6285 | BU11: 6285 | BV11: 6285 | BW11: 6285 | BX11: 6285 | BY11: 6285 | BZ11: 6285 | CA11: 6285 | CB11: 6285 | CC11: 6285 | CD11: 6285 | CE11: 6285 | CF11: 6285 | CG11: 6285 | CH11: 6285 | CI11: 6285 | CJ11: 6285 | CK11: 6285 | CL11: 6285 | CM11: 6285 | CN11: 6285 | CO11: 6285 | CP11: 6285 | CQ11: 6285 | CR11: 6285 | CS11: 6285
A12: 46245 | B12: 6314 | C12: 6314 | D12: 6314 | E12: 6314 | F12: 6314 | G12: 6314 | H12: 6314 | I12: 6314 | J12: 6314 | K12: 6314 | L12: 6314 | M12: 6314 | N12: 6314 | O12: 6314 | P12: 6314 | Q12: 6314 | R12: 6314 | S12: 6314 | T12: 6314 | U12: 6314 | V12: 6314 | W12: 6314 | X12: 6314 | Y12: 6314 | Z12: 6314 | AA12: 6314 | AB12: 6314 | AC12: 6314 | AD12: 6314 | AE12: 6314 | AF12: 6314 | AG12: 6314 | AH12: 6314 | AI12: 6314 | AJ12: 6314 | AK12: 6314 | AL12: 6314 | AM12: 6314 | AN12: 6314 | AO12: 6314 | AP12: 6314 | AQ12: 6314 | AR12: 6314 | AS12: 6314 | AT12: 6314 | AU12: 6314 | AV12: 6314 | AW12: 6314 | AX12: 6314 | AY12: 6314 | AZ12: 6314 | BA12: 6314 | BB12: 6314 | BC12: 6314 | BD12: 6314 | BE12: 6314 | BF12: 6314 | BG12: 6314 | BH12: 6314 | BI12: 6314 | BJ12: 6314 | BK12: 6314 | BL12: 6314 | BM12: 6314 | BN12: 6314 | BO12: 6314 | BP12: 6314 | BQ12: 6314 | BR12: 6314 | BS12: 6314 | BT12: 6314 | BU12: 6314 | BV12: 6314 | BW12: 6314 | BX12: 6314 | BY12: 6314 | BZ12: 6314 | CA12: 6314 | CB12: 6314 | CC12: 6314 | CD12: 6314 | CE12: 6314 | CF12: 6314 | CG12: 6314 | CH12: 6314 | CI12: 6314 | CJ12: 6314 | CK12: 6314 | CL12: 6314 | CM12: 6314 | CN12: 6314 | CO12: 6314 | CP12: 6314 | CQ12: 6314 | CR12: 6314 | CS12: 6314
A13: 46246 | B13: 6362 | C13: 6362 | D13: 6362 | E13: 6362 | F13: 6362 | G13: 6362 | H13: 6362 | I13: 6362 | J13: 6362 | K13: 6362 | L13: 6362 | M13: 6362 | N13: 6362 | O13: 6362 | P13: 6362 | Q13: 6362 | R13: 6362 | S13: 6362 | T13: 6362 | U13: 6362 | V13: 6362 | W13: 6362 | X13: 6362 | Y13: 6362 | Z13: 6362 | AA13: 6362 | AB13: 6362 | AC13: 6362 | AD13: 6362 | AE13: 6362 | AF13: 6362 | AG13: 6362 | AH13: 6362 | AI13: 6362 | AJ13: 6362 | AK13: 6362 | AL13: 6362 | AM13: 6362 | AN13: 6362 | AO13: 6362 | AP13: 6355 | AQ13: 6355 | AR13: 6355 | AS13: 6342 | AT13: 6342 | AU13: 6342 | AV13: 6342 | AW13: 6362 | AX13: 6362 | AY13: 6362 | AZ13: 6362 | BA13: 6362 | BB13: 6362 | BC13: 6362 | BD13: 6362 | BE13: 6362 | BF13: 6362 | BG13: 6362 | BH13: 6362 | BI13: 6362 | BJ13: 6352 | BK13: 6352 | BL13: 6342 | BM13: 6342 | BN13: 6342 | BO13: 6362 | BP13: 6362 | BQ13: 6362 | BR13: 6362 | BS13: 6362 | BT13: 6362 | BU13: 6362 | BV13: 6362 | BW13: 6362 | BX13: 6362 | BY13: 6362 | BZ13: 6362 | CA13: 6362 | CB13: 6362 | CC13: 6362 | CD13: 6362 | CE13: 6362 | CF13: 6362 | CG13: 6362 | CH13: 6362 | CI13: 6362 | CJ13: 6362 | CK13: 6362 | CL13: 6362 | CM13: 6362 | CN13: 6362 | CO13: 6362 | CP13: 6362 | CQ13: 6362 | CR13: 6362 | CS13: 6362
... A32: 46265 | B32: 6361 | C32: 6361 | D32: 6361 | E32: 6361 | F32: 6361 | G32: 6361 | H32: 6361 | I32: 6361 | J32: 6361 | K32: 6361 | L32: 6361 | M32: 6361 | N32: 6361 | O32: 6361 | P32: 6361 | Q32: 6361 | R32: 6361 | S32: 6361 | T32: 6361 | U32: 6361 | V32: 6361 | W32: 6361 | X32: 6361 | Y32: 6361 | Z32: 6361 | AA32: 6361 | AB32: 6361 | AC32: 6361 | AD32: 6361 | AE32: 6361 | AF32: 6361 | AG32: 6361 | AH32: 6361 | AI32: 6361 | AJ32: 6361 | AK32: 6361 | AL32: 6361 | AM32: 6361 | AN32: 6361 | AO32: 6361 | AP32: 6361 | AQ32: 6361 | AR32: 6361 | AS32: 6361 | AT32: 6361 | AU32: 6361 | AV32: 6361 | AW32: 6361 | AX32: 6361 | AY32: 6361 | AZ32: 6361 | BA32: 6361 | BB32: 6361 | BC32: 6361 | BD32: 6361 | BE32: 6361 | BF32: 6361 | BG32: 6361 | BH32: 6361 | BI32: 6361 | BJ32: 6361 | BK32: 6361 | BL32: 6361 | BM32: 6361 | BN32: 6361 | BO32: 6361 | BP32: 6361 | BQ32: 6361 | BR32: 6361 | BS32: 6361 | BT32: 6361 | BU32: 6361 | BV32: 6361 | BW32: 6361 | BX32: 6361 | BY32: 6361 | BZ32: 6361 | CA32: 6361 | CB32: 6361 | CC32: 6361 | CD32: 6361 | CE32: 6361 | CF32: 6361 | CG32: 6361 | CH32: 6361 | CI32: 6361 | CJ32: 6361 | CK32: 6361 | CL32: 6361 | CM32: 6361 | CN32: 6361 | CO32: 6361 | CP32: 6361 | CQ32: 6361 | CR32: 6361 | CS32: 6361

Sheet 地方燃煤
A1: 日期 | B1: 0.010416667 | C1: 0.020833333 | D1: 0.03125 | E1: 0.041666667 | F1: 0.052083333 | G1: 0.0625 | H1: 0.072916667 | I1: 0.083333333 | J1: 0.09375 | K1: 0.10416667 | L1: 0.11458333 | M1: 0.125 | N1: 0.13541667 | O1: 0.14583333 | P1: 0.15625 | Q1: 0.16666667 | R1: 0.17708333 | S1: 0.1875 | T1: 0.19791667 | U1: 0.20833333 | V1: 0.21875 | W1: 0.22916667 | X1: 0.23958333 | Y1: 0.25 | Z1: 0.26041667 | AA1: 0.27083333 | AB1: 0.28125 | AC1: 0.29166667 | AD1: 0.30208333 | AE1: 0.3125 | AF1: 0.32291667 | AG1: 0.33333333 | AH1: 0.34375 | AI1: 0.35416667 | AJ1: 0.36458333 | AK1: 0.375 | AL1: 0.38541667 | AM1: 0.39583333 | AN1: 0.40625 | AO1: 0.41666667 | AP1: 0.42708333 | AQ1: 0.4375 | AR1: 0.44791667 | AS1: 0.45833333 | AT1: 0.46875 | AU1: 0.47916667 | AV1: 0.48958333 | AW1: 0.5 | AX1: 0.51041667 | AY1: 0.52083333 | AZ1: 0.53125 | BA1: 0.54166667 | BB1: 0.55208333 | BC1: 0.5625 | BD1: 0.57291667 | BE1: 0.58333333 | BF1: 0.59375 | BG1: 0.60416667 | BH1: 0.61458333 | BI1: 0.625 | BJ1: 0.63541667 | BK1: 0.64583333 | BL1: 0.65625 | BM1: 0.66666667 | BN1: 0.67708333 | BO1: 0.6875 | BP1: 0.69791667 | BQ1: 0.70833333 | BR1: 0.71875 | BS1: 0.72916667 | BT1: 0.73958333 | BU1: 0.75 | BV1: 0.76041667 | BW1: 0.77083333 | BX1: 0.78125 | BY1: 0.79166667 | BZ1: 0.80208333 | CA1: 0.8125 | CB1: 0.82291667 | CC1: 0.83333333 | CD1: 0.84375 | CE1: 0.85416667 | CF1: 0.86458333 | CG1: 0.875 | CH1: 0.88541667 | CI1: 0.89583333 | CJ1: 0.90625 | CK1: 0.91666667 | CL1: 0.92708333 | CM1: 0.9375 | CN1: 0.94791667 | CO1: 0.95833333 | CP1: 0.96875 | CQ1: 0.97916667 | CR1: 0.98958333 | CS1: 1
A2: 46235 | B2: 313.19 | C2: 313.19 | D2: 313.19 | E2: 313.19 | F2: 303.12 | G2: 303.12 | H2: 303.12 | I2: 303.12 | J2: 304.24 | K2: 304.24 | L2: 304.24 | M2: 304.24 | N2: 314.89 | O2: 314.89 | P2: 314.89 | Q2: 314.89 | R2: 313.99 | S2: 313.99 | T2: 313.99 | U2: 313.99 | V2: 314.34 | W2: 314.34 | X2: 314.34 | Y2: 314.34 | Z2: 314.11 | AA2: 314.11 | AB2: 314.11 | AC2: 314.11 | AD2: 314.77 | AE2: 314.77 | AF2: 314.77 | AG2: 314.77 | AH2: 313.48 | AI2: 313.48 | AJ2: 313.48 | AK2: 313.48 | AL2: 312.58 | AM2: 312.58 | AN2: 312.58 | AO2: 312.58 | AP2: 323.64 | AQ2: 323.64 | AR2: 323.64 | AS2: 323.64 | AT2: 324.76 | AU2: 324.76 | AV2: 324.76 | AW2: 324.76 | AX2: 325.3 | AY2: 325.3 | AZ2: 325.3 | BA2: 325.3 | BB2: 315.72 | BC2: 315.72 | BD2: 315.72 | BE2: 315.72 | BF2: 315.37 | BG2: 315.37 | BH2: 315.37 | BI2: 315.37 | BJ2: 314.4 | BK2: 314.4 | BL2: 314.4 | BM2: 314.4 | BN2: 315.09 | BO2: 315.09 | BP2: 315.09 | BQ2: 315.09 | BR2: 305.88 | BS2: 305.88 | BT2: 305.88 | BU2: 305.88 | BV2: 305.96 | BW2: 305.96 | BX2: 305.96 | BY2: 305.96 | BZ2: 316.35 | CA2: 316.35 | CB2: 316.35 | CC2: 316.35 | CD2: 329.79 | CE2: 329.79 | CF2: 329.79 | CG2: 329.79 | CH2: 330.62 | CI2: 330.62 | CJ2: 330.62 | CK2: 330.62 | CL2: 315.49 | CM2: 315.49 | CN2: 315.49 | CO2: 315.49 | CP2: 317.79 | CQ2: 317.79 | CR2: 317.79 | CS2: 317.79
A3: 46236 | B3: 311.69 | C3: 311.69 | D3: 311.69 | E3: 311.69 | F3: 301.62 | G3: 301.62 | H3: 301.62 | I3: 301.62 | J3: 302.74 | K3: 302.74 | L3: 302.74 | M3: 302.74 | N3: 313.39 | O3: 313.39 | P3: 313.39 | Q3: 313.39 | R3: 312.49 | S3: 312.49 | T3: 312.49 | U3: 312.49 | V3: 312.84 | W3: 312.84 | X3: 312.84 | Y3: 312.84 | Z3: 312.61 | AA3: 312.61 | AB3: 312.61 | AC3: 312.61 | AD3: 313.27 | AE3: 313.27 | AF3: 313.27 | AG3: 313.27 | AH3: 311.98 | AI3: 311.98 | AJ3: 311.98 | AK3: 311.98 | AL3: 311.08 | AM3: 311.08 | AN3: 311.08 | AO3: 311.08 | AP3: 322.14 | AQ3: 322.14 | AR3: 322.14 | AS3: 322.14 | AT3: 323.26 | AU3: 323.26 | AV3: 323.26 | AW3: 323.26 | AX3: 323.8 | AY3: 323.8 | AZ3: 323.8 | BA3: 323.8 | BB3: 314.22 | BC3: 314.22 | BD3: 314.22 | BE3: 314.22 | BF3: 313.87 | BG3: 313.87 | BH3: 313.87 | BI3: 313.87 | BJ3: 312.9 | BK3: 312.9 | BL3: 312.9 | BM3: 312.9 | BN3: 313.59 | BO3: 313.59 | BP3: 313.59 | BQ3: 313.59 | BR3: 304.38 | BS3: 304.38 | BT3: 304.38 | BU3: 304.38 | BV3: 304.46 | BW3: 304.46 | BX3: 304.46 | BY3: 304.46 | BZ3: 314.85 | CA3: 314.85 | CB3: 314.85 | CC3: 314.85 | CD3: 328.29 | CE3: 328.29 | CF3: 328.29 | CG3: 328.29 | CH3: 329.12 | CI3: 329.12 | CJ3: 329.12 | CK3: 329.12 | CL3: 313.99 | CM3: 313.99 | CN3: 313.99 | CO3: 313.99 | CP3: 316.29 | CQ3: 316.29 | CR3: 316.29 | CS3: 316.29
A4: 46237 | B4: 309.35 | C4: 309.35 | D4: 309.35 | E4: 309.35 | F4: 296.52 | G4: 296.52 | H4: 296.52 | I4: 296.52 | J4: 298.19 | K4: 298.19 | L4: 298.19 | M4: 298.19 | N4: 310.95 | O4: 310.95 | P4: 310.95 | Q4: 310.95 | R4: 311.12 | S4: 311.12 | T4: 311.12 | U4: 311.12 | V4: 311.61 | W4: 311.61 | X4: 311.61 | Y4: 311.61 | Z4: 312.06 | AA4: 312.06 | AB4: 312.06 | AC4: 312.06 | AD4: 312.4 | AE4: 312.4 | AF4: 312.4 | AG4: 312.4 | AH4: 310.2 | AI4: 310.2 | AJ4: 310.2 | AK4: 310.2 | AL4: 308.85 | AM4: 308.85 | AN4: 308.85 | AO4: 308.85 | AP4: 318.56 | AQ4: 318.56 | AR4: 318.56 | AS4: 318.56 | AT4: 318.65 | AU4: 318.65 | AV4: 318.65 | AW4: 318.65 | AX4: 321.58 | AY4: 321.58 | AZ4: 321.58 | BA4: 321.58 | BB4: 307.15 | BC4: 307.15 | BD4: 307.15 | BE4: 307.15 | BF4: 307.05 | BG4: 307.05 | BH4: 307.05 | BI4: 307.05 | BJ4: 307.11 | BK4: 307.11 | BL4: 307.11 | BM4: 307.11 | BN4: 311.05 | BO4: 311.05 | BP4: 311.05 | BQ4: 311.05 | BR4: 302.72 | BS4: 302.72 | BT4: 302.72 | BU4: 302.72 | BV4: 302.44 | BW4: 302.44 | BX4: 302.44 | BY4: 302.44 | BZ4: 313.44 | CA4: 313.44 | CB4: 313.44 | CC4: 313.44 | CD4: 327.13 | CE4: 327.13 | CF4: 327.13 | CG4: 327.13 | CH4: 326.09 | CI4: 326.09 | CJ4: 326.09 | CK4: 326.09 | CL4: 312.42 | CM4: 312.42 | CN4: 312.42 | CO4: 312.42 | CP4: 311.97 | CQ4: 311.97 | CR4: 311.97 | CS4: 311.97
A5: 46238 | B5: 309.35 | C5: 309.35 | D5: 309.35 | E5: 309.35 | F5: 296.52 | G5: 296.52 | H5: 296.52 | I5: 296.52 | J5: 298.19 | K5: 298.19 | L5: 298.19 | M5: 298.19 | N5: 310.95 | O5: 310.95 | P5: 310.95 | Q5: 310.95 | R5: 311.12 | S5: 311.12 | T5: 311.12 | U5: 311.12 | V5: 311.61 | W5: 311.61 | X5: 311.61 | Y5: 311.61 | Z5: 312.06 | AA5: 312.06 | AB5: 312.06 | AC5: 312.06 | AD5: 312.4 | AE5: 312.4 | AF5: 312.4 | AG5: 312.4 | AH5: 310.2 | AI5: 310.2 | AJ5: 310.2 | AK5: 310.2 | AL5: 308.85 | AM5: 308.85 | AN5: 308.85 | AO5: 308.85 | AP5: 318.56 | AQ5: 318.56 | AR5: 318.56 | AS5: 318.56 | AT5: 318.65 | AU5: 318.65 | AV5: 318.65 | AW5: 318.65 | AX5: 321.58 | AY5: 321.58 | AZ5: 321.58 | BA5: 321.58 | BB5: 307.15 | BC5: 307.15 | BD5: 307.15 | BE5: 307.15 | BF5: 307.05 | BG5: 307.05 | BH5: 307.05 | BI5: 307.05 | BJ5: 307.11 | BK5: 307.11 | BL5: 307.11 | BM5: 307.11 | BN5: 311.05 | BO5: 311.05 | BP5: 311.05 | BQ5: 311.05 | BR5: 302.72 | BS5: 302.72 | BT5: 302.72 | BU5: 302.72 | BV5: 302.44 | BW5: 302.44 | BX5: 302.44 | BY5: 302.44 | BZ5: 313.44 | CA5: 313.44 | CB5: 313.44 | CC5: 313.44 | CD5: 327.13 | CE5: 327.13 | CF5: 327.13 | CG5: 327.13 | CH5: 326.09 | CI5: 326.09 | CJ5: 326.09 | CK5: 326.09 | CL5: 312.42 | CM5: 312.42 | CN5: 312.42 | CO5: 312.42 | CP5: 311.97 | CQ5: 311.97 | CR5: 311.97 | CS5: 311.97
A6: 46239 | B6: 309.35 | C6: 309.35 | D6: 309.35 | E6: 309.35 | F6: 296.52 | G6: 296.52 | H6: 296.52 | I6: 296.52 | J6: 298.19 | K6: 298.19 | L6: 298.19 | M6: 298.19 | N6: 310.95 | O6: 310.95 | P6: 310.95 | Q6: 310.95 | R6: 311.12 | S6: 311.12 | T6: 311.12 | U6: 311.12 | V6: 311.61 | W6: 311.61 | X6: 311.61 | Y6: 311.61 | Z6: 312.06 | AA6: 312.06 | AB6: 312.06 | AC6: 312.06 | AD6: 312.4 | AE6: 312.4 | AF6: 312.4 | AG6: 312.4 | AH6: 310.2 | AI6: 310.2 | AJ6: 310.2 | AK6: 310.2 | AL6: 308.85 | AM6: 308.85 | AN6: 308.85 | AO6: 308.85 | AP6: 318.56 | AQ6: 318.56 | AR6: 318.56 | AS6: 318.56 | AT6: 318.65 | AU6: 318.65 | AV6: 318.65 | AW6: 318.65 | AX6: 321.58 | AY6: 321.58 | AZ6: 321.58 | BA6: 321.58 | BB6: 307.15 | BC6: 307.15 | BD6: 307.15 | BE6: 307.15 | BF6: 307.05 | BG6: 307.05 | BH6: 307.05 | BI6: 307.05 | BJ6: 307.11 | BK6: 307.11 | BL6: 307.11 | BM6: 307.11 | BN6: 311.05 | BO6: 311.05 | BP6: 311.05 | BQ6: 311.05 | BR6: 302.72 | BS6: 302.72 | BT6: 302.72 | BU6: 302.72 | BV6: 302.44 | BW6: 302.44 | BX6: 302.44 | BY6: 302.44 | BZ6: 313.44 | CA6: 313.44 | CB6: 313.44 | CC6: 313.44 | CD6: 327.13 | CE6: 327.13 | CF6: 327.13 | CG6: 327.13 | CH6: 326.09 | CI6: 326.09 | CJ6: 326.09 | CK6: 326.09 | CL6: 312.42 | CM6: 312.42 | CN6: 312.42 | CO6: 312.42 | CP6: 311.97 | CQ6: 311.97 | CR6: 311.97 | CS6: 311.97
A7: 46240 | B7: 318.15 | C7: 318.15 | D7: 318.15 | E7: 318.15 | F7: 305.32 | G7: 305.32 | H7: 305.32 | I7: 305.32 | J7: 306.99 | K7: 306.99 | L7: 306.99 | M7: 306.99 | N7: 319.75 | O7: 319.75 | P7: 319.75 | Q7: 319.75 | R7: 319.92 | S7: 319.92 | T7: 319.92 | U7: 319.92 | V7: 320.41 | W7: 320.41 | X7: 320.41 | Y7: 320.41 | Z7: 320.86 | AA7: 320.86 | AB7: 320.86 | AC7: 320.86 | AD7: 321.2 | AE7: 321.2 | AF7: 321.2 | AG7: 321.2 | AH7: 319 | AI7: 319 | AJ7: 319 | AK7: 319 | AL7: 317.65 | AM7: 317.65 | AN7: 317.65 | AO7: 317.65 | AP7: 327.36 | AQ7: 327.36 | AR7: 327.36 | AS7: 327.36 | AT7: 327.45 | AU7: 327.45 | AV7: 327.45 | AW7: 327.45 | AX7: 330.38 | AY7: 330.38 | AZ7: 330.38 | BA7: 330.38 | BB7: 315.95 | BC7: 315.95 | BD7: 315.95 | BE7: 315.95 | BF7: 315.85 | BG7: 315.85 | BH7: 315.85 | BI7: 315.85 | BJ7: 315.91 | BK7: 315.91 | BL7: 315.91 | BM7: 315.91 | BN7: 319.85 | BO7: 319.85 | BP7: 319.85 | BQ7: 319.85 | BR7: 311.52 | BS7: 311.52 | BT7: 311.52 | BU7: 311.52 | BV7: 311.24 | BW7: 311.24 | BX7: 311.24 | BY7: 311.24 | BZ7: 322.24 | CA7: 322.24 | CB7: 322.24 | CC7: 322.24 | CD7: 335.93 | CE7: 335.93 | CF7: 335.93 | CG7: 335.93 | CH7: 334.89 | CI7: 334.89 | CJ7: 334.89 | CK7: 334.89 | CL7: 321.22 | CM7: 321.22 | CN7: 321.22 | CO7: 321.22 | CP7: 320.77 | CQ7: 320.77 | CR7: 320.77 | CS7: 320.77
A8: 46241 | B8: 319.65 | C8: 319.65 | D8: 319.65 | E8: 319.65 | F8: 308 | G8: 308 | H8: 308 | I8: 308 | J8: 307.68 | K8: 307.68 | L8: 307.68 | M8: 307.68 | N8: 319.42 | O8: 319.42 | P8: 319.42 | Q8: 319.42 | R8: 319.65 | S8: 319.65 | T8: 319.65 | U8: 319.65 | V8: 318.48 | W8: 318.48 | X8: 318.48 | Y8: 318.48 | Z8: 319.05 | AA8: 319.05 | AB8: 319.05 | AC8: 319.05 | AD8: 319.05 | AE8: 319.05 | AF8: 319.05 | AG8: 319.05 | AH8: 319.6 | AI8: 319.6 | AJ8: 319.6 | AK8: 319.6 | AL8: 318.71 | AM8: 318.71 | AN8: 318.71 | AO8: 318.71 | AP8: 329.1 | AQ8: 329.1 | AR8: 329.1 | AS8: 329.1 | AT8: 325.33 | AU8: 325.33 | AV8: 325.33 | AW8: 325.33 | AX8: 324.12 | AY8: 324.12 | AZ8: 324.12 | BA8: 324.12 | BB8: 317.84 | BC8: 317.84 | BD8: 317.84 | BE8: 317.84 | BF8: 318.82 | BG8: 318.82 | BH8: 318.82 | BI8: 318.82 | BJ8: 316.78 | BK8: 316.78 | BL8: 316.78 | BM8: 316.78 | BN8: 318.39 | BO8: 318.39 | BP8: 318.39 | BQ8: 318.39 | BR8: 309.35 | BS8: 309.35 | BT8: 309.35 | BU8: 309.35 | BV8: 306.19 | BW8: 306.19 | BX8: 306.19 | BY8: 306.19 | BZ8: 322.36 | CA8: 322.36 | CB8: 322.36 | CC8: 322.36 | CD8: 331.39 | CE8: 331.39 | CF8: 331.39 | CG8: 331.39 | CH8: 330.82 | CI8: 330.82 | CJ8: 330.82 | CK8: 330.82 | CL8: 319.17 | CM8: 319.17 | CN8: 319.17 | CO8: 319.17 | CP8: 318.65 | CQ8: 318.65 | CR8: 318.65 | CS8: 318.65
A9: 46242 | B9: 319.65 | C9: 319.65 | D9: 319.65 | E9: 319.65 | F9: 308 | G9: 308 | H9: 308 | I9: 308 | J9: 307.68 | K9: 307.68 | L9: 307.68 | M9: 307.68 | N9: 319.42 | O9: 319.42 | P9: 319.42 | Q9: 319.42 | R9: 319.65 | S9: 319.65 | T9: 319.65 | U9: 319.65 | V9: 318.48 | W9: 318.48 | X9: 318.48 | Y9: 318.48 | Z9: 319.05 | AA9: 319.05 | AB9: 319.05 | AC9: 319.05 | AD9: 319.05 | AE9: 319.05 | AF9: 319.05 | AG9: 319.05 | AH9: 319.6 | AI9: 319.6 | AJ9: 319.6 | AK9: 319.6 | AL9: 318.71 | AM9: 318.71 | AN9: 318.71 | AO9: 318.71 | AP9: 329.1 | AQ9: 329.1 | AR9: 329.1 | AS9: 329.1 | AT9: 325.33 | AU9: 325.33 | AV9: 325.33 | AW9: 325.33 | AX9: 324.12 | AY9: 324.12 | AZ9: 324.12 | BA9: 324.12 | BB9: 317.84 | BC9: 317.84 | BD9: 317.84 | BE9: 317.84 | BF9: 318.82 | BG9: 318.82 | BH9: 318.82 | BI9: 318.82 | BJ9: 316.78 | BK9: 316.78 | BL9: 316.78 | BM9: 316.78 | BN9: 318.39 | BO9: 318.39 | BP9: 318.39 | BQ9: 318.39 | BR9: 309.35 | BS9: 309.35 | BT9: 309.35 | BU9: 309.35 | BV9: 306.19 | BW9: 306.19 | BX9: 306.19 | BY9: 306.19 | BZ9: 322.36 | CA9: 322.36 | CB9: 322.36 | CC9: 322.36 | CD9: 331.39 | CE9: 331.39 | CF9: 331.39 | CG9: 331.39 | CH9: 330.82 | CI9: 330.82 | CJ9: 330.82 | CK9: 330.82 | CL9: 319.17 | CM9: 319.17 | CN9: 319.17 | CO9: 319.17 | CP9: 318.65 | CQ9: 318.65 | CR9: 318.65 | CS9: 318.65
