Workbook

Sheet 负荷
A1: 日期 | B1: 0.010416667 | C1: 0.020833333 | D1: 0.03125 | E1: 0.041666667 | F1: 0.052083333 | G1: 0.0625 | H1: 0.072916667 | I1: 0.083333333 | J1: 0.09375 | K1: 0.10416667 | L1: 0.11458333 | M1: 0.125 | N1: 0.13541667 | O1: 0.14583333 | P1: 0.15625 | Q1: 0.16666667 | R1: 0.17708333 | S1: 0.1875 | T1: 0.19791667 | U1: 0.20833333 | V1: 0.21875 | W1: 0.22916667 | X1: 0.23958333 | Y1: 0.25 | Z1: 0.26041667 | AA1: 0.27083333 | AB1: 0.28125 | AC1: 0.29166667 | AD1: 0.30208333 | AE1: 0.3125 | AF1: 0.32291667 | AG1: 0.33333333 | AH1: 0.34375 | AI1: 0.35416667 | AJ1: 0.36458333 | AK1: 0.375 | AL1: 0.38541667 | AM1: 0.39583333 | AN1: 0.40625 | AO1: 0.41666667 | AP1: 0.42708333 | AQ1: 0.4375 | AR1: 0.44791667 | AS1: 0.45833333 | AT1: 0.46875 | AU1: 0.47916667 | AV1: 0.48958333 | AW1: 0.5 | AX1: 0.51041667 | AY1: 0.52083333 | AZ1: 0.53125 | BA1: 0.54166667 | BB1: 0.55208333 | BC1: 0.5625 | BD1: 0.57291667 | BE1: 0.58333333 | BF1: 0.59375 | BG1: 0.60416667 | BH1: 0.61458333 | BI1: 0.625 | BJ1: 0.63541667 | BK1: 0.64583333 | BL1: 0.65625 | BM1: 0.66666667 | BN1: 0.67708333 | BO1: 0.6875 | BP1: 0.69791667 | BQ1: 0.70833333 | BR1: 0.71875 | BS1: 0.72916667 | BT1: 0.73958333 | BU1: 0.75 | BV1: 0.76041667 | BW1: 0.77083333 | BX1: 0.78125 | BY1: 0.79166667 | BZ1: 0.80208333 | CA1: 0.8125 | CB1: 0.82291667 | CC1: 0.83333333 | CD1: 0.84375 | CE1: 0.85416667 | CF1: 0.86458333 | CG1: 0.875 | CH1: 0.88541667 | CI1: 0.89583333 | CJ1: 0.90625 | CK1: 0.91666667 | CL1: 0.92708333 | CM1: 0.9375 | CN1: 0.94791667 | CO1: 0.95833333 | CP1: 0.96875 | CQ1: 0.97916667 | CR1: 0.98958333 | CS1: 1
A2: 46235 | B2: 33942.6 | C2: 33732.3 | D2: 33342 | E2: 32911.7 | F2: 32507.3 | G2: 32250.5 | H2: 31941.1 | I2: 31818.6 | J2: 31815.9 | K2: 31595.2 | L2: 31504.6 | M2: 31472 | N2: 31277.9 | O2: 31194.6 | P2: 31275.4 | Q2: 31097.3 | R2: 31291.1 | S2: 31098.9 | T2: 31288 | U2: 31415.9 | V2: 31971.1 | W2: 32352.7 | X2: 32561.9 | Y2: 33089.7 | Z2: 33227.9 | AA2: 34081.5 | AB2: 34678.3 | AC2: 35002.7 | AD2: 35965.9 | AE2: 36696 | AF2: 37593.7 | AG2: 38427.7 | AH2: 39920.1 | AI2: 40544.1 | AJ2: 41254.6 | AK2: 41683.5 | AL2: 42740.9 | AM2: 43546.7 | AN2: 43665.8 | AO2: 43643.3 | AP2: 44138.7 | AQ2: 44675.3 | AR2: 44745.8 | AS2: 44486.6 | AT2: 44128 | AU2: 44707.9 | AV2: 44431.6 | AW2: 44614.2 | AX2: 44269.6 | AY2: 44445.2 | AZ2: 44888.5 | BA2: 44431.1 | BB2: 45002.7 | BC2: 44682.2 | BD2: 44674.3 | BE2: 44331.9 | BF2: 44121.4 | BG2: 44287 | BH2: 44198.7 | BI2: 44155 | BJ2: 44049.8 | BK2: 44182.1 | BL2: 44356.5 | BM2: 44051 | BN2: 44415 | BO2: 44063.7 | BP2: 43848.2 | BQ2: 43114.8 | BR2: 42759.5 | BS2: 42797.7 | BT2: 42415.8 | BU2: 42350.1 | BV2: 41959 | BW2: 41789.5 | BX2: 42139.8 | BY2: 41903.1 | BZ2: 42167.6 | CA2: 42131 | CB2: 42540.6 | CC2: 42417.2 | CD2: 42071.4 | CE2: 42104.6 | CF2: 41630.1 | CG2: 41104 | CH2: 40844.3 | CI2: 40119.3 | CJ2: 39394.6 | CK2: 38821.2 | CL2: 38716.2 | CM2: 38026.2 | CN2: 37230.9 | CO2: 36533.9 | CP2: 35949.7 | CQ2: 35320 | CR2: 34844.5 | CS2: 34102.1
A3: 46236 | B3: 33700.7 | C3: 33603.4 | D3: 33224.1 | E3: 32850.5 | F3: 32627.5 | G3: 32185 | H3: 32011.8 | I3: 31623.7 | J3: 31477.1 | K3: 31503.5 | L3: 31371.4 | M3: 30972.3 | N3: 30909.3 | O3: 30827.8 | P3: 30882.8 | Q3: 30583.9 | R3: 30926.5 | S3: 30848.3 | T3: 30656 | U3: 30862.5 | V3: 31197.6 | W3: 31432.3 | X3: 31888 | Y3: 32279.7 | Z3: 32680.1 | AA3: 33268.1 | AB3: 33732.8 | AC3: 34295 | AD3: 34692.4 | AE3: 35367.3 | AF3: 36220.2 | AG3: 37198.4 | AH3: 37979 | AI3: 38647.6 | AJ3: 39606.3 | AK3: 39945.1 | AL3: 40668.2 | AM3: 41438.5 | AN3: 41923 | AO3: 42700.3 | AP3: 42937.3 | AQ3: 42792.3 | AR3: 43356.4 | AS3: 43761.2 | AT3: 43717.8 | AU3: 43898.8 | AV3: 43560.2 | AW3: 43375.4 | AX3: 43763 | AY3: 43490.8 | AZ3: 43451.2 | BA3: 43359.7 | BB3: 43501.3 | BC3: 43125.4 | BD3: 43265.6 | BE3: 43361.2 | BF3: 43119.8 | BG3: 43319.4 | BH3: 43122.7 | BI3: 42980.2 | BJ3: 43186.6 | BK3: 43361.3 | BL3: 43652.9 | BM3: 43478.1 | BN3: 43399.9 | BO3: 43434 | BP3: 43320.6 | BQ3: 42678.2 | BR3: 42715.8 | BS3: 42639.1 | BT3: 42399.4 | BU3: 42588.1 | BV3: 41998.8 | BW3: 42005.4 | BX3: 41967.6 | BY3: 41650.8 | BZ3: 42102.7 | CA3: 42406.9 | CB3: 42762.5 | CC3: 42630.2 | CD3: 42584.9 | CE3: 42353.5 | CF3: 41714 | CG3: 41240.4 | CH3: 40799.9 | CI3: 40296.5 | CJ3: 39456.9 | CK3: 38655.6 | CL3: 38738.2 | CM3: 37869.3 | CN3: 37025.2 | CO3: 36444.6 | CP3: 35665.5 | CQ3: 35182.8 | CR3: 34363.4 | CS3: 33816.6
A4: 46237 | B4: 33530.8 | C4: 33207.1 | D4: 32827.8 | E4: 32433.4 | F4: 32377.5 | G4: 32110 | H4: 31762.9 | I4: 31616.8 | J4: 31521.2 | K4: 31404.9 | L4: 31155.1 | M4: 30766.5 | N4: 31096 | O4: 31003.7 | P4: 30738.2 | Q4: 30632.6 | R4: 30545.1 | S4: 30754.9 | T4: 30870.8 | U4: 31207.8 | V4: 31663.4 | W4: 31983.6 | X4: 32519.7 | Y4: 32834.8 | Z4: 33929.1 | AA4: 34671.5 | AB4: 35264.1 | AC4: 35922.5 | AD4: 36783 | AE4: 37804 | AF4: 38705.3 | AG4: 39625.6 | AH4: 41118.4 | AI4: 42070.2 | AJ4: 42844.3 | AK4: 43860.5 | AL4: 44595.8 | AM4: 45029.4 | AN4: 45785.7 | AO4: 46440.9 | AP4: 46749.6 | AQ4: 47177.7 | AR4: 47117.4 | AS4: 47417.9 | AT4: 47298.8 | AU4: 46937.8 | AV4: 46947.9 | AW4: 46959.5 | AX4: 46635.9 | AY4: 47162.4 | AZ4: 47003.8 | BA4: 47077.9 | BB4: 47088.5 | BC4: 46936.5 | BD4: 46857.4 | BE4: 46556.4 | BF4: 47097.7 | BG4: 47064.9 | BH4: 46243.6 | BI4: 45811.4 | BJ4: 46400.2 | BK4: 45999 | BL4: 45024.6 | BM4: 44622.9 | BN4: 45337.9 | BO4: 43978.6 | BP4: 44089.9 | BQ4: 43786.5 | BR4: 42649.2 | BS4: 42346 | BT4: 42327 | BU4: 42321.1 | BV4: 41615.2 | BW4: 41359.7 | BX4: 41507 | BY4: 41365.7 | BZ4: 41499.2 | CA4: 41624.6 | CB4: 41953.2 | CC4: 41736.5 | CD4: 42435.5 | CE4: 41997.6 | CF4: 41256.6 | CG4: 41548.6 | CH4: 42008.1 | CI4: 41000.5 | CJ4: 40485.8 | CK4: 39915.8 | CL4: 39621.4 | CM4: 39009.8 | CN4: 38087.7 | CO4: 37458.9 | CP4: 36845.6 | CQ4: 36232.1 | CR4: 35612.7 | CS4: 34905.6
A5: 46238 | B5: 34488.5 | C5: 34124.5 | D5: 33556.5 | E5: 33402.1 | F5: 33065.4 | G5: 32783.1 | H5: 32466.6 | I5: 32349.8 | J5: 32069.3 | K5: 31963.1 | L5: 31875.9 | M5: 31645.7 | N5: 31441.3 | O5: 31274 | P5: 31190.2 | Q5: 31099.6 | R5: 31224.3 | S5: 31206.8 | T5: 31307 | U5: 31662.7 | V5: 32044.6 | W5: 32503.6 | X5: 32767.9 | Y5: 33472.1 | Z5: 34151.2 | AA5: 34654.6 | AB5: 35338.5 | AC5: 35904.2 | AD5: 36774.9 | AE5: 37640.6 | AF5: 38347.4 | AG5: 39408.9 | AH5: 40594.4 | AI5: 41565.8 | AJ5: 42171.4 | AK5: 43260.5 | AL5: 44238.9 | AM5: 44800.4 | AN5: 45310.8 | AO5: 45605.9 | AP5: 46003.2 | AQ5: 46633.1 | AR5: 46581.4 | AS5: 46441.9 | AT5: 46442.4 | AU5: 46236.4 | AV5: 46417.4 | AW5: 46206.8 | AX5: 46278.8 | AY5: 46657 | AZ5: 46564.7 | BA5: 46520 | BB5: 46925.6 | BC5: 46553.8 | BD5: 46756.1 | BE5: 46610.7 | BF5: 46822.2 | BG5: 46604.4 | BH5: 46443.6 | BI5: 46401.8 | BJ5: 46288.8 | BK5: 46285.7 | BL5: 46668.7 | BM5: 46201.6 | BN5: 46766.3 | BO5: 46158.5 | BP5: 46017.9 | BQ5: 45152.7 | BR5: 44955.7 | BS5: 45037 | BT5: 44571.9 | BU5: 44788.1 | BV5: 44479.6 | BW5: 44323.9 | BX5: 44189.8 | BY5: 43997.7 | BZ5: 44309.4 | CA5: 44504.1 | CB5: 44561.4 | CC5: 44411.6 | CD5: 43972.1 | CE5: 43726.9 | CF5: 43149.4 | CG5: 42680.4 | CH5: 42160.1 | CI5: 41408.1 | CJ5: 40800.4 | CK5: 39920.6 | CL5: 39687.3 | CM5: 38641.9 | CN5: 37955.4 | CO5: 37220.6 | CP5: 36527.2 | CQ5: 36022.2 | CR5: 35295 | CS5: 34509.9
A6: 46239 | B6: 34544.1 | C6: 34102 | D6: 33554.9 | E6: 33515.8 | F6: 33099.4 | G6: 32746.6 | H6: 32541.2 | I6: 32278.1 | J6: 32340.2 | K6: 32113.5 | L6: 31819.1 | M6: 31568.9 | N6: 31333.3 | O6: 31186.6 | P6: 31170.4 | Q6: 31280.5 | R6: 31333.8 | S6: 31321.6 | T6: 31130.7 | U6: 31620.9 | V6: 31877.1 | W6: 32388.6 | X6: 32846.8 | Y6: 33261.9 | Z6: 33903.7 | AA6: 34607.2 | AB6: 35217.8 | AC6: 35856.7 | AD6: 36820.5 | AE6: 37625.5 | AF6: 38416.8 | AG6: 39518.2 | AH6: 40703.5 | AI6: 41686.7 | AJ6: 42619.8 | AK6: 43522.8 | AL6: 44017.3 | AM6: 44407.9 | AN6: 44925.6 | AO6: 45567.5 | AP6: 45858.2 | AQ6: 46489.9 | AR6: 46586.7 | AS6: 46699.9 | AT6: 46760.2 | AU6: 46459 | AV6: 46174.5 | AW6: 46176.4 | AX6: 46440.1 | AY6: 46254.4 | AZ6: 46754.5 | BA6: 46572.3 | BB6: 46752.5 | BC6: 46867.5 | BD6: 47023.1 | BE6: 46533.5 | BF6: 46538.7 | BG6: 46521.7 | BH6: 46887.3 | BI6: 46800.2 | BJ6: 46832.1 | BK6: 46982.6 | BL6: 47006 | BM6: 45774.1 | BN6: 46524.6 | BO6: 46321.1 | BP6: 46464 | BQ6: 45943.9 | BR6: 45573.9 | BS6: 45567.9 | BT6: 45578.8 | BU6: 45428.6 | BV6: 45043.2 | BW6: 45108.8 | BX6: 44796 | BY6: 44720.4 | BZ6: 45036.5 | CA6: 44989.2 | CB6: 45196.6 | CC6: 44990.5 | CD6: 44500.2 | CE6: 44567.5 | CF6: 44129.6 | CG6: 43290.9 | CH6: 42620.4 | CI6: 42007.5 | CJ6: 41298.6 | CK6: 40504.8 | CL6: 40048.6 | CM6: 39330.9 | CN6: 38536.2 | CO6: 37724.2 | CP6: 36965.9 | CQ6: 36387.1 | CR6: 35840.6 | CS6: 35205.2
A7: 46240 | B7: 34824.2 | C7: 34530.5 | D7: 34223.1 | E7: 33754.9 | F7: 33413.6 | G7: 33187.6 | H7: 32998.5 | I7: 32724.9 | J7: 32488.2 | K7: 32225.7 | L7: 31981.2 | M7: 31699.9 | N7: 31758.6 | O7: 31455.3 | P7: 31419.9 | Q7: 31199.3 | R7: 31421 | S7: 31434.2 | T7: 31577.7 | U7: 31904.4 | V7: 32273.9 | W7: 32459.5 | X7: 33007 | Y7: 33527.9 | Z7: 34350.5 | AA7: 34940.6 | AB7: 35509.8 | AC7: 36237.4 | AD7: 37010.8 | AE7: 37859.4 | AF7: 38717.8 | AG7: 39968.9 | AH7: 41175.5 | AI7: 42071.7 | AJ7: 43020.3 | AK7: 43813.2 | AL7: 44209.7 | AM7: 45328.9 | AN7: 45515.5 | AO7: 46098 | AP7: 46647.9 | AQ7: 46914.8 | AR7: 47010.4 | AS7: 47321.9 | AT7: 47258.2 | AU7: 47057.4 | AV7: 46870.4 | AW7: 46626.2 | AX7: 46885.3 | AY7: 46902.4 | AZ7: 46994.8 | BA7: 46982 | BB7: 47303.4 | BC7: 47414.7 | BD7: 47271.2 | BE7: 47507.9 | BF7: 47211.8 | BG7: 47310.2 | BH7: 47318 | BI7: 47405.1 | BJ7: 47585.5 | BK7: 47701.8 | BL7: 47439.1 | BM7: 47377.1 | BN7: 47559.7 | BO7: 47477.4 | BP7: 47177.7 | BQ7: 46643.5 | BR7: 46436 | BS7: 46428.4 | BT7: 46263.1 | BU7: 46399.8 | BV7: 46061.7 | BW7: 45968.9 | BX7: 45590.6 | BY7: 45361.3 | BZ7: 45708.2 | CA7: 45744.8 | CB7: 45767.3 | CC7: 45811.6 | CD7: 45204.4 | CE7: 44730.6 | CF7: 44242.6 | CG7: 43869.8 | CH7: 43131.7 | CI7: 42474.4 | CJ7: 41615.4 | CK7: 40791.8 | CL7: 40404.1 | CM7: 39736.5 | CN7: 38865.5 | CO7: 38073 | CP7: 37611.3 | CQ7: 36809 | CR7: 36200.7 | CS7: 35705.2
A8: 46241 | B8: 35146.6 | C8: 34574.5 | D8: 34244.1 | E8: 33762.4 | F8: 33607.7 | G8: 33000 | H8: 32850.8 | I8: 32536.1 | J8: 32371.4 | K8: 32055 | L8: 31876.9 | M8: 31840.6 | N8: 31689.2 | O8: 31478.4 | P8: 31480.9 | Q8: 31253.4 | R8: 31568.9 | S8: 31263.8 | T8: 31492.6 | U8: 31740.6 | V8: 32231.9 | W8: 32356.2 | X8: 32745.1 | Y8: 33379.7 | Z8: 33833.1 | AA8: 34392.1 | AB8: 35051.3 | AC8: 35576.8 | AD8: 35999.8 | AE8: 36425.2 | AF8: 37102.8 | AG8: 37847 | AH8: 38932.8 | AI8: 39424.9 | AJ8: 40109.3 | AK8: 40562.4 | AL8: 41040.5 | AM8: 41453.1 | AN8: 41401.4 | AO8: 41391.1 | AP8: 41380.3 | AQ8: 42195 | AR8: 42283.1 | AS8: 42101.3 | AT8: 42253.2 | AU8: 41943.3 | AV8: 41768.4 | AW8: 41644.8 | AX8: 41378 | AY8: 41575.9 | AZ8: 41510.3 | BA8: 41349.4 | BB8: 41961.8 | BC8: 41745 | BD8: 41176.3 | BE8: 41052.1 | BF8: 41186.5 | BG8: 40973.9 | BH8: 40745.9 | BI8: 40631.4 | BJ8: 40625 | BK8: 40805.3 | BL8: 40778.5 | BM8: 40817.5 | BN8: 40724.6 | BO8: 40613.2 | BP8: 40270.2 | BQ8: 39803.9 | BR8: 39172.3 | BS8: 39218.3 | BT8: 38775.6 | BU8: 38404.1 | BV8: 38203.6 | BW8: 37980.1 | BX8: 37800.6 | BY8: 37498.2 | BZ8: 37811.9 | CA8: 37922 | CB8: 38097.8 | CC8: 37689.7 | CD8: 37113.3 | CE8: 36956.7 | CF8: 36524.3 | CG8: 35875.6 | CH8: 35762.5 | CI8: 35034.9 | CJ8: 34592.4 | CK8: 33783.4 | CL8: 33995.5 | CM8: 33447.5 | CN8: 32778.8 | CO8: 32070.1 | CP8: 31487.8 | CQ8: 31146.1 | CR8: 30542.6 | CS8: 30137
A9: 46242 | B9: 30019.6 | C9: 29570 | D9: 29224.9 | E9: 28995.2 | F9: 28597 | G9: 28558.6 | H9: 28367.5 | I9: 28058.1 | J9: 27969.6 | K9: 27723.9 | L9: 27891.8 | M9: 27454.4 | N9: 27722.2 | O9: 27620.5 | P9: 27520.1 | Q9: 27280.8 | R9: 27382.8 | S9: 27605.2 | T9: 27760.1 | U9: 27922.8 | V9: 28530.5 | W9: 28809 | X9: 29041 | Y9: 29233.1 | Z9: 29647.6 | AA9: 30071.3 | AB9: 30360.8 | AC9: 30437.3 | AD9: 30768.7 | AE9: 31068.4 | AF9: 31305.4 | AG9: 31668.1 | AH9: 32686.1 | AI9: 32972.7 | AJ9: 33385.3 | AK9: 33396.1 | AL9: 33932.4 | AM9: 34299.4 | AN9: 34366.3 | AO9: 34372.9 | AP9: 34623.7 | AQ9: 34649.7 | AR9: 34904.8 | AS9: 34641 | AT9: 34405.7 | AU9: 33682.9 | AV9: 33513 | AW9: 33573 | AX9: 33312.7 | AY9: 33083.2 | AZ9: 33731.7 | BA9: 33883.8 | BB9: 34038.8 | BC9: 33914.5 | BD9: 34357.7 | BE9: 34166.2 | BF9: 34443.8 | BG9: 34301.8 | BH9: 34503.8 | BI9: 34391.4 | BJ9: 34713.9 | BK9: 34870.5 | BL9: 34881.5 | BM9: 34955.8 | BN9: 34876 | BO9: 35107.4 | BP9: 35304 | BQ9: 34707.8 | BR9: 34320.2 | BS9: 34602.7 | BT9: 34335 | BU9: 34394.7 | BV9: 34133.3 | BW9: 34032.9 | BX9: 34204.3 | BY9: 33993.5 | BZ9: 34245.3 | CA9: 34241 | CB9: 34338.2 | CC9: 33926.2 | CD9: 33921.3 | CE9: 33628.3 | CF9: 33352.5 | CG9: 32836.7 | CH9: 32817.4 | CI9: 32381.2 | CJ9: 31790.9 | CK9: 31183.1 | CL9: 31421.8 | CM9: 30842.2 | CN9: 30462.7 | CO9: 30134.3 | CP9: 29757.5 | CQ9: 29325.4 | CR9: 28899.1 | CS9: 28415.5
A10: 46243 | B10: 28293.5 | C10: 28112.1 | D10: 28068.1 | E10: 27465.8 | F10: 27456.9 | G10: 27168.6 | H10: 27047.5 | I10: 26858.1 | J10: 26711 | K10: 26646.8 | L10: 26568.4 | M10: 26401.5 | N10: 26447.6 | O10: 26398.5 | P10: 26390.5 | Q10: 26465.6 | R10: 26355 | S10: 26819.6 | T10: 27032.9 | U10: 27281.7 | V10: 27803.4 | W10: 27897.3 | X10: 28355.8 | Y10: 28534.4 | Z10: 28970 | AA10: 29327.3 | AB10: 29731.8 | AC10: 29905.4 | AD10: 30175.9 | AE10: 30314.2 | AF10: 30842.5 | AG10: 31133.7 | AH10: 31827.6 | AI10: 32237 | AJ10: 32664.1 | AK10: 33158.9 | AL10: 33345.3 | AM10: 33750.1 | AN10: 34024.4 | AO10: 34457.8 | AP10: 34747.8 | AQ10: 34866 | AR10: 35124.6 | AS10: 35038.7 | AT10: 35396.2 | AU10: 34447.6 | AV10: 34683.3 | AW10: 34445.3 | AX10: 34594.3 | AY10: 34660.7 | AZ10: 35088.1 | BA10: 35190.1 | BB10: 35456.8 | BC10: 35565.9 | BD10: 35799.8 | BE10: 35595 | BF10: 35878.2 | BG10: 35815.9 | BH10: 35616.3 | BI10: 35865.3 | BJ10: 36202.6 | BK10: 36079.5 | BL10: 36139.7 | BM10: 36209.5 | BN10: 36379.1 | BO10: 36359.1 | BP10: 36201.7 | BQ10: 36067.5 | BR10: 36025.8 | BS10: 35887 | BT10: 35782.7 | BU10: 35808.8 | BV10: 35402.2 | BW10: 35471.7 | BX10: 35344.1 | BY10: 35360.9 | BZ10: 35736.8 | CA10: 36035.1 | CB10: 36001 | CC10: 35956.5 | CD10: 35632.9 | CE10: 35468.9 | CF10: 35259.4 | CG10: 34833.5 | CH10: 34449.4 | CI10: 33942.5 | CJ10: 33484 | CK10: 32756.3 | CL10: 32804 | CM10: 32222.3 | CN10: 31703.3 | CO10: 31263.9 | CP10: 30764.2 | CQ10: 30331.5 | CR10: 29887.3 | CS10: 29366.7
A11: 46244 | B11: 29140.9 | C11: 28824.3 | D11: 28411.7 | E11: 28280 | F11: 28083.9 | G11: 27842.4 | H11: 27802.6 | I11: 27594.3 | J11: 27570.3 | K11: 27301.5 | L11: 27215.7 | M11: 27283.1 | N11: 27131.3 | O11: 26875.2 | P11: 27112.2 | Q11: 26997.1 | R11: 27144.2 | S11: 27151.2 | T11: 27525 | U11: 27925.7 | V11: 28429.1 | W11: 28946.9 | X11: 29210.8 | Y11: 29857 | Z11: 30505.2 | AA11: 30920.5 | AB11: 31460.1 | AC11: 31905.6 | AD11: 32384.4 | AE11: 32797.3 | AF11: 33855.6 | AG11: 34556.6 | AH11: 35724.9 | AI11: 36542.3 | AJ11: 37040.7 | AK11: 37602.4 | AL11: 38234.7 | AM11: 38864.5 | AN11: 38838.5 | AO11: 39531 | AP11: 39694.1 | AQ11: 39818.8 | AR11: 40081.4 | AS11: 39814.9 | AT11: 40072.3 | AU11: 39757.2 | AV11: 39345.2 | AW11: 39539.4 | AX11: 40218 | AY11: 40053.7 | AZ11: 40230.7 | BA11: 40269.9 | BB11: 40882 | BC11: 41020.5 | BD11: 41003.5 | BE11: 40731 | BF11: 41175 | BG11: 40882.6 | BH11: 41011.5 | BI11: 41082.1 | BJ11: 41426 | BK11: 41217.9 | BL11: 41510.7 | BM11: 41774.9 | BN11: 41543.3 | BO11: 41478 | BP11: 41170.2 | BQ11: 40624.2 | BR11: 40196 | BS11: 39968.5 | BT11: 39942.3 | BU11: 39786.1 | BV11: 39395.7 | BW11: 39328.1 | BX11: 39292.1 | BY11: 39097.8 | BZ11: 39562.8 | CA11: 39771.6 | CB11: 39788.6 | CC11: 39545 | CD11: 39336.2 | CE11: 39153.6 | CF11: 38497.2 | CG11: 38401.7 | CH11: 37648.1 | CI11: 36848.8 | CJ11: 36423.5 | CK11: 35781.6 | CL11: 35622.3 | CM11: 34835.6 | CN11: 34650.1 | CO11: 33682 | CP11: 33006 | CQ11: 32490.4 | CR11: 32125.5 | CS11: 31209.1
A12: 46245 | B12: 31083.8 | C12: 30969.7 | D12: 30358.1 | E12: 30119 | F12: 29761.1 | G12: 29513.7 | H12: 29400 | I12: 29365.5 | J12: 29248.1 | K12: 29165.6 | L12: 28940 | M12: 28741.4 | N12: 28817.6 | O12: 28651.3 | P12: 28607.6 | Q12: 28648.2 | R12: 28635.1 | S12: 28712.9 | T12: 28798.2 | U12: 29206.3 | V12: 29813.8 | W12: 30022.9 | X12: 30877.7 | Y12: 31151.8 | Z12: 31887.4 | AA12: 32219.9 | AB12: 32872.9 | AC12: 33509.5 | AD12: 33801.7 | AE12: 34306.7 | AF12: 35091.1 | AG12: 36085.3 | AH12: 37330.8 | AI12: 38036.9 | AJ12: 38646.4 | AK12: 39486.3 | AL12: 40184.1 | AM12: 40761.7 | AN12: 41029.3 | AO12: 41331.6 | AP12: 41564.6 | AQ12: 41981.8 | AR12: 42177.3 | AS12: 42631.4 | AT12: 42264.3 | AU12: 42222.9 | AV12: 41974.6 | AW12: 41952.8 | AX12: 42161.5 | AY12: 42503 | AZ12: 42309.2 | BA12: 43000.2 | BB12: 43557.9 | BC12: 43033.4 | BD12: 43479 | BE12: 43206.6 | BF12: 43037.9 | BG12: 43498.3 | BH12: 43173.1 | BI12: 43131.6 | BJ12: 43158.3 | BK12: 43356.2 | BL12: 43157.6 | BM12: 43191.3 | BN12: 43323.4 | BO12: 43150.6 | BP12: 43123.4 | BQ12: 42364.8 | BR12: 41959.3 | BS12: 41969.3 | BT12: 41974.5 | BU12: 41572.3 | BV12: 41394.3 | BW12: 41100.3 | BX12: 41125.8 | BY12: 40839.9 | BZ12: 40851.3 | CA12: 40972.9 | CB12: 41167.4 | CC12: 41063.9 | CD12: 40779.7 | CE12: 40484.2 | CF12: 39955.5 | CG12: 39429.7 | CH12: 38962.1 | CI12: 38392.5 | CJ12: 37667.1 | CK12: 36705.4 | CL12: 36577.4 | CM12: 35921.8 | CN12: 35090.3 | CO12: 34351.7 | CP12: 33742.9 | CQ12: 33187.5 | CR12: 32796.1 | CS12: 32131.8
A13: 46246 | B13: 32048.5 | C13: 31544.5 | D13: 31368.9 | E13: 31037.8 | F13: 30881.9 | G13: 30528.5 | H13: 30269.9 | I13: 29993 | J13: 29808.5 | K13: 29732.7 | L13: 29715.6 | M13: 29440.5 | N13: 29339.3 | O13: 29227.1 | P13: 29232.3 | Q13: 29072.4 | R13: 29339.7 | S13: 29176.8 | T13: 29451 | U13: 29581.1 | V13: 30129.9 | W13: 30458.2 | X13: 30754 | Y13: 31426 | Z13: 32173.5 | AA13: 32528.6 | AB13: 33357.4 | AC13: 33638.4 | AD13: 34184.5 | AE13: 34993.8 | AF13: 35687 | AG13: 36597.9 | AH13: 37671.4 | AI13: 38551.5 | AJ13: 39296.4 | AK13: 39962.1 | AL13: 40620.5 | AM13: 40767.3 | AN13: 41171 | AO13: 41301.9 | AP13: 41858.4 | AQ13: 42161.7 | AR13: 42452.7 | AS13: 42524.9 | AT13: 42182.1 | AU13: 42366.4 | AV13: 42204.9 | AW13: 42124 | AX13: 42026.3 | AY13: 42168.9 | AZ13: 42322.4 | BA13: 42141 | BB13: 42654.5 | BC13: 42810.5 | BD13: 42903.7 | BE13: 42753.3 | BF13: 42988.9 | BG13: 42539.9 | BH13: 42534.5 | BI13: 42522 | BJ13: 42607.1 | BK13: 42381 | BL13: 42191.2 | BM13: 42321.4 | BN13: 42224.1 | BO13: 42093.5 | BP13: 41668.8 | BQ13: 40867.6 | BR13: 40568.2 | BS13: 40351.5 | BT13: 40083.6 | BU13: 40015.6 | BV13: 39660.7 | BW13: 39513.5 | BX13: 39751.9 | BY13: 39653.2 | BZ13: 40053.8 | CA13: 39875.9 | CB13: 40121 | CC13: 39564.3 | CD13: 39191.5 | CE13: 38942.9 | CF13: 38620.7 | CG13: 37843.5 | CH13: 37436.1 | CI13: 36845.3 | CJ13: 36045.3 | CK13: 35651.6 | CL13: 35359.7 | CM13: 34580.1 | CN13: 33875.1 | CO13: 33100.4 | CP13: 32801.7 | CQ13: 32369.5 | CR13: 31822.4 | CS13: 31228
... A32: 46265 | B32: 27331.4 | C32: 27259.6 | D32: 26937.8 | E32: 26872.9 | F32: 26580.3 | G32: 26513.3 | H32: 26222 | I32: 26001.1 | J32: 26093.1 | K32: 26049.4 | L32: 25853.6 | M32: 25661.9 | N32: 25697.4 | O32: 25633 | P32: 25655.6 | Q32: 25469.2 | R32: 25772.3 | S32: 25819.7 | T32: 25954 | U32: 26174.2 | V32: 26785.3 | W32: 27256.4 | X32: 27789.9 | Y32: 28489.9 | Z32: 29170.8 | AA32: 29597.7 | AB32: 30226.2 | AC32: 30173 | AD32: 30790.6 | AE32: 31220.6 | AF32: 31432.2 | AG32: 31993.6 | AH32: 32665.5 | AI32: 33243.2 | AJ32: 33696.5 | AK32: 34091.5 | AL32: 34264.7 | AM32: 34769.3 | AN32: 34972.8 | AO32: 35174.8 | AP32: 35451.9 | AQ32: 35406.4 | AR32: 35900.6 | AS32: 35748.2 | AT32: 35463.3 | AU32: 35271.9 | AV32: 34670 | AW32: 34533.7 | AX32: 34624.3 | AY32: 35074.7 | AZ32: 35455.3 | BA32: 35160.3 | BB32: 35895.1 | BC32: 35838 | BD32: 36041 | BE32: 35490.5 | BF32: 35837.1 | BG32: 35673.6 | BH32: 35095 | BI32: 35270.5 | BJ32: 35593.9 | BK32: 35230.3 | BL32: 35298.9 | BM32: 35314.6 | BN32: 35726.7 | BO32: 35626.5 | BP32: 35371.8 | BQ32: 34897.3 | BR32: 34558.2 | BS32: 34388.1 | BT32: 34129.1 | BU32: 34273.6 | BV32: 34114.7 | BW32: 34377.3 | BX32: 34717.2 | BY32: 34779.8 | BZ32: 34816 | CA32: 34561.2 | CB32: 34641.9 | CC32: 34351.7 | CD32: 34039.6 | CE32: 33708.6 | CF32: 33448.7 | CG32: 32883.9 | CH32: 32459.7 | CI32: 31728 | CJ32: 31370.3 | CK32: 30557.8 | CL32: 30811.9 | CM32: 30340.9 | CN32: 29968.4 | CO32: 29371.1 | CP32: 28741.7 | CQ32: 28334.2 | CR32: 27894.3 | CS32: 27548.7

Sheet 水电
A1: 日期 | B1: 0.010416667 | C1: 0.020833333 | D1: 0.03125 | E1: 0.041666667 | F1: 0.052083333 | G1: 0.0625 | H1: 0.072916667 | I1: 0.083333333 | J1: 0.09375 | K1: 0.10416667 | L1: 0.11458333 | M1: 0.125 | N1: 0.13541667 | O1: 0.14583333 | P1: 0.15625 | Q1: 0.16666667 | R1: 0.17708333 | S1: 0.1875 | T1: 0.19791667 | U1: 0.20833333 | V1: 0.21875 | W1: 0.22916667 | X1: 0.23958333 | Y1: 0.25 | Z1: 0.26041667 | AA1: 0.27083333 | AB1: 0.28125 | AC1: 0.29166667 | AD1: 0.30208333 | AE1: 0.3125 | AF1: 0.32291667 | AG1: 0.33333333 | AH1: 0.34375 | AI1: 0.35416667 | AJ1: 0.36458333 | AK1: 0.375 | AL1: 0.38541667 | AM1: 0.39583333 | AN1: 0.40625 | AO1: 0.41666667 | AP1: 0.42708333 | AQ1: 0.4375 | AR1: 0.44791667 | AS1: 0.45833333 | AT1: 0.46875 | AU1: 0.47916667 | AV1: 0.48958333 | AW1: 0.5 | AX1: 0.51041667 | AY1: 0.52083333 | AZ1: 0.53125 | BA1: 0.54166667 | BB1: 0.55208333 | BC1: 0.5625 | BD1: 0.57291667 | BE1: 0.58333333 | BF1: 0.59375 | BG1: 0.60416667 | BH1: 0.61458333 | BI1: 0.625 | BJ1: 0.63541667 | BK1: 0.64583333 | BL1: 0.65625 | BM1: 0.66666667 | BN1: 0.67708333 | BO1: 0.6875 | BP1: 0.69791667 | BQ1: 0.70833333 | BR1: 0.71875 | BS1: 0.72916667 | BT1: 0.73958333 | BU1: 0.75 | BV1: 0.76041667 | BW1: 0.77083333 | BX1: 0.78125 | BY1: 0.79166667 | BZ1: 0.80208333 | CA1: 0.8125 | CB1: 0.82291667 | CC1: 0.83333333 | CD1: 0.84375 | CE1: 0.85416667 | CF1: 0.86458333 | CG1: 0.875 | CH1: 0.88541667 | CI1: 0.89583333 | CJ1: 0.90625 | CK1: 0.91666667 | CL1: 0.92708333 | CM1: 0.9375 | CN1: 0.94791667 | CO1: 0.95833333 | CP1: 0.96875 | CQ1: 0.97916667 | CR1: 0.98958333 | CS1: 1
A2: 46235 | B2: 566 | C2: 564 | D2: 560 | E2: 561 | F2: 561 | G2: 561 | H2: 559 | I2: 559 | J2: 558 | K2: 559 | L2: 557 | M2: 558 | N2: 559 | O2: 558 | P2: 558 | Q2: 559 | R2: 619 | S2: 616 | T2: 618 | U2: 618 | V2: 618 | W2: 618 | X2: 618 | Y2: 618 | Z2: 618 | AA2: 618 | AB2: 617 | AC2: 618 | AD2: 617 | AE2: 618 | AF2: 616 | AG2: 617 | AH2: 616 | AI2: 616 | AJ2: 615 | AK2: 617 | AL2: 616 | AM2: 616 | AN2: 617 | AO2: 616 | AP2: 616 | AQ2: 617 | AR2: 616 | AS2: 617 | AT2: 616 | AU2: 616 | AV2: 616 | AW2: 617 | AX2: 615 | AY2: 512 | AZ2: 512 | BA2: 512 | BB2: 453 | BC2: 453 | BD2: 453 | BE2: 453 | BF2: 453 | BG2: 453 | BH2: 453 | BI2: 453 | BJ2: 453 | BK2: 453 | BL2: 452 | BM2: 452 | BN2: 452 | BO2: 451 | BP2: 451 | BQ2: 446 | BR2: 431 | BS2: 430 | BT2: 430 | BU2: 430 | BV2: 431 | BW2: 431 | BX2: 430 | BY2: 430 | BZ2: 431 | CA2: 429 | CB2: 490 | CC2: 491 | CD2: 492 | CE2: 491 | CF2: 492 | CG2: 492 | CH2: 431 | CI2: 431 | CJ2: 432 | CK2: 431 | CL2: 431 | CM2: 431 | CN2: 431 | CO2: 432 | CP2: 432 | CQ2: 431 | CR2: 431 | CS2: 310
A3: 46236 | B3: 708 | C3: 708 | D3: 709 | E3: 710 | F3: 599 | G3: 596 | H3: 596 | I3: 597 | J3: 597 | K3: 598 | L3: 596 | M3: 597 | N3: 597 | O3: 598 | P3: 597 | Q3: 597 | R3: 598 | S3: 597 | T3: 459 | U3: 459 | V3: 458 | W3: 446 | X3: 447 | Y3: 446 | Z3: 446 | AA3: 442 | AB3: 441 | AC3: 439 | AD3: 438 | AE3: 440 | AF3: 439 | AG3: 441 | AH3: 381 | AI3: 379 | AJ3: 382 | AK3: 385 | AL3: 385 | AM3: 385 | AN3: 386 | AO3: 386 | AP3: 387 | AQ3: 386 | AR3: 386 | AS3: 517 | AT3: 538 | AU3: 539 | AV3: 538 | AW3: 539 | AX3: 599 | AY3: 600 | AZ3: 601 | BA3: 602 | BB3: 601 | BC3: 605 | BD3: 604 | BE3: 604 | BF3: 604 | BG3: 603 | BH3: 604 | BI3: 604 | BJ3: 604 | BK3: 604 | BL3: 604 | BM3: 604 | BN3: 537 | BO3: 499 | BP3: 499 | BQ3: 498 | BR3: 496 | BS3: 492 | BT3: 495 | BU3: 495 | BV3: 436 | BW3: 436 | BX3: 439 | BY3: 443 | BZ3: 443 | CA3: 442 | CB3: 443 | CC3: 443 | CD3: 442 | CE3: 443 | CF3: 443 | CG3: 442 | CH3: 442 | CI3: 443 | CJ3: 442 | CK3: 443 | CL3: 441 | CM3: 441 | CN3: 442 | CO3: 441 | CP3: 442 | CQ3: 441 | CR3: 440 | CS3: 440
A4: 46237 | B4: 498 | C4: 497 | D4: 497 | E4: 497 | F4: 499 | G4: 539 | H4: 538 | I4: 537 | J4: 536 | K4: 538 | L4: 537 | M4: 536 | N4: 536 | O4: 535 | P4: 536 | Q4: 536 | R4: 535 | S4: 535 | T4: 534 | U4: 530 | V4: 531 | W4: 530 | X4: 530 | Y4: 530 | Z4: 596 | AA4: 596 | AB4: 597 | AC4: 600 | AD4: 600 | AE4: 602 | AF4: 603 | AG4: 602 | AH4: 602 | AI4: 608 | AJ4: 608 | AK4: 608 | AL4: 608 | AM4: 608 | AN4: 607 | AO4: 605 | AP4: 546 | AQ4: 547 | AR4: 525 | AS4: 525 | AT4: 525 | AU4: 526 | AV4: 526 | AW4: 526 | AX4: 525 | AY4: 525 | AZ4: 525 | BA4: 525 | BB4: 524 | BC4: 524 | BD4: 525 | BE4: 525 | BF4: 481 | BG4: 481 | BH4: 476 | BI4: 539 | BJ4: 539 | BK4: 537 | BL4: 538 | BM4: 537 | BN4: 536 | BO4: 537 | BP4: 536 | BQ4: 532 | BR4: 493 | BS4: 493 | BT4: 493 | BU4: 492 | BV4: 432 | BW4: 432 | BX4: 433 | BY4: 433 | BZ4: 434 | CA4: 434 | CB4: 434 | CC4: 434 | CD4: 432 | CE4: 432 | CF4: 432 | CG4: 432 | CH4: 432 | CI4: 431 | CJ4: 431 | CK4: 431 | CL4: 432 | CM4: 432 | CN4: 431 | CO4: 431 | CP4: 431 | CQ4: 431 | CR4: 430 | CS4: 430
A5: 46238 | B5: 539 | C5: 540 | D5: 541 | E5: 543 | F5: 543 | G5: 543 | H5: 543 | I5: 543 | J5: 542 | K5: 543 | L5: 543 | M5: 543 | N5: 543 | O5: 543 | P5: 544 | Q5: 543 | R5: 544 | S5: 543 | T5: 543 | U5: 543 | V5: 563 | W5: 564 | X5: 564 | Y5: 564 | Z5: 565 | AA5: 565 | AB5: 606 | AC5: 605 | AD5: 605 | AE5: 605 | AF5: 607 | AG5: 607 | AH5: 607 | AI5: 607 | AJ5: 606 | AK5: 606 | AL5: 606 | AM5: 605 | AN5: 606 | AO5: 605 | AP5: 605 | AQ5: 605 | AR5: 606 | AS5: 604 | AT5: 605 | AU5: 586 | AV5: 538 | AW5: 540 | AX5: 539 | AY5: 539 | AZ5: 538 | BA5: 539 | BB5: 538 | BC5: 538 | BD5: 539 | BE5: 539 | BF5: 539 | BG5: 535 | BH5: 535 | BI5: 536 | BJ5: 493 | BK5: 495 | BL5: 433 | BM5: 432 | BN5: 433 | BO5: 432 | BP5: 432 | BQ5: 433 | BR5: 432 | BS5: 432 | BT5: 427 | BU5: 427 | BV5: 427 | BW5: 426 | BX5: 426 | BY5: 427 | BZ5: 426 | CA5: 426 | CB5: 427 | CC5: 426 | CD5: 427 | CE5: 426 | CF5: 426 | CG5: 426 | CH5: 426 | CI5: 426 | CJ5: 426 | CK5: 425 | CL5: 426 | CM5: 426 | CN5: 426 | CO5: 425 | CP5: 426 | CQ5: 427 | CR5: 427 | CS5: 427
A6: 46239 | B6: 585 | C6: 590 | D6: 590 | E6: 592 | F6: 592 | G6: 592 | H6: 592 | I6: 591 | J6: 592 | K6: 592 | L6: 593 | M6: 592 | N6: 593 | O6: 592 | P6: 593 | Q6: 592 | R6: 592 | S6: 593 | T6: 597 | U6: 598 | V6: 599 | W6: 598 | X6: 599 | Y6: 599 | Z6: 598 | AA6: 599 | AB6: 600 | AC6: 600 | AD6: 600 | AE6: 600 | AF6: 600 | AG6: 601 | AH6: 599 | AI6: 598 | AJ6: 599 | AK6: 600 | AL6: 602 | AM6: 601 | AN6: 602 | AO6: 602 | AP6: 601 | AQ6: 602 | AR6: 601 | AS6: 601 | AT6: 601 | AU6: 600 | AV6: 600 | AW6: 600 | AX6: 603 | AY6: 603 | AZ6: 603 | BA6: 603 | BB6: 603 | BC6: 603 | BD6: 584 | BE6: 583 | BF6: 583 | BG6: 473 | BH6: 431 | BI6: 369 | BJ6: 358 | BK6: 349 | BL6: 349 | BM6: 348 | BN6: 345 | BO6: 345 | BP6: 345 | BQ6: 344 | BR6: 344 | BS6: 339 | BT6: 343 | BU6: 346 | BV6: 346 | BW6: 347 | BX6: 346 | BY6: 346 | BZ6: 344 | CA6: 343 | CB6: 343 | CC6: 343 | CD6: 343 | CE6: 342 | CF6: 414 | CG6: 475 | CH6: 480 | CI6: 482 | CJ6: 481 | CK6: 481 | CL6: 479 | CM6: 479 | CN6: 479 | CO6: 478 | CP6: 475 | CQ6: 475 | CR6: 474 | CS6: 474
A7: 46240 | B7: 517 | C7: 517 | D7: 517 | E7: 513 | F7: 513 | G7: 513 | H7: 514 | I7: 513 | J7: 513 | K7: 513 | L7: 513 | M7: 513 | N7: 513 | O7: 512 | P7: 512 | Q7: 498 | R7: 497 | S7: 498 | T7: 498 | U7: 498 | V7: 497 | W7: 498 | X7: 497 | Y7: 497 | Z7: 498 | AA7: 498 | AB7: 496 | AC7: 497 | AD7: 497 | AE7: 496 | AF7: 497 | AG7: 394 | AH7: 394 | AI7: 393 | AJ7: 394 | AK7: 394 | AL7: 393 | AM7: 393 | AN7: 393 | AO7: 393 | AP7: 393 | AQ7: 393 | AR7: 393 | AS7: 393 | AT7: 393 | AU7: 393 | AV7: 392 | AW7: 392 | AX7: 518 | AY7: 516 | AZ7: 518 | BA7: 519 | BB7: 519 | BC7: 518 | BD7: 519 | BE7: 517 | BF7: 517 | BG7: 517 | BH7: 517 | BI7: 518 | BJ7: 489 | BK7: 478 | BL7: 510 | BM7: 547 | BN7: 550 | BO7: 550 | BP7: 554 | BQ7: 558 | BR7: 559 | BS7: 560 | BT7: 560 | BU7: 663 | BV7: 663 | BW7: 664 | BX7: 664 | BY7: 664 | BZ7: 565 | CA7: 564 | CB7: 562 | CC7: 562 | CD7: 561 | CE7: 561 | CF7: 696 | CG7: 502 | CH7: 498 | CI7: 702 | CJ7: 563 | CK7: 563 | CL7: 563 | CM7: 499 | CN7: 499 | CO7: 498 | CP7: 498 | CQ7: 499 | CR7: 499 | CS7: 499
A8: 46241 | B8: 466 | C8: 466 | D8: 466 | E8: 466 | F8: 466 | G8: 467 | H8: 466 | I8: 466 | J8: 466 | K8: 466 | L8: 529 | M8: 528 | N8: 528 | O8: 528 | P8: 528 | Q8: 528 | R8: 528 | S8: 528 | T8: 528 | U8: 528 | V8: 528 | W8: 527 | X8: 528 | Y8: 527 | Z8: 525 | AA8: 524 | AB8: 524 | AC8: 191 | AD8: 130 | AE8: 125 | AF8: 126 | AG8: 125 | AH8: 125 | AI8: 125 | AJ8: 125 | AK8: 124 | AL8: 125 | AM8: 124 | AN8: 124 | AO8: 121 | AP8: 120 | AQ8: 120 | AR8: 120 | AS8: 120 | AT8: 117 | AU8: 117 | AV8: 117 | AW8: 116 | AX8: 113 | AY8: 113 | AZ8: 113 | BA8: 113 | BB8: 113 | BC8: 113 | BD8: 113 | BE8: 111 | BF8: 113 | BG8: 115 | BH8: 113 | BI8: 116 | BJ8: 116 | BK8: 116 | BL8: 116 | BM8: 116 | BN8: 116 | BO8: 116 | BP8: 116 | BQ8: 114 | BR8: 114 | BS8: 114 | BT8: 114 | BU8: 114 | BV8: 114 | BW8: 601 | BX8: 612 | BY8: 619 | BZ8: 544 | CA8: 541 | CB8: 354 | CC8: 249 | CD8: 170 | CE8: 129 | CF8: 129 | CG8: 129 | CH8: 128 | CI8: 129 | CJ8: 124 | CK8: 124 | CL8: 124 | CM8: 123 | CN8: 123 | CO8: 123 | CP8: 123 | CQ8: 123 | CR8: 122 | CS8: 119
A9: 46242 | B9: 118 | C9: 118 | D9: 118 | E9: 118 | F9: 117 | G9: 118 | H9: 118 | I9: 118 | J9: 118 | K9: 118 | L9: 118 | M9: 118 | N9: 117 | O9: 118 | P9: 118 | Q9: 117 | R9: 117 | S9: 117 | T9: 116 | U9: 116 | V9: 116 | W9: 117 | X9: 115 | Y9: 114 | Z9: 117 | AA9: 117 | AB9: 117 | AC9: 117 | AD9: 117 | AE9: 116 | AF9: 116 | AG9: 116 | AH9: 115 | AI9: 116 | AJ9: 116 | AK9: 115 | AL9: 115 | AM9: 116 | AN9: 115 | AO9: 113 | AP9: 113 | AQ9: 113 | AR9: 113 | AS9: 113 | AT9: 113 | AU9: 113 | AV9: 112 | AW9: 112 | AX9: 113 | AY9: 112 | AZ9: 112 | BA9: 113 | BB9: 112 | BC9: 113 | BD9: 112 | BE9: 112 | BF9: 111 | BG9: 110 | BH9: 109 | BI9: 108 | BJ9: 108 | BK9: 108 | BL9: 108 | BM9: 108 | BN9: 109 | BO9: 109 | BP9: 108 | BQ9: 108 | BR9: 108 | BS9: 108 | BT9: 109 | BU9: 108 | BV9: 108 | BW9: 505 | BX9: 570 | BY9: 578 | BZ9: 581 | CA9: 580 | CB9: 580 | CC9: 588 | CD9: 593 | CE9: 598 | CF9: 598 | CG9: 598 | CH9: 499 | CI9: 499 | CJ9: 500 | CK9: 499 | CL9: 499 | CM9: 499 | CN9: 499 | CO9: 498 | CP9: 498 | CQ9: 499 | CR9: 498 | CS9: 497
A10: 46243 | B10: 384 | C10: 384 | D10: 384 | E10: 384 | F10: 384 | G10: 383 | H10: 383 | I10: 382 | J10: 378 | K10: 378 | L10: 379 | M10: 379 | N10: 378 | O10: 378 | P10: 378 | Q10: 401 | R10: 401 | S10: 401 | T10: 402 | U10: 397 | V10: 437 | W10: 437 | X10: 414 | Y10: 413 | Z10: 414 | AA10: 414 | AB10: 414 | AC10: 413 | AD10: 413 | AE10: 413 | AF10: 413 | AG10: 416 | AH10: 477 | AI10: 472 | AJ10: 473 | AK10: 473 | AL10: 513 | AM10: 130 | AN10: 123 | AO10: 123 | AP10: 122 | AQ10: 122 | AR10: 122 | AS10: 121 | AT10: 121 | AU10: 119 | AV10: 119 | AW10: 116 | AX10: 112 | AY10: 112 | AZ10: 113 | BA10: 112 | BB10: 112 | BC10: 113 | BD10: 114 | BE10: 198 | BF10: 409 | BG10: 580 | BH10: 579 | BI10: 580 | BJ10: 582 | BK10: 584 | BL10: 585 | BM10: 585 | BN10: 585 | BO10: 586 | BP10: 588 | BQ10: 588 | BR10: 588 | BS10: 588 | BT10: 592 | BU10: 593 | BV10: 532 | BW10: 533 | BX10: 532 | BY10: 531 | BZ10: 532 | CA10: 532 | CB10: 531 | CC10: 532 | CD10: 531 | CE10: 554 | CF10: 592 | CG10: 555 | CH10: 555 | CI10: 556 | CJ10: 555 | CK10: 555 | CL10: 556 | CM10: 557 | CN10: 496 | CO10: 494 | CP10: 494 | CQ10: 493 | CR10: 493 | CS10: 493
A11: 46244 | B11: 485 | C11: 483 | D11: 481 | E11: 479 | F11: 480 | G11: 481 | H11: 480 | I11: 480 | J11: 419 | K11: 419 | L11: 419 | M11: 417 | N11: 417 | O11: 417 | P11: 417 | Q11: 417 | R11: 416 | S11: 416 | T11: 416 | U11: 416 | V11: 416 | W11: 416 | X11: 415 | Y11: 415 | Z11: 415 | AA11: 415 | AB11: 415 | AC11: 413 | AD11: 413 | AE11: 413 | AF11: 412 | AG11: 411 | AH11: 410 | AI11: 410 | AJ11: 410 | AK11: 467 | AL11: 510 | AM11: 508 | AN11: 508 | AO11: 509 | AP11: 289 | AQ11: 241 | AR11: 241 | AS11: 240 | AT11: 123 | AU11: 116 | AV11: 116 | AW11: 116 | AX11: 114 | AY11: 113 | AZ11: 113 | BA11: 113 | BB11: 113 | BC11: 113 | BD11: 113 | BE11: 111 | BF11: 110 | BG11: 107 | BH11: 107 | BI11: 107 | BJ11: 107 | BK11: 107 | BL11: 262 | BM11: 569 | BN11: 573 | BO11: 574 | BP11: 679 | BQ11: 677 | BR11: 577 | BS11: 578 | BT11: 580 | BU11: 579 | BV11: 578 | BW11: 581 | BX11: 579 | BY11: 580 | BZ11: 537 | CA11: 536 | CB11: 536 | CC11: 537 | CD11: 539 | CE11: 549 | CF11: 548 | CG11: 548 | CH11: 510 | CI11: 510 | CJ11: 510 | CK11: 512 | CL11: 510 | CM11: 510 | CN11: 511 | CO11: 510 | CP11: 490 | CQ11: 490 | CR11: 490 | CS11: 489
A12: 46245 | B12: 480 | C12: 481 | D12: 481 | E12: 479 | F12: 442 | G12: 441 | H12: 441 | I12: 442 | J12: 442 | K12: 442 | L12: 442 | M12: 442 | N12: 420 | O12: 420 | P12: 421 | Q12: 419 | R12: 416 | S12: 417 | T12: 416 | U12: 417 | V12: 417 | W12: 415 | X12: 414 | Y12: 410 | Z12: 410 | AA12: 411 | AB12: 411 | AC12: 410 | AD12: 410 | AE12: 410 | AF12: 410 | AG12: 410 | AH12: 412 | AI12: 410 | AJ12: 411 | AK12: 411 | AL12: 513 | AM12: 512 | AN12: 511 | AO12: 512 | AP12: 512 | AQ12: 512 | AR12: 512 | AS12: 510 | AT12: 512 | AU12: 581 | AV12: 582 | AW12: 586 | AX12: 584 | AY12: 585 | AZ12: 585 | BA12: 590 | BB12: 592 | BC12: 591 | BD12: 590 | BE12: 588 | BF12: 592 | BG12: 592 | BH12: 593 | BI12: 593 | BJ12: 591 | BK12: 591 | BL12: 591 | BM12: 591 | BN12: 591 | BO12: 590 | BP12: 589 | BQ12: 589 | BR12: 588 | BS12: 588 | BT12: 588 | BU12: 587 | BV12: 525 | BW12: 526 | BX12: 526 | BY12: 525 | BZ12: 525 | CA12: 525 | CB12: 525 | CC12: 526 | CD12: 524 | CE12: 524 | CF12: 525 | CG12: 524 | CH12: 488 | CI12: 488 | CJ12: 489 | CK12: 489 | CL12: 490 | CM12: 490 | CN12: 489 | CO12: 489 | CP12: 489 | CQ12: 489 | CR12: 489 | CS12: 489
A13: 46246 | B13: 480 | C13: 481 | D13: 481 | E13: 479 | F13: 442 | G13: 441 | H13: 441 | I13: 442 | J13: 442 | K13: 442 | L13: 442 | M13: 442 | N13: 420 | O13: 420 | P13: 421 | Q13: 419 | R13: 416 | S13: 417 | T13: 416 | U13: 417 | V13: 417 | W13: 415 | X13: 414 | Y13: 410 | Z13: 410 | AA13: 411 | AB13: 411 | AC13: 410 | AD13: 410 | AE13: 410 | AF13: 410 | AG13: 410 | AH13: 412 | AI13: 410 | AJ13: 411 | AK13: 411 | AL13: 513 | AM13: 512 | AN13: 511 | AO13: 512 | AP13: 512 | AQ13: 512 | AR13: 512 | AS13: 510 | AT13: 512 | AU13: 581 | AV13: 582 | AW13: 586 | AX13: 584 | AY13: 585 | AZ13: 585 | BA13: 590 | BB13: 592 | BC13: 591 | BD13: 590 | BE13: 588 | BF13: 592 | BG13: 592 | BH13: 593 | BI13: 593 | BJ13: 591 | BK13: 591 | BL13: 591 | BM13: 591 | BN13: 591 | BO13: 590 | BP13: 589 | BQ13: 589 | BR13: 588 | BS13: 588 | BT13: 588 | BU13: 587 | BV13: 525 | BW13: 526 | BX13: 526 | BY13: 525 | BZ13: 525 | CA13: 525 | CB13: 525 | CC13: 526 | CD13: 524 | CE13: 524 | CF13: 525 | CG13: 524 | CH13: 488 | CI13: 488 | CJ13: 489 | CK13: 489 | CL13: 490 | CM13: 490 | CN13: 489 | CO13: 489 | CP13: 489 | CQ13: 489 | CR13: 489 | CS13: 489
... A32: 46265 | B32: 207 | C32: 206 | D32: 196 | E32: 196 | F32: 196 | G32: 196 | H32: 197 | I32: 197 | J32: 239 | K32: 238 | L32: 238 | M32: 238 | N32: 237 | O32: 235 | P32: 235 | Q32: 235 | R32: 236 | S32: 235 | T32: 235 | U32: 236 | V32: 172 | W32: 173 | X32: 172 | Y32: 173 | Z32: 173 | AA32: 172 | AB32: 172 | AC32: 172 | AD32: 171 | AE32: 171 | AF32: 171 | AG32: 171 | AH32: 171 | AI32: 99 | AJ32: 99 | AK32: 99 | AL32: 97 | AM32: 97 | AN32: 97 | AO32: 97 | AP32: 97 | AQ32: 97 | AR32: 97 | AS32: 97 | AT32: 97 | AU32: 97 | AV32: 97 | AW32: 97 | AX32: 96 | AY32: 96 | AZ32: 96 | BA32: 95 | BB32: 95 | BC32: 96 | BD32: 93 | BE32: 92 | BF32: 93 | BG32: 92 | BH32: 92 | BI32: 92 | BJ32: 92 | BK32: 92 | BL32: 92 | BM32: 92 | BN32: 227 | BO32: 228 | BP32: 228 | BQ32: 246 | BR32: 269 | BS32: 269 | BT32: 269 | BU32: 269 | BV32: 269 | BW32: 268 | BX32: 269 | BY32: 268 | BZ32: 268 | CA32: 269 | CB32: 269 | CC32: 268 | CD32: 269 | CE32: 231 | CF32: 231 | CG32: 230 | CH32: 230 | CI32: 230 | CJ32: 230 | CK32: 230 | CL32: 230 | CM32: 230 | CN32: 230 | CO32: 230 | CP32: 250 | CQ32: 250 | CR32: 249 | CS32: 249

Sheet 核电
A1: 日期 | B1: 0.010416667 | C1: 0.020833333 | D1: 0.03125 | E1: 0.041666667 | F1: 0.052083333 | G1: 0.0625 | H1: 0.072916667 | I1: 0.083333333 | J1: 0.09375 | K1: 0.10416667 | L1: 0.11458333 | M1: 0.125 | N1: 0.13541667 | O1: 0.14583333 | P1: 0.15625 | Q1: 0.16666667 | R1: 0.17708333 | S1: 0.1875 | T1: 0.19791667 | U1: 0.20833333 | V1: 0.21875 | W1: 0.22916667 | X1: 0.23958333 | Y1: 0.25 | Z1: 0.26041667 | AA1: 0.27083333 | AB1: 0.28125 | AC1: 0.29166667 | AD1: 0.30208333 | AE1: 0.3125 | AF1: 0.32291667 | AG1: 0.33333333 | AH1: 0.34375 | AI1: 0.35416667 | AJ1: 0.36458333 | AK1: 0.375 | AL1: 0.38541667 | AM1: 0.39583333 | AN1: 0.40625 | AO1: 0.41666667 | AP1: 0.42708333 | AQ1: 0.4375 | AR1: 0.44791667 | AS1: 0.45833333 | AT1: 0.46875 | AU1: 0.47916667 | AV1: 0.48958333 | AW1: 0.5 | AX1: 0.51041667 | AY1: 0.52083333 | AZ1: 0.53125 | BA1: 0.54166667 | BB1: 0.55208333 | BC1: 0.5625 | BD1: 0.57291667 | BE1: 0.58333333 | BF1: 0.59375 | BG1: 0.60416667 | BH1: 0.61458333 | BI1: 0.625 | BJ1: 0.63541667 | BK1: 0.64583333 | BL1: 0.65625 | BM1: 0.66666667 | BN1: 0.67708333 | BO1: 0.6875 | BP1: 0.69791667 | BQ1: 0.70833333 | BR1: 0.71875 | BS1: 0.72916667 | BT1: 0.73958333 | BU1: 0.75 | BV1: 0.76041667 | BW1: 0.77083333 | BX1: 0.78125 | BY1: 0.79166667 | BZ1: 0.80208333 | CA1: 0.8125 | CB1: 0.82291667 | CC1: 0.83333333 | CD1: 0.84375 | CE1: 0.85416667 | CF1: 0.86458333 | CG1: 0.875 | CH1: 0.88541667 | CI1: 0.89583333 | CJ1: 0.90625 | CK1: 0.91666667 | CL1: 0.92708333 | CM1: 0.9375 | CN1: 0.94791667 | CO1: 0.95833333 | CP1: 0.96875 | CQ1: 0.97916667 | CR1: 0.98958333 | CS1: 1
A2: 46235 | B2: 6301.15 | C2: 6299.14 | D2: 6306.36 | E2: 6307.19 | F2: 6313.61 | G2: 6310.4 | H2: 6309.58 | I2: 6305.57 | J2: 6307.57 | K2: 6306.77 | L2: 6305.56 | M2: 6309.58 | N2: 6304.35 | O2: 6308.78 | P2: 6307.98 | Q2: 6305.98 | R2: 6308.38 | S2: 6309.99 | T2: 6311.6 | U2: 6302.35 | V2: 6316.02 | W2: 6298.73 | X2: 6310 | Y2: 6306.37 | Z2: 6299.14 | AA2: 6301.54 | AB2: 6313.21 | AC2: 6314 | AD2: 6301.95 | AE2: 6298.33 | AF2: 6305.17 | AG2: 6311.6 | AH2: 6303.57 | AI2: 6306.37 | AJ2: 6306.38 | AK2: 6302.34 | AL2: 6305.97 | AM2: 6301.94 | AN2: 6305.97 | AO2: 6305.97 | AP2: 6304.77 | AQ2: 6303.97 | AR2: 6303.56 | AS2: 6302.76 | AT2: 6308.79 | AU2: 6307.18 | AV2: 6303.15 | AW2: 6301.55 | AX2: 6304.36 | AY2: 6309.59 | AZ2: 6304.37 | BA2: 6308.38 | BB2: 6299.96 | BC2: 6296.33 | BD2: 6299.94 | BE2: 6297.92 | BF2: 6299.55 | BG2: 6292.72 | BH2: 6288.68 | BI2: 6288.69 | BJ2: 6288.28 | BK2: 6287.49 | BL2: 6289.09 | BM2: 6279.45 | BN2: 6278.65 | BO2: 6284.67 | BP2: 6288.28 | BQ2: 6288.69 | BR2: 6272.21 | BS2: 6276.23 | BT2: 6285.48 | BU2: 6285.87 | BV2: 6279.45 | BW2: 6282.26 | BX2: 6276.24 | BY2: 6288.3 | BZ2: 6276.63 | CA2: 6289.89 | CB2: 6283.46 | CC2: 6283.08 | CD2: 6285.48 | CE2: 6285.09 | CF2: 6281.85 | CG2: 6285.09 | CH2: 6283.47 | CI2: 6278.23 | CJ2: 6281.86 | CK2: 6284.27 | CL2: 6285.08 | CM2: 6281.87 | CN2: 6287.5 | CO2: 6283.47 | CP2: 6290.7 | CQ2: 6277.44 | CR2: 6283.07 | CS2: 6292.7
A3: 46236 | B3: 6289.9 | C3: 6281.46 | D3: 6286.28 | E3: 6279.86 | F3: 6277.43 | G3: 6282.26 | H3: 6281.87 | I3: 6279.85 | J3: 6282.67 | K3: 6282.67 | L3: 6289.5 | M3: 6287.49 | N3: 6291.9 | O3: 6283.87 | P3: 6287.9 | Q3: 6286.68 | R3: 6283.45 | S3: 6278.65 | T3: 6281.46 | U3: 6292.3 | V3: 6287.48 | W3: 6283.47 | X3: 6287.09 | Y3: 6289.49 | Z3: 6281.85 | AA3: 6275.43 | AB3: 6281.06 | AC3: 6287.09 | AD3: 6285.88 | AE3: 6279.46 | AF3: 6277.43 | AG3: 6284.27 | AH3: 6278.24 | AI3: 6276.64 | AJ3: 6281.86 | AK3: 6283.06 | AL3: 6279.04 | AM3: 6285.88 | AN3: 6285.47 | AO3: 6282.66 | AP3: 6280.64 | AQ3: 6282.67 | AR3: 6277.03 | AS3: 6280.65 | AT3: 6278.25 | AU3: 6287.07 | AV3: 6292.3 | AW3: 6282.66 | AX3: 6283.06 | AY3: 6277.04 | AZ3: 6283.88 | BA3: 6284.68 | BB3: 6284.28 | BC3: 6277.44 | BD3: 6285.48 | BE3: 6277.84 | BF3: 6284.27 | BG3: 6287.09 | BH3: 6281.46 | BI3: 6291.1 | BJ3: 6285.49 | BK3: 6281.06 | BL3: 6273.03 | BM3: 6276.64 | BN3: 6268.6 | BO3: 6277.44 | BP3: 6275.83 | BQ3: 6269 | BR3: 6270.62 | BS3: 6267.79 | BT3: 6270.21 | BU3: 6269.4 | BV3: 6271.41 | BW3: 6279.43 | BX3: 6273.43 | BY3: 6263.77 | BZ3: 6268.2 | CA3: 6264.58 | CB3: 6263.76 | CC3: 6269.41 | CD3: 6271.81 | CE3: 6262.97 | CF3: 6271.02 | CG3: 6267.8 | CH3: 6269.41 | CI3: 6274.22 | CJ3: 6273.01 | CK3: 6274.63 | CL3: 6272.21 | CM3: 6262.57 | CN3: 6268.59 | CO3: 6269.81 | CP3: 6270.61 | CQ3: 6272.61 | CR3: 6272.62 | CS3: 6268.99
A4: 46237 | B4: 6275.43 | C4: 6275.04 | D4: 6270.61 | E4: 6275.43 | F4: 6276.23 | G4: 6271.81 | H4: 6277.04 | I4: 6267.78 | J4: 6278.65 | K4: 6277.44 | L4: 6272.61 | M4: 6271.81 | N4: 6274.61 | O4: 6270.2 | P4: 6272.22 | Q4: 6267.39 | R4: 6274.63 | S4: 6271.8 | T4: 6276.64 | U4: 6268.19 | V4: 6275.43 | W4: 6275.43 | X4: 6266.58 | Y4: 6274.22 | Z4: 6268.19 | AA4: 6270.61 | AB4: 6275.83 | AC4: 6271.41 | AD4: 6275.81 | AE4: 6271.01 | AF4: 6275.43 | AG4: 6267.79 | AH4: 6271.8 | AI4: 6269.81 | AJ4: 6262.18 | AK4: 6266.18 | AL4: 6267.79 | AM4: 6259.76 | AN4: 6268.58 | AO4: 6262.56 | AP4: 6263.37 | AQ4: 6266.2 | AR4: 6261.77 | AS4: 6268.21 | AT4: 6267 | AU4: 6267.79 | AV4: 6266.98 | AW4: 6271.01 | AX4: 6269 | AY4: 6270.21 | AZ4: 6268.6 | BA4: 6277.44 | BB4: 6263.78 | BC4: 6269.81 | BD4: 6273.01 | BE4: 6269.8 | BF4: 6269 | BG4: 6269.8 | BH4: 6268.59 | BI4: 6262.96 | BJ4: 6270.2 | BK4: 6273.82 | BL4: 6271.82 | BM4: 6270.2 | BN4: 6262.57 | BO4: 6260.95 | BP4: 6262.16 | BQ4: 6265.78 | BR4: 6260.16 | BS4: 6260.96 | BT4: 6257.74 | BU4: 6273.01 | BV4: 6261.77 | BW4: 6258.95 | BX4: 6256.54 | BY4: 6265.38 | BZ4: 6263.78 | CA4: 6254.52 | CB4: 6260.96 | CC4: 6260.95 | CD4: 6252.51 | CE4: 6254.13 | CF4: 6253.72 | CG4: 6263.77 | CH4: 6259.35 | CI4: 6267.79 | CJ4: 6256.13 | CK4: 6265.79 | CL4: 6256.95 | CM4: 6262.97 | CN4: 6258.15 | CO4: 6262.96 | CP4: 6266.59 | CQ4: 6264.19 | CR4: 6258.95 | CS4: 6259.75
A5: 46238 | B5: 6268.18 | C5: 6264.99 | D5: 6263.78 | E5: 6265.79 | F5: 6262.57 | G5: 6263.78 | H5: 6258.95 | I5: 6259.34 | J5: 6260.55 | K5: 6265.38 | L5: 6264.98 | M5: 6263.37 | N5: 6271.82 | O5: 6269.8 | P5: 6267.39 | Q5: 6260.16 | R5: 6257.75 | S5: 6268.61 | T5: 6262.97 | U5: 6266.59 | V5: 6262.17 | W5: 6262.98 | X5: 6263.37 | Y5: 6264.17 | Z5: 6264.17 | AA5: 6267.78 | AB5: 6266.58 | AC5: 6268.99 | AD5: 6264.99 | AE5: 6260.56 | AF5: 6255.73 | AG5: 6263.37 | AH5: 6256.54 | AI5: 6261.36 | AJ5: 6260.96 | AK5: 6270.61 | AL5: 6260.56 | AM5: 6267.4 | AN5: 6265.38 | AO5: 6260.97 | AP5: 6259.77 | AQ5: 6265.78 | AR5: 6263.37 | AS5: 6260.55 | AT5: 6258.55 | AU5: 6260.55 | AV5: 6259.75 | AW5: 6259.76 | AX5: 6268.18 | AY5: 6263.38 | AZ5: 6260.97 | BA5: 6262.17 | BB5: 6254.55 | BC5: 6254.94 | BD5: 6269.4 | BE5: 6259.35 | BF5: 6265.38 | BG5: 6259.36 | BH5: 6262.17 | BI5: 6263.37 | BJ5: 6266.6 | BK5: 6260.96 | BL5: 6262.97 | BM5: 6262.97 | BN5: 6262.17 | BO5: 6265.79 | BP5: 6271.41 | BQ5: 6260.96 | BR5: 6262.18 | BS5: 6253.72 | BT5: 6258.95 | BU5: 6262.17 | BV5: 6252.12 | BW5: 6255.74 | BX5: 6255.32 | BY5: 6253.31 | BZ5: 6250.92 | CA5: 6248.1 | CB5: 6254.93 | CC5: 6254.52 | CD5: 6256.54 | CE5: 6258.15 | CF5: 6257.34 | CG5: 6254.13 | CH5: 6256.94 | CI5: 6250.9 | CJ5: 6258.55 | CK5: 6256.94 | CL5: 6255.73 | CM5: 6251.72 | CN5: 6257.74 | CO5: 6254.93 | CP5: 6254.14 | CQ5: 6258.15 | CR5: 6257.74 | CS5: 6263.38
A6: 46239 | B6: 6246.09 | C6: 6258.15 | D6: 6255.34 | E6: 6250.51 | F6: 6257.35 | G6: 6259.76 | H6: 6254.94 | I6: 6264.17 | J6: 6259.76 | K6: 6252.53 | L6: 6259.35 | M6: 6260.56 | N6: 6256.53 | O6: 6255.33 | P6: 6257.35 | Q6: 6263.37 | R6: 6265.39 | S6: 6257.34 | T6: 6261.76 | U6: 6263.37 | V6: 6257.75 | W6: 6256.94 | X6: 6256.94 | Y6: 6255.75 | Z6: 6257.34 | AA6: 6256.96 | AB6: 6253.72 | AC6: 6257.75 | AD6: 6253.33 | AE6: 6257.75 | AF6: 6255.34 | AG6: 6251.32 | AH6: 6249.7 | AI6: 6254.94 | AJ6: 6250.52 | AK6: 6258.54 | AL6: 6256.94 | AM6: 6252.92 | AN6: 6262.17 | AO6: 6255.74 | AP6: 6261.36 | AQ6: 6252.52 | AR6: 6259.76 | AS6: 6259.36 | AT6: 6250.11 | AU6: 6262.16 | AV6: 6255.34 | AW6: 6252.54 | AX6: 6257.75 | AY6: 6256.94 | AZ6: 6256.14 | BA6: 6252.91 | BB6: 6256.96 | BC6: 6249.31 | BD6: 6256.14 | BE6: 6252.12 | BF6: 6256.95 | BG6: 6254.12 | BH6: 6253.34 | BI6: 6247.3 | BJ6: 6253.72 | BK6: 6250.12 | BL6: 6251.72 | BM6: 6257.35 | BN6: 6246.1 | BO6: 6259.36 | BP6: 6255.73 | BQ6: 6248.52 | BR6: 6251.73 | BS6: 6257.75 | BT6: 6256.14 | BU6: 6252.93 | BV6: 6253.33 | BW6: 6248.9 | BX6: 6247.69 | BY6: 6250.12 | BZ6: 6254.13 | CA6: 6252.93 | CB6: 6245.28 | CC6: 6250.51 | CD6: 6244.49 | CE6: 6251.31 | CF6: 6253.74 | CG6: 6251.71 | CH6: 6255.34 | CI6: 6254.52 | CJ6: 6252.93 | CK6: 6238.05 | CL6: 6244.89 | CM6: 6253.33 | CN6: 6253.31 | CO6: 6245.68 | CP6: 6254.94 | CQ6: 6245.29 | CR6: 6252.93 | CS6: 6250.12
A7: 46240 | B7: 6251.72 | C7: 6251.71 | D7: 6250.11 | E7: 6252.11 | F7: 6252.93 | G7: 6246.09 | H7: 6250.51 | I7: 6250.11 | J7: 6247.69 | K7: 6251.31 | L7: 6244.08 | M7: 6250.91 | N7: 6246.09 | O7: 6256.55 | P7: 6244.07 | Q7: 6242.47 | R7: 6250.92 | S7: 6246.9 | T7: 6256.95 | U7: 6246.49 | V7: 6250.52 | W7: 6253.33 | X7: 6250.11 | Y7: 6250.92 | Z7: 6242.47 | AA7: 6244.49 | AB7: 6249.31 | AC7: 6252.52 | AD7: 6242.07 | AE7: 6250.11 | AF7: 6254.93 | AG7: 6249.72 | AH7: 6255.34 | AI7: 6247.71 | AJ7: 6249.31 | AK7: 6256.14 | AL7: 6253.33 | AM7: 6250.51 | AN7: 6242.47 | AO7: 6240.87 | AP7: 6244.5 | AQ7: 6247.7 | AR7: 6241.27 | AS7: 6244.08 | AT7: 6253.33 | AU7: 6245.3 | AV7: 6247.3 | AW7: 6250.92 | AX7: 6247.29 | AY7: 6242.47 | AZ7: 6242.08 | BA7: 6249.31 | BB7: 6250.52 | BC7: 6258.95 | BD7: 6249.71 | BE7: 6256.53 | BF7: 6246.89 | BG7: 6250.52 | BH7: 6254.14 | BI7: 6259.34 | BJ7: 6255.34 | BK7: 6248.9 | BL7: 6254.93 | BM7: 6250.92 | BN7: 6250.52 | BO7: 6247.3 | BP7: 6250.11 | BQ7: 6246.1 | BR7: 6253.32 | BS7: 6250.51 | BT7: 6248.5 | BU7: 6254.13 | BV7: 6250.91 | BW7: 6256.55 | BX7: 6262.17 | BY7: 6261.76 | BZ7: 6254.53 | CA7: 6248.49 | CB7: 6253.73 | CC7: 6252.52 | CD7: 6259.35 | CE7: 6253.73 | CF7: 6257.75 | CG7: 6255.74 | CH7: 6256.14 | CI7: 6260.15 | CJ7: 6252.52 | CK7: 6249.71 | CL7: 6253.33 | CM7: 6250.11 | CN7: 6258.94 | CO7: 6253.73 | CP7: 6253.32 | CQ7: 6257.35 | CR7: 6255.74 | CS7: 6251.71
A8: 46241 | B8: 6250.51 | C8: 6258.15 | D8: 6251.72 | E8: 6252.91 | F8: 6254.94 | G8: 6254.53 | H8: 6259.35 | I8: 6247.69 | J8: 6256.14 | K8: 6252.12 | L8: 6262.16 | M8: 6254.14 | N8: 6253.74 | O8: 6248.5 | P8: 6252.92 | Q8: 6258.14 | R8: 6256.94 | S8: 6259.35 | T8: 6255.74 | U8: 6256.53 | V8: 6265.78 | W8: 6262.17 | X8: 6257.75 | Y8: 6264.58 | Z8: 6262.97 | AA8: 6255.74 | AB8: 6265.79 | AC8: 6261.76 | AD8: 6256.95 | AE8: 6260.17 | AF8: 6262.57 | AG8: 6254.11 | AH8: 6263.37 | AI8: 6253.72 | AJ8: 6249.31 | AK8: 6251.73 | AL8: 6254.14 | AM8: 6261.77 | AN8: 6255.34 | AO8: 6252.12 | AP8: 6246.89 | AQ8: 6249.31 | AR8: 6251.32 | AS8: 6256.95 | AT8: 6249.71 | AU8: 6260.57 | AV8: 6248.9 | AW8: 6257.76 | AX8: 6258.95 | AY8: 6261.78 | AZ8: 6256.14 | BA8: 6257.35 | BB8: 6260.56 | BC8: 6254.93 | BD8: 6253.31 | BE8: 6255.75 | BF8: 6256.14 | BG8: 6250.52 | BH8: 6254.13 | BI8: 6254.14 | BJ8: 6254.53 | BK8: 6260.16 | BL8: 6251.31 | BM8: 6264.58 | BN8: 6249.3 | BO8: 6259.35 | BP8: 6254.52 | BQ8: 6261.77 | BR8: 6260.56 | BS8: 6262.56 | BT8: 6257.33 | BU8: 6260.96 | BV8: 6251.31 | BW8: 6258.95 | BX8: 6259.34 | BY8: 6260.56 | BZ8: 6257.75 | CA8: 6261.36 | CB8: 6260.16 | CC8: 6258.55 | CD8: 6258.95 | CE8: 6258.55 | CF8: 6254.14 | CG8: 6258.94 | CH8: 6268.61 | CI8: 6262.57 | CJ8: 6263.77 | CK8: 6263.37 | CL8: 6268.6 | CM8: 6266.59 | CN8: 6266.58 | CO8: 6266.99 | CP8: 6262.97 | CQ8: 6263.77 | CR8: 6265.4 | CS8: 6267
A9: 46242 | B9: 6258.96 | C9: 6266.18 | D9: 6269.81 | E9: 6271.01 | F9: 6271.02 | G9: 6268.99 | H9: 6258.55 | I9: 6264.58 | J9: 6265.78 | K9: 6260.97 | L9: 6272.61 | M9: 6271.01 | N9: 6263.77 | O9: 6270.61 | P9: 6270.61 | Q9: 6275.42 | R9: 6279.06 | S9: 6273.42 | T9: 6274.23 | U9: 6284.67 | V9: 6280.26 | W9: 6273.01 | X9: 6281.05 | Y9: 6281.45 | Z9: 6279.05 | AA9: 6278.64 | AB9: 6278.25 | AC9: 6277.84 | AD9: 6287.09 | AE9: 6284.66 | AF9: 6283.47 | AG9: 6283.06 | AH9: 6289.09 | AI9: 6288.69 | AJ9: 6286.27 | AK9: 6304.76 | AL9: 6290.3 | AM9: 6291.1 | AN9: 6293.52 | AO9: 6295.12 | AP9: 6287.07 | AQ9: 6290.31 | AR9: 6285.88 | AS9: 6292.3 | AT9: 6280.25 | AU9: 6297.14 | AV9: 6295.13 | AW9: 6295.13 | AX9: 6290.29 | AY9: 6289.5 | AZ9: 6293.12 | BA9: 6285.07 | BB9: 6291.1 | BC9: 6282.25 | BD9: 6289.1 | BE9: 6291.9 | BF9: 6289.91 | BG9: 6290.29 | BH9: 6291.91 | BI9: 6287.08 | BJ9: 6290.69 | BK9: 6286.28 | BL9: 6292.71 | BM9: 6291.5 | BN9: 6291.91 | BO9: 6293.11 | BP9: 6285.88 | BQ9: 6291.1 | BR9: 6302.75 | BS9: 6283.88 | BT9: 6287.09 | BU9: 6298.74 | BV9: 6293.11 | BW9: 6294.73 | BX9: 6296.33 | BY9: 6291.9 | BZ9: 6287.08 | CA9: 6287.08 | CB9: 6287.47 | CC9: 6294.72 | CD9: 6286.69 | CE9: 6303.16 | CF9: 6288.69 | CG9: 6294.32 | CH9: 6291.5 | CI9: 6288.29 | CJ9: 6289.9 | CK9: 6296.34 | CL9: 6292.7 | CM9: 6290.69 | CN9: 6289.5 | CO9: 6292.71 | CP9: 6291.9 | CQ9: 6292.7 | CR9: 6293.92 | CS9: 6289.5
A10: 46243 | B10: 6294.71 | C10: 6288.69 | D10: 6291.91 | E10: 6295.12 | F10: 6294.72 | G10: 6294.72 | H10: 6293.92 | I10: 6291.1 | J10: 6292.3 | K10: 6291.91 | L10: 6294.32 | M10: 6293.11 | N10: 6291.9 | O10: 6293.51 | P10: 6292.3 | Q10: 6298.73 | R10: 6301.95 | S10: 6300.34 | T10: 6300.33 | U10: 6296.33 | V10: 6297.93 | W10: 6299.14 | X10: 6301.15 | Y10: 6299.15 | Z10: 6310.79 | AA10: 6295.92 | AB10: 6297.54 | AC10: 6303.96 | AD10: 6310 | AE10: 6304.36 | AF10: 6310.8 | AG10: 6311.2 | AH10: 6306.38 | AI10: 6301.95 | AJ10: 6301.95 | AK10: 6303.16 | AL10: 6316.02 | AM10: 6311.99 | AN10: 6307.18 | AO10: 6318.83 | AP10: 6318.04 | AQ10: 6308.39 | AR10: 6309.59 | AS10: 6313.63 | AT10: 6308.79 | AU10: 6312.42 | AV10: 6314.41 | AW10: 6318.42 | AX10: 6312.41 | AY10: 6315.6 | AZ10: 6310 | BA10: 6312.01 | BB10: 6317.63 | BC10: 6307.18 | BD10: 6310 | BE10: 6309.98 | BF10: 6330.08 | BG10: 6315.62 | BH10: 6317.22 | BI10: 6323.65 | BJ10: 6312.4 | BK10: 6318.43 | BL10: 6326.47 | BM10: 6326.06 | BN10: 6336.11 | BO10: 6323.64 | BP10: 6329.67 | BQ10: 6325.27 | BR10: 6328.87 | BS10: 6332.09 | BT10: 6319.64 | BU10: 6324.87 | BV10: 6331.27 | BW10: 6333.7 | BX10: 6339.32 | BY10: 6343.74 | BZ10: 6344.55 | CA10: 6342.93 | CB10: 6349.78 | CC10: 6346.96 | CD10: 6338.13 | CE10: 6339.33 | CF10: 6339.73 | CG10: 6353.79 | CH10: 6346.16 | CI10: 6349.78 | CJ10: 6336.12 | CK10: 6357.01 | CL10: 6343.35 | CM10: 6344.96 | CN10: 6351.38 | CO10: 6348.17 | CP10: 6342.14 | CQ10: 6346.17 | CR10: 6338.53 | CS10: 6353.4
A11: 46244 | B11: 6348.97 | C11: 6344.55 | D11: 6343.74 | E11: 6344.14 | F11: 6344.55 | G11: 6343.74 | H11: 6344.95 | I11: 6345.77 | J11: 6340.94 | K11: 6343.75 | L11: 6337.33 | M11: 6348.17 | N11: 6338.12 | O11: 6346.56 | P11: 6341.34 | Q11: 6347.77 | R11: 6351.39 | S11: 6348.57 | T11: 6348.16 | U11: 6349.37 | V11: 6342.54 | W11: 6351.39 | X11: 6344.15 | Y11: 6345.36 | Z11: 6349.39 | AA11: 6344.95 | AB11: 6347.76 | AC11: 6343.73 | AD11: 6340.94 | AE11: 6351.79 | AF11: 6348.96 | AG11: 6351.78 | AH11: 6350.18 | AI11: 6341.73 | AJ11: 6348.98 | AK11: 6346.96 | AL11: 6344.16 | AM11: 6350.18 | AN11: 6347.37 | AO11: 6349.77 | AP11: 6342.14 | AQ11: 6342.54 | AR11: 6346.97 | AS11: 6346.57 | AT11: 6349.77 | AU11: 6348.57 | AV11: 6344.95 | AW11: 6346.97 | AX11: 6346.16 | AY11: 6344.55 | AZ11: 6335.72 | BA11: 6347.77 | BB11: 6344.15 | BC11: 6342.54 | BD11: 6338.93 | BE11: 6344.55 | BF11: 6346.55 | BG11: 6347.36 | BH11: 6336.92 | BI11: 6342.13 | BJ11: 6346.16 | BK11: 6342.94 | BL11: 6345.77 | BM11: 6342.14 | BN11: 6347.37 | BO11: 6344.96 | BP11: 6343.35 | BQ11: 6351.8 | BR11: 6342.15 | BS11: 6345.76 | BT11: 6341.34 | BU11: 6337.33 | BV11: 6346.56 | BW11: 6338.51 | BX11: 6342.53 | BY11: 6347.36 | BZ11: 6346.97 | CA11: 6342.96 | CB11: 6346.56 | CC11: 6344.57 | CD11: 6344.95 | CE11: 6340.13 | CF11: 6348.98 | CG11: 6351.38 | CH11: 6345.35 | CI11: 6356.21 | CJ11: 6338.92 | CK11: 6344.14 | CL11: 6350.58 | CM11: 6343.34 | CN11: 6352.19 | CO11: 6349.38 | CP11: 6344.95 | CQ11: 6348.98 | CR11: 6341.34 | CS11: 6347.78
A12: 46245 | B12: 6346.97 | C12: 6344.96 | D12: 6349.38 | E12: 6351.39 | F12: 6350.17 | G12: 6346.17 | H12: 6343.34 | I12: 6346.17 | J12: 6352.19 | K12: 6343.75 | L12: 6341.74 | M12: 6339.73 | N12: 6350.98 | O12: 6343.76 | P12: 6348.57 | Q12: 6340.93 | R12: 6342.94 | S12: 6340.13 | T12: 6350.18 | U12: 6344.14 | V12: 6347.36 | W12: 6348.17 | X12: 6345.76 | Y12: 6345.36 | Z12: 6344.55 | AA12: 6346.97 | AB12: 6344.15 | AC12: 6346.57 | AD12: 6343.76 | AE12: 6346.55 | AF12: 6352.19 | AG12: 6349.38 | AH12: 6344.56 | AI12: 6341.33 | AJ12: 6347.35 | AK12: 6350.58 | AL12: 6347.37 | AM12: 6353.39 | AN12: 6339.34 | AO12: 6338.93 | AP12: 6349.38 | AQ12: 6350.59 | AR12: 6350.98 | AS12: 6348.98 | AT12: 6348.98 | AU12: 6345.77 | AV12: 6341.34 | AW12: 6343.35 | AX12: 6338.92 | AY12: 6341.34 | AZ12: 6342.14 | BA12: 6337.72 | BB12: 6334.1 | BC12: 6345.76 | BD12: 6343.35 | BE12: 6343.35 | BF12: 6334.91 | BG12: 6340.94 | BH12: 6345.76 | BI12: 6344.56 | BJ12: 6336.92 | BK12: 6336.92 | BL12: 6338.11 | BM12: 6340.93 | BN12: 6334.5 | BO12: 6339.74 | BP12: 6344.55 | BQ12: 6336.92 | BR12: 6339.73 | BS12: 6339.73 | BT12: 6341.34 | BU12: 6343.75 | BV12: 6335.3 | BW12: 6340.95 | BX12: 6336.51 | BY12: 6339.33 | BZ12: 6342.94 | CA12: 6344.55 | CB12: 6346.16 | CC12: 6344.96 | CD12: 6339.33 | CE12: 6341.73 | CF12: 6349.77 | CG12: 6340.93 | CH12: 6351.38 | CI12: 6345.76 | CJ12: 6331.7 | CK12: 6353 | CL12: 6341.74 | CM12: 6345.75 | CN12: 6338.52 | CO12: 6344.54 | CP12: 6344.95 | CQ12: 6344.54 | CR12: 6341.32 | CS12: 6350.18
A13: 46246 | B13: 6346.97 | C13: 6344.56 | D13: 6346.97 | E13: 6352.19 | F13: 6336.52 | G13: 6338.52 | H13: 6336.92 | I13: 6339.32 | J13: 6340.53 | K13: 6341.34 | L13: 6344.95 | M13: 6344.56 | N13: 6340.53 | O13: 6349.37 | P13: 6338.93 | Q13: 6352.59 | R13: 6350.18 | S13: 6340.12 | T13: 6332.5 | U13: 6345.36 | V13: 6352.99 | W13: 6344.94 | X13: 6340.14 | Y13: 6339.34 | Z13: 6340.13 | AA13: 6350.98 | AB13: 6341.74 | AC13: 6345.76 | AD13: 6335.72 | AE13: 6337.71 | AF13: 6345.75 | AG13: 6348.58 | AH13: 6338.52 | AI13: 6342.54 | AJ13: 6342.15 | AK13: 6343.35 | AL13: 6343.74 | AM13: 6346.96 | AN13: 6346.56 | AO13: 6344.94 | AP13: 6342.14 | AQ13: 6334.1 | AR13: 6319.23 | AS13: 6314.41 | AT13: 6328.07 | AU13: 6314.41 | AV13: 6315.61 | AW13: 6346.15 | AX13: 6346.96 | AY13: 6344.56 | AZ13: 6338.52 | BA13: 6342.95 | BB13: 6331.7 | BC13: 6338.53 | BD13: 6338.52 | BE13: 6340.92 | BF13: 6334.91 | BG13: 6329.68 | BH13: 6333.7 | BI13: 6335.71 | BJ13: 6320.84 | BK13: 6329.68 | BL13: 6334.49 | BM13: 6311.2 | BN13: 6303.16 | BO13: 6308.39 | BP13: 6292.72 | BQ13: 6314.41 | BR13: 6314.81 | BS13: 6327.69 | BT13: 6328.08 | BU13: 6332.5 | BV13: 6322.45 | BW13: 6329.68 | BX13: 6332.5 | BY13: 6337.72 | BZ13: 6326.47 | CA13: 6328.89 | CB13: 6322.05 | CC13: 6330.48 | CD13: 6337.31 | CE13: 6338.12 | CF13: 6334.9 | CG13: 6331.29 | CH13: 6334.1 | CI13: 6336.91 | CJ13: 6337.72 | CK13: 6337.72 | CL13: 6337.31 | CM13: 6336.93 | CN13: 6336.51 | CO13: 6333.29 | CP13: 6334.5 | CQ13: 6334.9 | CR13: 6336.5 | CS13: 6331.28
... A32: 46265 | B32: 6338.53 | C32: 6337.71 | D32: 6332.89 | E32: 6332.49 | F32: 6335.71 | G32: 6335.72 | H32: 6336.92 | I32: 6333.3 | J32: 6335.32 | K32: 6339.73 | L32: 6334.91 | M32: 6334.92 | N32: 6330.49 | O32: 6330.5 | P32: 6329.69 | Q32: 6325.27 | R32: 6330.5 | S32: 6330.89 | T32: 6325.66 | U32: 6328.06 | V32: 6337.32 | W32: 6330.08 | X32: 6332.1 | Y32: 6332.1 | Z32: 6332.91 | AA32: 6326.07 | AB32: 6328.88 | AC32: 6334.89 | AD32: 6322.05 | AE32: 6331.7 | AF32: 6332.89 | AG32: 6340.14 | AH32: 6330.88 | AI32: 6323.65 | AJ32: 6328.88 | AK32: 6324.85 | AL32: 6330.48 | AM32: 6329.68 | AN32: 6330.09 | AO32: 6330.49 | AP32: 6323.26 | AQ32: 6326.87 | AR32: 6332.51 | AS32: 6329.29 | AT32: 6335.71 | AU32: 6333.7 | AV32: 6341.74 | AW32: 6334.91 | AX32: 6331.69 | AY32: 6328.48 | AZ32: 6318.02 | BA32: 6332.09 | BB32: 6329.29 | BC32: 6327.67 | BD32: 6330.48 | BE32: 6330.48 | BF32: 6329.67 | BG32: 6336.51 | BH32: 6334.91 | BI32: 6342.95 | BJ32: 6332.49 | BK32: 6318.43 | BL32: 6339.32 | BM32: 6331.69 | BN32: 6340.14 | BO32: 6343.35 | BP32: 6339.33 | BQ32: 6343.35 | BR32: 6341.35 | BS32: 6328.08 | BT32: 6343.75 | BU32: 6336.91 | BV32: 6336.52 | BW32: 6331.28 | BX32: 6336.52 | BY32: 6345.36 | BZ32: 6330.89 | CA32: 6328.87 | CB32: 6339.74 | CC32: 6348.16 | CD32: 6334.51 | CE32: 6331.3 | CF32: 6333.3 | CG32: 6332.1 | CH32: 6335.31 | CI32: 6335.71 | CJ32: 6335.32 | CK32: 6336.11 | CL32: 6342.55 | CM32: 6335.71 | CN32: 6328.87 | CO32: 6338.53 | CP32: 6329.28 | CQ32: 6333.7 | CR32: 6334.09 | CS32: 6327.68

Sheet 地方燃煤
A1: 日期 | B1: 0.010416667 | C1: 0.020833333 | D1: 0.03125 | E1: 0.041666667 | F1: 0.052083333 | G1: 0.0625 | H1: 0.072916667 | I1: 0.083333333 | J1: 0.09375 | K1: 0.10416667 | L1: 0.11458333 | M1: 0.125 | N1: 0.13541667 | O1: 0.14583333 | P1: 0.15625 | Q1: 0.16666667 | R1: 0.17708333 | S1: 0.1875 | T1: 0.19791667 | U1: 0.20833333 | V1: 0.21875 | W1: 0.22916667 | X1: 0.23958333 | Y1: 0.25 | Z1: 0.26041667 | AA1: 0.27083333 | AB1: 0.28125 | AC1: 0.29166667 | AD1: 0.30208333 | AE1: 0.3125 | AF1: 0.32291667 | AG1: 0.33333333 | AH1: 0.34375 | AI1: 0.35416667 | AJ1: 0.36458333 | AK1: 0.375 | AL1: 0.38541667 | AM1: 0.39583333 | AN1: 0.40625 | AO1: 0.41666667 | AP1: 0.42708333 | AQ1: 0.4375 | AR1: 0.44791667 | AS1: 0.45833333 | AT1: 0.46875 | AU1: 0.47916667 | AV1: 0.48958333 | AW1: 0.5 | AX1: 0.51041667 | AY1: 0.52083333 | AZ1: 0.53125 | BA1: 0.54166667 | BB1: 0.55208333 | BC1: 0.5625 | BD1: 0.57291667 | BE1: 0.58333333 | BF1: 0.59375 | BG1: 0.60416667 | BH1: 0.61458333 | BI1: 0.625 | BJ1: 0.63541667 | BK1: 0.64583333 | BL1: 0.65625 | BM1: 0.66666667 | BN1: 0.67708333 | BO1: 0.6875 | BP1: 0.69791667 | BQ1: 0.70833333 | BR1: 0.71875 | BS1: 0.72916667 | BT1: 0.73958333 | BU1: 0.75 | BV1: 0.76041667 | BW1: 0.77083333 | BX1: 0.78125 | BY1: 0.79166667 | BZ1: 0.80208333 | CA1: 0.8125 | CB1: 0.82291667 | CC1: 0.83333333 | CD1: 0.84375 | CE1: 0.85416667 | CF1: 0.86458333 | CG1: 0.875 | CH1: 0.88541667 | CI1: 0.89583333 | CJ1: 0.90625 | CK1: 0.91666667 | CL1: 0.92708333 | CM1: 0.9375 | CN1: 0.94791667 | CO1: 0.95833333 | CP1: 0.96875 | CQ1: 0.97916667 | CR1: 0.98958333 | CS1: 1
A2: 46235 | B2: 35.54 | C2: 35.7 | D2: 37.28 | E2: 35.98 | F2: 39.41 | G2: 39.97 | H2: 36.43 | I2: 36.79 | J2: 38.32 | K2: 38.43 | L2: 37.41 | M2: 36.45 | N2: 37.04 | O2: 37.75 | P2: 37.49 | Q2: 36.94 | R2: 36 | S2: 38.47 | T2: 39.75 | U2: 40.24 | V2: 39.14 | W2: 38.98 | X2: 38.28 | Y2: 39.45 | Z2: 40.84 | AA2: 40.33 | AB2: 38.99 | AC2: 38.43 | AD2: 38.52 | AE2: 40.14 | AF2: 39.08 | AG2: 40.51 | AH2: 41.3 | AI2: 41.05 | AJ2: 41.09 | AK2: 41.95 | AL2: 40.36 | AM2: 39.91 | AN2: 41.13 | AO2: 42.5 | AP2: 41.77 | AQ2: 39.14 | AR2: 37.4 | AS2: 38.91 | AT2: 37.22 | AU2: 38.4 | AV2: 36.75 | AW2: 37.07 | AX2: 38.3 | AY2: 37.74 | AZ2: 37.49 | BA2: 38 | BB2: 38.07 | BC2: 37.39 | BD2: 38.01 | BE2: 39.21 | BF2: 38.36 | BG2: 37.73 | BH2: 39.91 | BI2: 38.51 | BJ2: 37.84 | BK2: 39.4 | BL2: 41.64 | BM2: 40.92 | BN2: 42.84 | BO2: 42.6 | BP2: 43.73 | BQ2: 44.73 | BR2: 44.86 | BS2: 44.24 | BT2: 43.67 | BU2: 43.72 | BV2: 42.8 | BW2: 43.91 | BX2: 42.62 | BY2: 41.32 | BZ2: 41.37 | CA2: 42.18 | CB2: 41.81 | CC2: 43.37 | CD2: 43.21 | CE2: 44.27 | CF2: 45 | CG2: 45.38 | CH2: 44.15 | CI2: 42.68 | CJ2: 42.91 | CK2: 43.04 | CL2: 43.17 | CM2: 41.97 | CN2: 41.68 | CO2: 42.07 | CP2: 44.06 | CQ2: 43.42 | CR2: 43.61 | CS2: 42.09
